Workbook

Sheet Matriz Trazabilidad
A1: WALVY | M4 – Matriz de Trazabilidad Cliente v1.3
A2: Matriz funcional consolidada para revisión de Producto. Incluye variantes, HU, criterios de aceptación, reglas de negocio, fuentes, caso de prueba de trazabilidad, evidencia y referencia Figma. No incorpora plan de ejecución QA ni registro de brechas.
A4: ID Variante | B4: Flujo / Subflujo | C4: Variante / Escenario | D4: Condición / Disparador | E4: Comportamiento esperado | F4: HU asociada | G4: CA asociado | H4: Regla de negocio asociada | I4: Origen / Estado RN | J4: Código fuente RN | K4: Descripción fuente RN | L4: Caso de Prueba | M4: Evidencia QA | N4: Estado evidencia | O4: Nodo Figma | P4: URL Figma | Q4: Clasificación de soporte | R4: Validación Cliente | S4: Decisión PO / Comentarios | T4: ID Pendiente Cliente
A5: M4-V01 | B5: Perfil Financiero | C5: Sin señal/estado de deuda | D5: Perfil no identifica señal de deuda relevante | E5: Mantener flujo principal de Perfil; M4 no se ejecuta dentro de la superficie. | F5: M4-HU-001 | G5: CA1-CA3 | H5: M4-RN-001 | I5: Documento v1.0 | J5: S1/S2 | K5: S1 – Walvy_Modulo4_Fase1_Flujo_Funcional_v1_0: Activación, entradas, validación, derivación, bloqueos, dependencias y datos mínimos. S2 – Walvy_Modulo4_Fase2_Matriz_Pantallas_Modales_Acciones_v1_0: Pantallas núcleo/condicionadas, estados, modales, acciones, componentes, fallback y criterios por pantalla. | L5: CP-M4-001 | M5: Pendiente de evidencia QA ejecutada | N5: Pendiente | O5: M4 · Nodo maestro 5897:11184 | P5: https://www.figma.com/design/v45c4HTKnPnU0XABMa5vjY/Walvi-APP---Edificate-Inteligente?node-id=5897-11184&t=MbYXTevtHjInQ9dh-4 | Q5: Confirmado documental | R5: Pendiente
A6: M4-V02 | B6: Perfil Financiero | C6: Datos insuficientes | D6: Existe señal de deuda, pero faltan datos mínimos para evaluar | E6: Derivar a completar información en Onboarding de Deudas; no afirmar deuda manejable/presionada. | F6: M4-HU-001 / M4-HU-007 | G6: CA1-CA3 | H6: M4-RN-003 / M4-RN-006 | I6: Documento v1.0 | J6: S1/S2 | K6: S1 – Walvy_Modulo4_Fase1_Flujo_Funcional_v1_0: Activación, entradas, validación, derivación, bloqueos, dependencias y datos mínimos. S2 – Walvy_Modulo4_Fase2_Matriz_Pantallas_Modales_Acciones_v1_0: Pantallas núcleo/condicionadas, estados, modales, acciones, componentes, fallback y criterios por pantalla. | L6: CP-M4-002 | M6: Pendiente de evidencia QA ejecutada | N6: Pendiente | O6: M4 · Nodo maestro 5897:11184 | P6: https://www.figma.com/design/v45c4HTKnPnU0XABMa5vjY/Walvi-APP---Edificate-Inteligente?node-id=5897-11184&t=MbYXTevtHjInQ9dh-4 | Q6: Confirmado documental | R6: Pendiente
A7: M4-V03 | B7: Perfil Financiero | C7: Deuda detectada no confirmada | D7: Existe deuda detectada/inferida sin confirmación individual | E7: Solicitar confirmación/corrección/descarte en OD; no afectar Salud de Deuda. | F7: M4-HU-001 / M4-HU-010 | G7: CA1-CA3 | H7: M4-RN-005 / M4-RN-014 | I7: Documento v1.0 | J7: S1/S2/S3 | K7: S1 – Walvy_Modulo4_Fase1_Flujo_Funcional_v1_0: Activación, entradas, validación, derivación, bloqueos, dependencias y datos mínimos. S2 – Walvy_Modulo4_Fase2_Matriz_Pantallas_Modales_Acciones_v1_0: Pantallas núcleo/condicionadas, estados, modales, acciones, componentes, fallback y criterios por pantalla. S3 – Walvy_Modulo4_Fase3_Reglas_Contextuales_Severidad_v1_0: Gatillos, severidad S0-S4, activación, transiciones, recomendaciones y guardrails. | L7: CP-M4-003 | M7: Pendiente de evidencia QA ejecutada | N7: Pendiente | O7: M4 · Nodo maestro 5897:11184 | P7: https://www.figma.com/design/v45c4HTKnPnU0XABMa5vjY/Walvi-APP---Edificate-Inteligente?node-id=5897-11184&t=MbYXTevtHjInQ9dh-4 | Q7: Confirmado documental | R7: Pendiente
A8: M4-V04 | B8: Perfil Financiero | C8: Deuda confirmada pero incompleta | D8: La deuda está confirmada y falta dato crítico | E8: Solicitar solo el dato crítico faltante en OD/edición puntual; no activar Ruta Despeje completa. | F8: M4-HU-001 / M4-HU-007 | G8: CA1-CA3 | H8: M4-RN-006 / M4-RN-004 | I8: Documento v1.0 | J8: S1/S2 | K8: S1 – Walvy_Modulo4_Fase1_Flujo_Funcional_v1_0: Activación, entradas, validación, derivación, bloqueos, dependencias y datos mínimos. S2 – Walvy_Modulo4_Fase2_Matriz_Pantallas_Modales_Acciones_v1_0: Pantallas núcleo/condicionadas, estados, modales, acciones, componentes, fallback y criterios por pantalla. | L8: CP-M4-004 | M8: Pendiente de evidencia QA ejecutada | N8: Pendiente | O8: M4 · Nodo maestro 5897:11184 | P8: https://www.figma.com/design/v45c4HTKnPnU0XABMa5vjY/Walvi-APP---Edificate-Inteligente?node-id=5897-11184&t=MbYXTevtHjInQ9dh-4 | Q8: Confirmado documental | R8: Pendiente
A9: M4-V05 | B9: Perfil Financiero | C9: Deuda manejable | D9: Deuda confirmada, pagos al día y presión baja/controlable | E9: Mostrar acceso a detalle/seguimiento DD-01 sin activar Ruta Despeje completa. | F9: M4-HU-001 / M4-HU-012 | G9: CA1-CA3 | H9: M4-RN-017 / M4-RN-042 | I9: Documento v1.0 | J9: S1/S2/S3 | K9: S1 – Walvy_Modulo4_Fase1_Flujo_Funcional_v1_0: Activación, entradas, validación, derivación, bloqueos, dependencias y datos mínimos. S2 – Walvy_Modulo4_Fase2_Matriz_Pantallas_Modales_Acciones_v1_0: Pantallas núcleo/condicionadas, estados, modales, acciones, componentes, fallback y criterios por pantalla. S3 – Walvy_Modulo4_Fase3_Reglas_Contextuales_Severidad_v1_0: Gatillos, severidad S0-S4, activación, transiciones, recomendaciones y guardrails. | L9: CP-M4-005 | M9: Pendiente de evidencia QA ejecutada | N9: Pendiente | O9: M4 · Nodo maestro 5897:11184 | P9: https://www.figma.com/design/v45c4HTKnPnU0XABMa5vjY/Walvi-APP---Edificate-Inteligente?node-id=5897-11184&t=MbYXTevtHjInQ9dh-4 | Q9: Confirmado documental | R9: Pendiente
A10: M4-V06 | B10: Perfil Financiero | C10: Deuda requiere atención | D10: Deuda confirmada con señal preventiva o S2 | E10: Derivar a revisión/Detalle de Deuda; Ruta Despeje solo si posteriormente cumple gate. | F10: M4-HU-001 / M4-HU-013 | G10: CA1-CA3 | H10: M4-RN-017 / M4-RN-018 | I10: Documento v1.0 | J10: S1/S2/S3 | K10: S1 – Walvy_Modulo4_Fase1_Flujo_Funcional_v1_0: Activación, entradas, validación, derivación, bloqueos, dependencias y datos mínimos. S2 – Walvy_Modulo4_Fase2_Matriz_Pantallas_Modales_Acciones_v1_0: Pantallas núcleo/condicionadas, estados, modales, acciones, componentes, fallback y criterios por pantalla. S3 – Walvy_Modulo4_Fase3_Reglas_Contextuales_Severidad_v1_0: Gatillos, severidad S0-S4, activación, transiciones, recomendaciones y guardrails. | L10: CP-M4-006 | M10: Pendiente de evidencia QA ejecutada | N10: Pendiente | O10: M4 · Nodo maestro 5897:11184 | P10: https://www.figma.com/design/v45c4HTKnPnU0XABMa5vjY/Walvi-APP---Edificate-Inteligente?node-id=5897-11184&t=MbYXTevtHjInQ9dh-4 | Q10: Confirmado documental | R10: Pendiente
A11: M4-V07 | B11: Perfil Financiero | C11: Deuda presionada elegible | D11: Deuda confirmada + gatillo suficiente + datos mínimos | E11: Habilitar acceso a Ruta Despeje completa; Perfil solo muestra señal/CTA contextual. | F11: M4-HU-001 / M4-HU-014 | G11: CA1-CA3 | H11: M4-RN-001 / M4-RN-004 | I11: BDD v1.0 / Documento v1.0 | J11: S1/S2/S3/S4 | K11: S1 – Walvy_Modulo4_Fase1_Flujo_Funcional_v1_0: Activación, entradas, validación, derivación, bloqueos, dependencias y datos mínimos. S2 – Walvy_Modulo4_Fase2_Matriz_Pantallas_Modales_Acciones_v1_0: Pantallas núcleo/condicionadas, estados, modales, acciones, componentes, fallback y criterios por pantalla. S3 – Walvy_Modulo4_Fase3_Reglas_Contextuales_Severidad_v1_0: Gatillos, severidad S0-S4, activación, transiciones, recomendaciones y guardrails. S4 – Walvy_Modulo4_Fase3_Anexo_BDD_Reglas_Productivas_v1_0: Parámetros MVP, fórmulas, entidades, campos, estados, enums, vigencia y reglas implementables. | L11: CP-M4-007 | M11: Pendiente de evidencia QA ejecutada | N11: Pendiente | O11: M4 · Nodo maestro 5897:11184 | P11: https://www.figma.com/design/v45c4HTKnPnU0XABMa5vjY/Walvi-APP---Edificate-Inteligente?node-id=5897-11184&t=MbYXTevtHjInQ9dh-4 | Q11: Confirmado documental | R11: Pendiente
A12: M4-V08 | B12: Home | C12: Deuda no dominante | D12: Existe deuda, pero no es la señal dominante del mes | E12: No forzar CTA principal de deuda; mantener flujo operativo principal y acceso secundario si corresponde. | F12: M4-HU-002 | G12: CA1-CA3 | H12: M4-RN-002 | I12: Documento v1.0 | J12: S1/S2 | K12: S1 – Walvy_Modulo4_Fase1_Flujo_Funcional_v1_0: Activación, entradas, validación, derivación, bloqueos, dependencias y datos mínimos. S2 – Walvy_Modulo4_Fase2_Matriz_Pantallas_Modales_Acciones_v1_0: Pantallas núcleo/condicionadas, estados, modales, acciones, componentes, fallback y criterios por pantalla. | L12: CP-M4-008 | M12: Pendiente de evidencia QA ejecutada | N12: Pendiente | O12: M4 · Nodo maestro 5897:11184 | P12: https://www.figma.com/design/v45c4HTKnPnU0XABMa5vjY/Walvi-APP---Edificate-Inteligente?node-id=5897-11184&t=MbYXTevtHjInQ9dh-4 | Q12: Confirmado documental | R12: Pendiente
A13: M4-V09 | B13: Home | C13: Deuda dominante y elegible | D13: Deuda es señal dominante, está confirmada, con presión/gatillo y datos mínimos | E13: Mostrar CTA principal hacia Ruta Despeje. | F13: M4-HU-002 / M4-HU-014 | G13: CA1-CA3 | H13: M4-RN-002 / M4-RN-004 | I13: BDD v1.0 / Documento v1.0 | J13: S1/S2/S3/S4 | K13: S1 – Walvy_Modulo4_Fase1_Flujo_Funcional_v1_0: Activación, entradas, validación, derivación, bloqueos, dependencias y datos mínimos. S2 – Walvy_Modulo4_Fase2_Matriz_Pantallas_Modales_Acciones_v1_0: Pantallas núcleo/condicionadas, estados, modales, acciones, componentes, fallback y criterios por pantalla. S3 – Walvy_Modulo4_Fase3_Reglas_Contextuales_Severidad_v1_0: Gatillos, severidad S0-S4, activación, transiciones, recomendaciones y guardrails. S4 – Walvy_Modulo4_Fase3_Anexo_BDD_Reglas_Productivas_v1_0: Parámetros MVP, fórmulas, entidades, campos, estados, enums, vigencia y reglas implementables. | L13: CP-M4-009 | M13: Pendiente de evidencia QA ejecutada | N13: Pendiente | O13: M4 · Nodo maestro 5897:11184 | P13: https://www.figma.com/design/v45c4HTKnPnU0XABMa5vjY/Walvi-APP---Edificate-Inteligente?node-id=5897-11184&t=MbYXTevtHjInQ9dh-4 | Q13: Confirmado documental | R13: Pendiente
A14: M4-V10 | B14: Home | C14: Deuda pendiente de confirmación | D14: Home detecta señal relevante, pero la deuda no está confirmada | E14: Derivar a OD para confirmar/corregir/descartar; no activar plan. | F14: M4-HU-002 / M4-HU-007 | G14: CA1-CA3 | H14: M4-RN-005 / M4-RN-003 | I14: Documento v1.0 | J14: S1/S2/S3 | K14: S1 – Walvy_Modulo4_Fase1_Flujo_Funcional_v1_0: Activación, entradas, validación, derivación, bloqueos, dependencias y datos mínimos. S2 – Walvy_Modulo4_Fase2_Matriz_Pantallas_Modales_Acciones_v1_0: Pantallas núcleo/condicionadas, estados, modales, acciones, componentes, fallback y criterios por pantalla. S3 – Walvy_Modulo4_Fase3_Reglas_Contextuales_Severidad_v1_0: Gatillos, severidad S0-S4, activación, transiciones, recomendaciones y guardrails. | L14: CP-M4-010 | M14: Pendiente de evidencia QA ejecutada | N14: Pendiente | O14: M4 · Nodo maestro 5897:11184 | P14: https://www.figma.com/design/v45c4HTKnPnU0XABMa5vjY/Walvi-APP---Edificate-Inteligente?node-id=5897-11184&t=MbYXTevtHjInQ9dh-4 | Q14: Confirmado documental | R14: Pendiente
A15: M4-V11 | B15: Home | C15: Dato crítico faltante | D15: Deuda relevante, pero falta un dato crítico para evaluar | E15: Derivar a completar dato en OD o edición puntual; mantener diagnóstico limitado. | F15: M4-HU-002 / M4-HU-007 | G15: CA1-CA3 | H15: M4-RN-006 | I15: BDD v1.0 / Documento v1.0 | J15: S1/S2/S4 | K15: S1 – Walvy_Modulo4_Fase1_Flujo_Funcional_v1_0: Activación, entradas, validación, derivación, bloqueos, dependencias y datos mínimos. S2 – Walvy_Modulo4_Fase2_Matriz_Pantallas_Modales_Acciones_v1_0: Pantallas núcleo/condicionadas, estados, modales, acciones, componentes, fallback y criterios por pantalla. S4 – Walvy_Modulo4_Fase3_Anexo_BDD_Reglas_Productivas_v1_0: Parámetros MVP, fórmulas, entidades, campos, estados, enums, vigencia y reglas implementables. | L15: CP-M4-011 | M15: Pendiente de evidencia QA ejecutada | N15: Pendiente | O15: M4 · Nodo maestro 5897:11184 | P15: https://www.figma.com/design/v45c4HTKnPnU0XABMa5vjY/Walvi-APP---Edificate-Inteligente?node-id=5897-11184&t=MbYXTevtHjInQ9dh-4 | Q15: Confirmado documental | R15: Pendiente
A16: M4-V12 | B16: Home | C16: Lote pendiente relevante | D16: Documento/lote generó varias deudas pendientes de revisión | E16: Derivar a OD-02 para revisión individual; no consolidar lote como deuda confirmada. | F16: M4-HU-002 / M4-HU-009 | G16: CA1-CA3 | H16: M4-RN-012 | I16: Documento v1.0 | J16: S1/S2/S3 | K16: S1 – Walvy_Modulo4_Fase1_Flujo_Funcional_v1_0: Activación, entradas, validación, derivación, bloqueos, dependencias y datos mínimos. S2 – Walvy_Modulo4_Fase2_Matriz_Pantallas_Modales_Acciones_v1_0: Pantallas núcleo/condicionadas, estados, modales, acciones, componentes, fallback y criterios por pantalla. S3 – Walvy_Modulo4_Fase3_Reglas_Contextuales_Severidad_v1_0: Gatillos, severidad S0-S4, activación, transiciones, recomendaciones y guardrails. | L16: CP-M4-012 | M16: Pendiente de evidencia QA ejecutada | N16: Pendiente | O16: M4 · Nodo maestro 5897:11184 | P16: https://www.figma.com/design/v45c4HTKnPnU0XABMa5vjY/Walvi-APP---Edificate-Inteligente?node-id=5897-11184&t=MbYXTevtHjInQ9dh-4 | Q16: Confirmado documental | R16: Pendiente
A17: M4-V13 | B17: Home | C17: Vencimiento crítico con capacidad | D17: Existe vencimiento relevante y evidencia de capacidad de pago | E17: Mostrar alerta/revisión; no activar Ruta Despeje por fecha solamente. | F17: M4-HU-002 / M4-HU-025 | G17: CA1-CA3 | H17: M4-RN-021 / M4-RN-043 | I17: Documento v1.0 | J17: S1/S2/S3 | K17: S1 – Walvy_Modulo4_Fase1_Flujo_Funcional_v1_0: Activación, entradas, validación, derivación, bloqueos, dependencias y datos mínimos. S2 – Walvy_Modulo4_Fase2_Matriz_Pantallas_Modales_Acciones_v1_0: Pantallas núcleo/condicionadas, estados, modales, acciones, componentes, fallback y criterios por pantalla. S3 – Walvy_Modulo4_Fase3_Reglas_Contextuales_Severidad_v1_0: Gatillos, severidad S0-S4, activación, transiciones, recomendaciones y guardrails. | L17: CP-M4-013 | M17: Pendiente de evidencia QA ejecutada | N17: Pendiente | O17: M4 · Nodo maestro 5897:11184 | P17: https://www.figma.com/design/v45c4HTKnPnU0XABMa5vjY/Walvi-APP---Edificate-Inteligente?node-id=5897-11184&t=MbYXTevtHjInQ9dh-4 | Q17: Confirmado documental / decisión pendiente | R17: Pendiente | T17: PD-M4-04 / PD-M4-07
A18: M4-V14 | B18: Home | C18: Vencimiento crítico sin capacidad | D18: Existe vencimiento relevante y no hay capacidad clara / hay presión | E18: Derivar a revisión de deuda y evaluar severidad; activar RD solo si se cumplen confirmación, mínimos y gatillo. | F18: M4-HU-002 / M4-HU-025 / M4-HU-014 | G18: CA1-CA3 | H18: M4-RN-021 / M4-RN-004 | I18: Documento v1.0 | J18: S1/S2/S3 | K18: S1 – Walvy_Modulo4_Fase1_Flujo_Funcional_v1_0: Activación, entradas, validación, derivación, bloqueos, dependencias y datos mínimos. S2 – Walvy_Modulo4_Fase2_Matriz_Pantallas_Modales_Acciones_v1_0: Pantallas núcleo/condicionadas, estados, modales, acciones, componentes, fallback y criterios por pantalla. S3 – Walvy_Modulo4_Fase3_Reglas_Contextuales_Severidad_v1_0: Gatillos, severidad S0-S4, activación, transiciones, recomendaciones y guardrails. | L18: CP-M4-014 | M18: Pendiente de evidencia QA ejecutada | N18: Pendiente | O18: M4 · Nodo maestro 5897:11184 | P18: https://www.figma.com/design/v45c4HTKnPnU0XABMa5vjY/Walvi-APP---Edificate-Inteligente?node-id=5897-11184&t=MbYXTevtHjInQ9dh-4 | Q18: Confirmado documental / decisión pendiente | R18: Pendiente | T18: PD-M4-04
A19: M4-V15 | B19: OD-01 · Método y captura | C19: Registro manual de deuda formal | D19: Usuario selecciona agregar deuda manualmente | E19: Capturar identificación/tipo, saldo aproximado y demás datos disponibles; permitir guardar pendiente si faltan mínimos. | F19: M4-HU-003 | G19: CA1-CA3 | H19: M4-RN-007 / M4-RN-010 | I19: BDD v1.0 / Documento v1.0 | J19: S2/S4 | K19: S2 – Walvy_Modulo4_Fase2_Matriz_Pantallas_Modales_Acciones_v1_0: Pantallas núcleo/condicionadas, estados, modales, acciones, componentes, fallback y criterios por pantalla. S4 – Walvy_Modulo4_Fase3_Anexo_BDD_Reglas_Productivas_v1_0: Parámetros MVP, fórmulas, entidades, campos, estados, enums, vigencia y reglas implementables. | L19: CP-M4-015 | M19: Pendiente de evidencia QA ejecutada | N19: Pendiente | O19: M4 · Nodo maestro 5897:11184 | P19: https://www.figma.com/design/v45c4HTKnPnU0XABMa5vjY/Walvi-APP---Edificate-Inteligente?node-id=5897-11184&t=MbYXTevtHjInQ9dh-4 | Q19: Confirmado documental | R19: Pendiente
A20: M4-V16 | B20: OD-01 · Método y captura | C20: Registro manual de deuda informal | D20: Usuario registra préstamo/deuda informal | E20: Usar variante manual con identificación, saldo y datos de compromiso/frecuencia según uso; lenguaje neutral. | F20: M4-HU-004 | G20: CA1-CA3 | H20: M4-RN-011 / M4-RN-010 | I20: BDD v1.0 / Documento v1.0 | J20: S2/S3/S4/S6 | K20: S2 – Walvy_Modulo4_Fase2_Matriz_Pantallas_Modales_Acciones_v1_0: Pantallas núcleo/condicionadas, estados, modales, acciones, componentes, fallback y criterios por pantalla. S3 – Walvy_Modulo4_Fase3_Reglas_Contextuales_Severidad_v1_0: Gatillos, severidad S0-S4, activación, transiciones, recomendaciones y guardrails. S4 – Walvy_Modulo4_Fase3_Anexo_BDD_Reglas_Productivas_v1_0: Parámetros MVP, fórmulas, entidades, campos, estados, enums, vigencia y reglas implementables. S6 – Walvy_Modulo4_Fase4_COPY_UX_v1_0: Títulos, bajadas, CTA, mensajes de fallback, estimaciones y guardrails de lenguaje. | L20: CP-M4-016 | M20: Pendiente de evidencia QA ejecutada | N20: Pendiente | O20: M4 · Nodo maestro 5897:11184 | P20: https://www.figma.com/design/v45c4HTKnPnU0XABMa5vjY/Walvi-APP---Edificate-Inteligente?node-id=5897-11184&t=MbYXTevtHjInQ9dh-4 | Q20: Confirmado documental | R20: Pendiente
A21: M4-V17 | B21: OD-01 · Método y captura | C21: Carga de documento | D21: Usuario selecciona subir documento de deuda | E21: Procesar documento y derivar a revisión/validación; los datos extraídos no quedan confirmados automáticamente. | F21: M4-HU-005 | G21: CA1-CA3 | H21: M4-RN-005 / M4-RN-012 | I21: Documento v1.0 | J21: S2/S3 | K21: S2 – Walvy_Modulo4_Fase2_Matriz_Pantallas_Modales_Acciones_v1_0: Pantallas núcleo/condicionadas, estados, modales, acciones, componentes, fallback y criterios por pantalla. S3 – Walvy_Modulo4_Fase3_Reglas_Contextuales_Severidad_v1_0: Gatillos, severidad S0-S4, activación, transiciones, recomendaciones y guardrails. | L21: CP-M4-017 | M21: Pendiente de evidencia QA ejecutada | N21: Pendiente | O21: M4 · Nodo maestro 5897:11184 | P21: https://www.figma.com/design/v45c4HTKnPnU0XABMa5vjY/Walvi-APP---Edificate-Inteligente?node-id=5897-11184&t=MbYXTevtHjInQ9dh-4 | Q21: Confirmado documental | R21: Pendiente
A22: M4-V18 | B22: OD-01 · Método y captura | C22: Revisar deuda detectada | D22: Existe una deuda detectada previamente por documento/inferencia | E22: Abrir revisión para confirmar, corregir, completar o marcar No corresponde. | F22: M4-HU-005 / M4-HU-007 | G22: CA1-CA3 | H22: M4-RN-005 / M4-RN-014 | I22: Documento v1.0 | J22: S2/S3 | K22: S2 – Walvy_Modulo4_Fase2_Matriz_Pantallas_Modales_Acciones_v1_0: Pantallas núcleo/condicionadas, estados, modales, acciones, componentes, fallback y criterios por pantalla. S3 – Walvy_Modulo4_Fase3_Reglas_Contextuales_Severidad_v1_0: Gatillos, severidad S0-S4, activación, transiciones, recomendaciones y guardrails. | L22: CP-M4-018 | M22: Pendiente de evidencia QA ejecutada | N22: Pendiente | O22: M4 · Nodo maestro 5897:11184 | P22: https://www.figma.com/design/v45c4HTKnPnU0XABMa5vjY/Walvi-APP---Edificate-Inteligente?node-id=5897-11184&t=MbYXTevtHjInQ9dh-4 | Q22: Confirmado documental | R22: Pendiente
A23: M4-V19 | B23: OD-01 · Documento protegido | C23: Documento requiere contraseña | D23: El procesador detecta que el documento está protegido | E23: Mostrar solicitud de contraseña solo en este estado recuperable; no mostrar campo por defecto. | F23: M4-HU-006 | G23: CA1-CA3 | H23: M4-RN-008 | I23: Documento v1.0 | J23: S2 | K23: S2 – Walvy_Modulo4_Fase2_Matriz_Pantallas_Modales_Acciones_v1_0: Pantallas núcleo/condicionadas, estados, modales, acciones, componentes, fallback y criterios por pantalla. | L23: CP-M4-019 | M23: Pendiente de evidencia QA ejecutada | N23: Pendiente | O23: M4 · Nodo maestro 5897:11184 | P23: https://www.figma.com/design/v45c4HTKnPnU0XABMa5vjY/Walvi-APP---Edificate-Inteligente?node-id=5897-11184&t=MbYXTevtHjInQ9dh-4 | Q23: Confirmado documental | R23: Pendiente
A24: M4-V20 | B24: OD-01 · Documento protegido | C24: Contraseña correcta | D24: Usuario ingresa contraseña válida | E24: Continuar procesamiento y luego llevar a revisión de datos; la clave no se convierte en dato funcional de deuda. | F24: M4-HU-006 | G24: CA1-CA3 | H24: M4-RN-008 | I24: Documento v1.0 | J24: S2 | K24: S2 – Walvy_Modulo4_Fase2_Matriz_Pantallas_Modales_Acciones_v1_0: Pantallas núcleo/condicionadas, estados, modales, acciones, componentes, fallback y criterios por pantalla. | L24: CP-M4-020 | M24: Pendiente de evidencia QA ejecutada | N24: Pendiente | O24: M4 · Nodo maestro 5897:11184 | P24: https://www.figma.com/design/v45c4HTKnPnU0XABMa5vjY/Walvi-APP---Edificate-Inteligente?node-id=5897-11184&t=MbYXTevtHjInQ9dh-4 | Q24: Confirmado documental | R24: Pendiente
A25: M4-V21 | B25: OD-01 · Documento protegido | C25: Contraseña incorrecta | D25: Usuario ingresa contraseña inválida | E25: Informar error controlado y permitir reintento sin perder el flujo. | F25: M4-HU-006 | G25: CA1-CA3 | H25: M4-RN-009 | I25: Documento v1.0 | J25: S2/S6 | K25: S2 – Walvy_Modulo4_Fase2_Matriz_Pantallas_Modales_Acciones_v1_0: Pantallas núcleo/condicionadas, estados, modales, acciones, componentes, fallback y criterios por pantalla. S6 – Walvy_Modulo4_Fase4_COPY_UX_v1_0: Títulos, bajadas, CTA, mensajes de fallback, estimaciones y guardrails de lenguaje. | L25: CP-M4-021 | M25: Pendiente de evidencia QA ejecutada | N25: Pendiente | O25: M4 · Nodo maestro 5897:11184 | P25: https://www.figma.com/design/v45c4HTKnPnU0XABMa5vjY/Walvi-APP---Edificate-Inteligente?node-id=5897-11184&t=MbYXTevtHjInQ9dh-4 | Q25: Confirmado documental | R25: Pendiente
A26: M4-V22 | B26: OD-01 · Documento protegido | C26: Usuario no dispone de contraseña | D26: Documento está protegido y usuario no conoce la clave | E26: Ofrecer cargar otro documento o ingresar deuda manualmente. | F26: M4-HU-006 | G26: CA1-CA3 | H26: M4-RN-009 | I26: Documento v1.0 | J26: S2/S6 | K26: S2 – Walvy_Modulo4_Fase2_Matriz_Pantallas_Modales_Acciones_v1_0: Pantallas núcleo/condicionadas, estados, modales, acciones, componentes, fallback y criterios por pantalla. S6 – Walvy_Modulo4_Fase4_COPY_UX_v1_0: Títulos, bajadas, CTA, mensajes de fallback, estimaciones y guardrails de lenguaje. | L26: CP-M4-022 | M26: Pendiente de evidencia QA ejecutada | N26: Pendiente | O26: M4 · Nodo maestro 5897:11184 | P26: https://www.figma.com/design/v45c4HTKnPnU0XABMa5vjY/Walvi-APP---Edificate-Inteligente?node-id=5897-11184&t=MbYXTevtHjInQ9dh-4 | Q26: Confirmado documental | R26: Pendiente
A27: M4-V23 | B27: OD-01 · Documento | C27: Documento no procesable | D27: Archivo no permite extracción usable | E27: No marcar procesamiento como exitoso; ofrecer otro archivo o registro manual y dejar estado recuperable. | F27: M4-HU-005 / M4-HU-006 | G27: CA1-CA3 | H27: M4-RN-006 / M4-RN-043 | I27: Documento v1.0 | J27: S2/S6 | K27: S2 – Walvy_Modulo4_Fase2_Matriz_Pantallas_Modales_Acciones_v1_0: Pantallas núcleo/condicionadas, estados, modales, acciones, componentes, fallback y criterios por pantalla. S6 – Walvy_Modulo4_Fase4_COPY_UX_v1_0: Títulos, bajadas, CTA, mensajes de fallback, estimaciones y guardrails de lenguaje. | L27: CP-M4-023 | M27: Pendiente de evidencia QA ejecutada | N27: Pendiente | O27: M4 · Nodo maestro 5897:11184 | P27: https://www.figma.com/design/v45c4HTKnPnU0XABMa5vjY/Walvi-APP---Edificate-Inteligente?node-id=5897-11184&t=MbYXTevtHjInQ9dh-4 | Q27: Confirmado documental | R27: Pendiente
A28: M4-V24 | B28: OD-01 · Registro manual | C28: Registro básico incompleto | D28: Se informa identificación/tipo y saldo aproximado, pero faltan datos para presión | E28: Guardar como pendiente/incompleta; no habilitar evaluación de presión, RD, priorización fuerte ni cronograma con fecha. | F28: M4-HU-003 / M4-HU-007 | G28: CA1-CA3 | H28: M4-RN-007 / M4-RN-006 | I28: BDD v1.0 / Documento v1.0 | J28: S2/S4 | K28: S2 – Walvy_Modulo4_Fase2_Matriz_Pantallas_Modales_Acciones_v1_0: Pantallas núcleo/condicionadas, estados, modales, acciones, componentes, fallback y criterios por pantalla. S4 – Walvy_Modulo4_Fase3_Anexo_BDD_Reglas_Productivas_v1_0: Parámetros MVP, fórmulas, entidades, campos, estados, enums, vigencia y reglas implementables. | L28: CP-M4-024 | M28: Pendiente de evidencia QA ejecutada | N28: Pendiente | O28: M4 · Nodo maestro 5897:11184 | P28: https://www.figma.com/design/v45c4HTKnPnU0XABMa5vjY/Walvi-APP---Edificate-Inteligente?node-id=5897-11184&t=MbYXTevtHjInQ9dh-4 | Q28: Confirmado documental | R28: Pendiente
A29: M4-V25 | B29: OD-02 · Validación | C29: Datos suficientes | D29: Deuda cuenta con datos requeridos para el uso actual | E29: Permitir confirmar y continuar a evaluación/derivación según severidad. | F29: M4-HU-007 | G29: CA1-CA3 | H29: M4-RN-006 / M4-RN-033 | I29: BDD v1.0 / Documento v1.0 | J29: S2/S4 | K29: S2 – Walvy_Modulo4_Fase2_Matriz_Pantallas_Modales_Acciones_v1_0: Pantallas núcleo/condicionadas, estados, modales, acciones, componentes, fallback y criterios por pantalla. S4 – Walvy_Modulo4_Fase3_Anexo_BDD_Reglas_Productivas_v1_0: Parámetros MVP, fórmulas, entidades, campos, estados, enums, vigencia y reglas implementables. | L29: CP-M4-025 | M29: Pendiente de evidencia QA ejecutada | N29: Pendiente | O29: M4 · Nodo maestro 5897:11184 | P29: https://www.figma.com/design/v45c4HTKnPnU0XABMa5vjY/Walvi-APP---Edificate-Inteligente?node-id=5897-11184&t=MbYXTevtHjInQ9dh-4 | Q29: Confirmado documental | R29: Pendiente
A30: M4-V26 | B30: OD-02 · Validación | C30: Datos faltantes | D30: Falta uno o más datos críticos | E30: Mostrar faltantes y solicitar solo lo necesario; mantener estado pendiente/S0 cuando corresponda. | F30: M4-HU-007 | G30: CA1-CA3 | H30: M4-RN-006 / M4-RN-017 | I30: BDD v1.0 / Documento v1.0 | J30: S2/S3/S4 | K30: S2 – Walvy_Modulo4_Fase2_Matriz_Pantallas_Modales_Acciones_v1_0: Pantallas núcleo/condicionadas, estados, modales, acciones, componentes, fallback y criterios por pantalla. S3 – Walvy_Modulo4_Fase3_Reglas_Contextuales_Severidad_v1_0: Gatillos, severidad S0-S4, activación, transiciones, recomendaciones y guardrails. S4 – Walvy_Modulo4_Fase3_Anexo_BDD_Reglas_Productivas_v1_0: Parámetros MVP, fórmulas, entidades, campos, estados, enums, vigencia y reglas implementables. | L30: CP-M4-026 | M30: Pendiente de evidencia QA ejecutada | N30: Pendiente | O30: M4 · Nodo maestro 5897:11184 | P30: https://www.figma.com/design/v45c4HTKnPnU0XABMa5vjY/Walvi-APP---Edificate-Inteligente?node-id=5897-11184&t=MbYXTevtHjInQ9dh-4 | Q30: Confirmado documental | R30: Pendiente
... A44: M4-V40 | B44: OD-03 · Deuda con deuda | C44: Caso puntual confirmado | D44: Uso puntual confirmado de deuda para pagar otra deuda | E44: Evaluar como señal fuerte, típicamente S3 según contexto, y revisar elegibilidad de RD. | F44: M4-HU-027 / M4-HU-013 | G44: CA1-CA3 | H44: M4-RN-019 | I44: BDD v1.0 / Documento v1.0 | J44: S3/S4 | K44: S3 – Walvy_Modulo4_Fase3_Reglas_Contextuales_Severidad_v1_0: Gatillos, severidad S0-S4, activación, transiciones, recomendaciones y guardrails. S4 – Walvy_Modulo4_Fase3_Anexo_BDD_Reglas_Productivas_v1_0: Parámetros MVP, fórmulas, entidades, campos, estados, enums, vigencia y reglas implementables. | L44: CP-M4-040 | M44: Pendiente de evidencia QA ejecutada | N44: Pendiente | O44: M4 · Nodo maestro 5897:11184 | P44: https://www.figma.com/design/v45c4HTKnPnU0XABMa5vjY/Walvi-APP---Edificate-Inteligente?node-id=5897-11184&t=MbYXTevtHjInQ9dh-4 | Q44: Confirmado documental | R44: Pendiente
A45: M4-V41 | B45: OD-03 · Deuda con deuda | C45: Caso recurrente/persistente confirmado | D45: Uso recurrente/persistente de deuda para pagar otra deuda | E45: Escalar a S4 y priorizar revisión/RD si se cumplen datos mínimos. | F45: M4-HU-027 / M4-HU-014 | G45: CA1-CA3 | H45: M4-RN-019 / M4-RN-004 | I45: BDD v1.0 / Documento v1.0 | J45: S3/S4 | K45: S3 – Walvy_Modulo4_Fase3_Reglas_Contextuales_Severidad_v1_0: Gatillos, severidad S0-S4, activación, transiciones, recomendaciones y guardrails. S4 – Walvy_Modulo4_Fase3_Anexo_BDD_Reglas_Productivas_v1_0: Parámetros MVP, fórmulas, entidades, campos, estados, enums, vigencia y reglas implementables. | L45: CP-M4-041 | M45: Pendiente de evidencia QA ejecutada | N45: Pendiente | O45: M4 · Nodo maestro 5897:11184 | P45: https://www.figma.com/design/v45c4HTKnPnU0XABMa5vjY/Walvi-APP---Edificate-Inteligente?node-id=5897-11184&t=MbYXTevtHjInQ9dh-4 | Q45: Confirmado documental / decisión pendiente | R45: Pendiente | T45: PD-M4-03
A46: M4-V42 | B46: OD-03 · Avance/liquidez | C46: Avance puntual justificable y pagable | D46: Uso puntual de crédito/avance con capacidad de pago | E46: Mantener seguimiento/Detalle; severidad preventiva según evidencia, sin RD automática. | F46: M4-HU-027 / M4-HU-012 | G46: CA1-CA3 | H46: M4-RN-020 | I46: BDD v1.0 / Documento v1.0 | J46: S3/S4 | K46: S3 – Walvy_Modulo4_Fase3_Reglas_Contextuales_Severidad_v1_0: Gatillos, severidad S0-S4, activación, transiciones, recomendaciones y guardrails. S4 – Walvy_Modulo4_Fase3_Anexo_BDD_Reglas_Productivas_v1_0: Parámetros MVP, fórmulas, entidades, campos, estados, enums, vigencia y reglas implementables. | L46: CP-M4-042 | M46: Pendiente de evidencia QA ejecutada | N46: Pendiente | O46: M4 · Nodo maestro 5897:11184 | P46: https://www.figma.com/design/v45c4HTKnPnU0XABMa5vjY/Walvi-APP---Edificate-Inteligente?node-id=5897-11184&t=MbYXTevtHjInQ9dh-4 | Q46: Confirmado documental | R46: Pendiente
A47: M4-V43 | B47: OD-03 · Avance/liquidez | C47: Avance regular para gasto del mes | D47: Uso regular de avance/crédito para cubrir liquidez mensual | E47: Evaluar presión y posible S3; recomendar revisión/RD condicionada al gate. | F47: M4-HU-027 / M4-HU-013 | G47: CA1-CA3 | H47: M4-RN-020 / M4-RN-004 | I47: BDD v1.0 / Documento v1.0 | J47: S3/S4 | K47: S3 – Walvy_Modulo4_Fase3_Reglas_Contextuales_Severidad_v1_0: Gatillos, severidad S0-S4, activación, transiciones, recomendaciones y guardrails. S4 – Walvy_Modulo4_Fase3_Anexo_BDD_Reglas_Productivas_v1_0: Parámetros MVP, fórmulas, entidades, campos, estados, enums, vigencia y reglas implementables. | L47: CP-M4-043 | M47: Pendiente de evidencia QA ejecutada | N47: Pendiente | O47: M4 · Nodo maestro 5897:11184 | P47: https://www.figma.com/design/v45c4HTKnPnU0XABMa5vjY/Walvi-APP---Edificate-Inteligente?node-id=5897-11184&t=MbYXTevtHjInQ9dh-4 | Q47: Confirmado documental / decisión pendiente | R47: Pendiente | T47: PD-M4-03
A48: M4-V44 | B48: OD-03 · Avance/liquidez | C48: Avance recurrente o para pagar otra deuda | D48: Uso recurrente/persistente o deuda-con-deuda confirmada | E48: Escalar severidad, pudiendo llegar a S4, y priorizar RD si se cumplen mínimos. | F48: M4-HU-027 / M4-HU-014 | G48: CA1-CA3 | H48: M4-RN-019 / M4-RN-020 | I48: BDD v1.0 / Documento v1.0 | J48: S3/S4 | K48: S3 – Walvy_Modulo4_Fase3_Reglas_Contextuales_Severidad_v1_0: Gatillos, severidad S0-S4, activación, transiciones, recomendaciones y guardrails. S4 – Walvy_Modulo4_Fase3_Anexo_BDD_Reglas_Productivas_v1_0: Parámetros MVP, fórmulas, entidades, campos, estados, enums, vigencia y reglas implementables. | L48: CP-M4-044 | M48: Pendiente de evidencia QA ejecutada | N48: Pendiente | O48: M4 · Nodo maestro 5897:11184 | P48: https://www.figma.com/design/v45c4HTKnPnU0XABMa5vjY/Walvi-APP---Edificate-Inteligente?node-id=5897-11184&t=MbYXTevtHjInQ9dh-4 | Q48: Confirmado documental / decisión pendiente | R48: Pendiente | T48: PD-M4-03
A49: M4-V45 | B49: OD-03 · Muchas cuotas | C49: Muchas cuotas con holgura suficiente | D49: Cumple condición de acumulación, pero mantiene balance/holgura aceptable | E49: Mostrar señal preventiva/seguimiento; no activar Ruta Despeje por este hecho solo. | F49: M4-HU-026 | G49: CA1-CA3 | H49: M4-RN-022 / M4-RN-023 / M4-RN-037 / R-TC-008 | I49: BDD v1.0 / Documento v1.0 | J49: S2/S3/S4 | K49: S2 – Walvy_Modulo4_Fase2_Matriz_Pantallas_Modales_Acciones_v1_0: Pantallas núcleo/condicionadas, estados, modales, acciones, componentes, fallback y criterios por pantalla. S3 – Walvy_Modulo4_Fase3_Reglas_Contextuales_Severidad_v1_0: Gatillos, severidad S0-S4, activación, transiciones, recomendaciones y guardrails. S4 – Walvy_Modulo4_Fase3_Anexo_BDD_Reglas_Productivas_v1_0: Parámetros MVP, fórmulas, entidades, campos, estados, enums, vigencia y reglas implementables. | L49: CP-M4-045 | M49: Pendiente de evidencia QA ejecutada | N49: Pendiente | O49: M4 · Nodo maestro 5897:11184 | P49: https://www.figma.com/design/v45c4HTKnPnU0XABMa5vjY/Walvi-APP---Edificate-Inteligente?node-id=5897-11184&t=MbYXTevtHjInQ9dh-4 | Q49: Confirmado documental / decisión pendiente | R49: Pendiente | T49: PD-M4-02
A50: M4-V46 | B50: OD-03 · Muchas cuotas | C50: Muchas cuotas + holgura baja | D50: Cumple umbral de cuotas y la holgura está bajo el umbral productivo | E50: Clasificar como requiere atención/S2 y revisar compromisos. | F50: M4-HU-026 / M4-HU-013 | G50: CA1-CA3 | H50: M4-RN-022 / M4-RN-023 / M4-RN-025 | I50: BDD v1.0 / Documento v1.0 | J50: S2/S3/S4 | K50: S2 – Walvy_Modulo4_Fase2_Matriz_Pantallas_Modales_Acciones_v1_0: Pantallas núcleo/condicionadas, estados, modales, acciones, componentes, fallback y criterios por pantalla. S3 – Walvy_Modulo4_Fase3_Reglas_Contextuales_Severidad_v1_0: Gatillos, severidad S0-S4, activación, transiciones, recomendaciones y guardrails. S4 – Walvy_Modulo4_Fase3_Anexo_BDD_Reglas_Productivas_v1_0: Parámetros MVP, fórmulas, entidades, campos, estados, enums, vigencia y reglas implementables. | L50: CP-M4-046 | M50: Pendiente de evidencia QA ejecutada | N50: Pendiente | O50: M4 · Nodo maestro 5897:11184 | P50: https://www.figma.com/design/v45c4HTKnPnU0XABMa5vjY/Walvi-APP---Edificate-Inteligente?node-id=5897-11184&t=MbYXTevtHjInQ9dh-4 | Q50: Confirmado documental / decisión pendiente | R50: Pendiente | T50: PD-M4-02
A51: M4-V47 | B51: OD-03 · Muchas cuotas | C51: Muchas cuotas + incapacidad/saldo negativo | D51: Acumulación de cuotas con saldo negativo o incapacidad de cubrir compromisos | E51: Escalar a S3 según evidencia y evaluar Ruta Despeje si cumple gate. | F51: M4-HU-026 / M4-HU-013 | G51: CA1-CA3 | H51: M4-RN-022 / M4-RN-017 | I51: Documento v1.0 | J51: S2/S3 | K51: S2 – Walvy_Modulo4_Fase2_Matriz_Pantallas_Modales_Acciones_v1_0: Pantallas núcleo/condicionadas, estados, modales, acciones, componentes, fallback y criterios por pantalla. S3 – Walvy_Modulo4_Fase3_Reglas_Contextuales_Severidad_v1_0: Gatillos, severidad S0-S4, activación, transiciones, recomendaciones y guardrails. | L51: CP-M4-047 | M51: Pendiente de evidencia QA ejecutada | N51: Pendiente | O51: M4 · Nodo maestro 5897:11184 | P51: https://www.figma.com/design/v45c4HTKnPnU0XABMa5vjY/Walvi-APP---Edificate-Inteligente?node-id=5897-11184&t=MbYXTevtHjInQ9dh-4 | Q51: Confirmado documental | R51: Pendiente
A52: M4-V48 | B52: OD-03 · Muchas cuotas | C52: Muchas cuotas + presión recurrente | D52: Acumulación con mora, mínimo recurrente, saldo negativo recurrente o deuda-con-deuda | E52: Escalar a S4 según evidencia y priorizar RD si se cumplen mínimos. | F52: M4-HU-026 / M4-HU-014 | G52: CA1-CA3 | H52: M4-RN-022 / M4-RN-017 | I52: BDD v1.0 / Documento v1.0 | J52: S2/S3/S4 | K52: S2 – Walvy_Modulo4_Fase2_Matriz_Pantallas_Modales_Acciones_v1_0: Pantallas núcleo/condicionadas, estados, modales, acciones, componentes, fallback y criterios por pantalla. S3 – Walvy_Modulo4_Fase3_Reglas_Contextuales_Severidad_v1_0: Gatillos, severidad S0-S4, activación, transiciones, recomendaciones y guardrails. S4 – Walvy_Modulo4_Fase3_Anexo_BDD_Reglas_Productivas_v1_0: Parámetros MVP, fórmulas, entidades, campos, estados, enums, vigencia y reglas implementables. | L52: CP-M4-048 | M52: Pendiente de evidencia QA ejecutada | N52: Pendiente | O52: M4 · Nodo maestro 5897:11184 | P52: https://www.figma.com/design/v45c4HTKnPnU0XABMa5vjY/Walvi-APP---Edificate-Inteligente?node-id=5897-11184&t=MbYXTevtHjInQ9dh-4 | Q52: Confirmado documental / decisión pendiente | R52: Pendiente | T52: PD-M4-03
A53: M4-V49 | B53: OD-03 · Vencimiento | C53: Vencimiento crítico con capacidad | D53: Fecha relevante con capacidad de pago y sin mora confirmada | E53: Mantener S1/S2 y gestionar alerta/revisión; no activar RD por fecha solamente. | F53: M4-HU-025 / M4-HU-013 | G53: CA1-CA3 | H53: M4-RN-021 / M4-RN-043 | I53: Documento v1.0 | J53: S2/S3 | K53: S2 – Walvy_Modulo4_Fase2_Matriz_Pantallas_Modales_Acciones_v1_0: Pantallas núcleo/condicionadas, estados, modales, acciones, componentes, fallback y criterios por pantalla. S3 – Walvy_Modulo4_Fase3_Reglas_Contextuales_Severidad_v1_0: Gatillos, severidad S0-S4, activación, transiciones, recomendaciones y guardrails. | L53: CP-M4-049 | M53: Pendiente de evidencia QA ejecutada | N53: Pendiente | O53: M4 · Nodo maestro 5897:11184 | P53: https://www.figma.com/design/v45c4HTKnPnU0XABMa5vjY/Walvi-APP---Edificate-Inteligente?node-id=5897-11184&t=MbYXTevtHjInQ9dh-4 | Q53: Confirmado documental / decisión pendiente | R53: Pendiente | T53: PD-M4-04 / PD-M4-07
A54: M4-V50 | B54: OD-03 · Vencimiento | C54: Vencimiento crítico sin capacidad | D54: Fecha relevante sin capacidad clara o con señal de presión | E54: Elevar evaluación a S3 según evidencia; RD sigue su gate de confirmación y mínimos. | F54: M4-HU-025 / M4-HU-014 | G54: CA1-CA3 | H54: M4-RN-021 / M4-RN-004 | I54: Documento v1.0 | J54: S2/S3 | K54: S2 – Walvy_Modulo4_Fase2_Matriz_Pantallas_Modales_Acciones_v1_0: Pantallas núcleo/condicionadas, estados, modales, acciones, componentes, fallback y criterios por pantalla. S3 – Walvy_Modulo4_Fase3_Reglas_Contextuales_Severidad_v1_0: Gatillos, severidad S0-S4, activación, transiciones, recomendaciones y guardrails. | L54: CP-M4-050 | M54: Pendiente de evidencia QA ejecutada | N54: Pendiente | O54: M4 · Nodo maestro 5897:11184 | P54: https://www.figma.com/design/v45c4HTKnPnU0XABMa5vjY/Walvi-APP---Edificate-Inteligente?node-id=5897-11184&t=MbYXTevtHjInQ9dh-4 | Q54: Confirmado documental / decisión pendiente | R54: Pendiente | T54: PD-M4-04
...

Sheet Historias y CA
A1: WALVY | M4 – Historias de Usuario y Criterios de Aceptación
A3: ID | B3: Historia | C3: Redacción | D3: Criterios de aceptación
A4: M4-HU-001 | B4: Acceder desde Perfil Financiero | C4: Como usuario, quiero acceder al tratamiento de deuda desde Perfil Financiero según mi estado, para completar, revisar o avanzar sin convertir Perfil en el módulo de deuda. | D4: CA1. Perfil muestra estado/señal/acción contextual y no ejecuta la Ruta Despeje completa. CA2. La derivación depende de confirmación, completitud y severidad. CA3. Si no corresponde deuda, se mantiene el flujo principal de Perfil.
A5: M4-HU-002 | B5: Recibir acción contextual desde Home | C5: Como usuario que vuelve a Home, quiero recibir una acción de deuda solo cuando sea relevante para mi mes, para mantener una única prioridad operativa. | D5: CA1. Si deuda no es señal dominante, Home no fuerza CTA principal de deuda. CA2. Si deuda domina, deriva según confirmación, datos y gatillo. CA3. Home actúa como superficie consumidora, no como panel de deuda.
A6: M4-HU-003 | B6: Registrar deuda manual | C6: Como usuario, quiero registrar una deuda desde cero, para incorporarla aunque aún no tenga todos los datos. | D6: CA1. Puede guardarse información básica como pendiente/incompleta. CA2. La falta de datos no bloquea el registro inicial. CA3. Sin mínimos no se evalúa presión ni se activa Ruta Despeje completa.
A7: M4-HU-004 | B7: Registrar deuda informal | C7: Como usuario, quiero registrar una deuda informal o préstamo personal, para incluir compromisos que no provienen de una institución financiera. | D7: CA1. Se captura con variante manual y lenguaje no estigmatizante. CA2. Para presión se requiere compromiso mensual/frecuencia y confirmación. CA3. Si está incompleta queda pendiente y no genera conclusiones fuertes.
A8: M4-HU-005 | B8: Cargar documento de deuda | C8: Como usuario, quiero cargar un documento de deuda, para que el sistema lea información y me permita revisarla antes de usarla. | D8: CA1. La carga puede detectar una o varias deudas. CA2. El dato extraído queda sujeto a revisión/confirmación individual. CA3. Un documento no usable ofrece alternativa manual u otro archivo.
A9: M4-HU-006 | B9: Resolver documento protegido o no procesable | C9: Como usuario, quiero recibir una salida recuperable cuando un documento requiere clave o no puede procesarse, para continuar por otra vía. | D9: CA1. La clave se solicita solo si el documento se detecta protegido. CA2. Clave incorrecta permite reintento; sin clave ofrece otra carga/manual. CA3. Un documento no procesable no se marca como procesado exitosamente.
A10: M4-HU-007 | B10: Validar y completar deuda | C10: Como usuario, quiero revisar los datos de una deuda y completar lo faltante, para decidir si puedo evaluarla. | D10: CA1. Se distinguen dato suficiente, faltante, desactualizado y baja confianza. CA2. Se solicitan solo datos críticos necesarios según el uso. CA3. Deuda no confirmada o incompleta no habilita conclusiones fuertes.
A11: M4-HU-008 | B11: Revisar posible duplicado | C11: Como usuario, quiero revisar deudas posiblemente duplicadas, para evitar consolidaciones automáticas incorrectas. | D11: CA1. El sistema puede marcar posible duplicado. CA2. No se fusionan deudas automáticamente. CA3. El usuario puede confirmar/corregir/descartar según corresponda.
A12: M4-HU-009 | B12: Revisar múltiples deudas de un documento | C12: Como usuario, quiero revisar individualmente las deudas obtenidas desde un documento con múltiples registros, para confirmar cuáles me corresponden. | D12: CA1. Cada deuda mantiene estado individual. CA2. Cada deuda requiere confirmación individual antes de afectar Salud de Deuda. CA3. El lote puede quedar pendiente sin bloquear las demás rutas.
A13: M4-HU-010 | B13: Descartar deuda no reconocida | C13: Como usuario, quiero marcar una deuda como No corresponde/No reconozco, para que no afecte mi diagnóstico. | D13: CA1. La deuda descartada no afecta Salud de Deuda. CA2. No activa Ruta Despeje. CA3. La fuente/historial se conserva con trazabilidad según criterio técnico.
A14: M4-HU-011 | B14: Obtener resultado y derivación | C14: Como usuario, quiero que el resultado de validación me dirija a seguimiento, Perfil o Ruta Despeje, para continuar según mi situación. | D14: CA1. La salida depende de confirmación, datos mínimos y severidad. CA2. Deuda manejable deriva a seguimiento/Perfil. CA3. Ruta Despeje completa solo se activa cuando se cumplen sus condiciones.
... A30: M4-HU-027 | B30: Evaluar deuda con deuda y avances | C30: Como usuario, quiero que el uso de nueva deuda para sostener liquidez o pagar otra deuda se evalúe por frecuencia y evidencia, para detectar presión real. | D30: CA1. Uso puntual puede tener severidad menor según capacidad. CA2. Uso regular/recurrente escala severidad. CA3. Deuda con deuda confirmada y recurrente puede llegar a S4.

Sheet Reglas de Negocio
A1: WALVY | M4 – Matriz consolidada de Reglas de Negocio
A3: ID | B3: Nombre / Grupo | C3: Regla | D3: Estado / Origen | E3: Código fuente RN | F3: Descripción fuente RN
A4: M4-RN-001 | B4: Superficies consumidoras | C4: Perfil Financiero y Home consumen señales/estados de M4, pero no ejecutan el flujo completo del módulo. | D4: Documentado v1.0 | E4: S1/S2/S9 | F4: S1 – Walvy_Modulo4_Fase1_Flujo_Funcional_v1_0: Activación, entradas, validación, derivación, bloqueos, dependencias y datos mínimos. S2 – Walvy_Modulo4_Fase2_Matriz_Pantallas_Modales_Acciones_v1_0: Pantallas núcleo/condicionadas, estados, modales, acciones, componentes, fallback y criterios por pantalla. S9 – Indicaciones paquete documental Modulo 4: Orden de lectura, autoridad documental por área y criterios importantes para desarrollo.
A5: M4-RN-002 | B5: Home prioriza deuda solo si domina | C5: Home no debe forzar una acción principal de deuda cuando la deuda no es señal dominante del mes. | D5: Documentado v1.0 | E5: S1/S2 | F5: S1 – Walvy_Modulo4_Fase1_Flujo_Funcional_v1_0: Activación, entradas, validación, derivación, bloqueos, dependencias y datos mínimos. S2 – Walvy_Modulo4_Fase2_Matriz_Pantallas_Modales_Acciones_v1_0: Pantallas núcleo/condicionadas, estados, modales, acciones, componentes, fallback y criterios por pantalla.
A6: M4-RN-003 | B6: Onboarding reutilizable | C6: Onboarding de Deudas es la ruta guiada reutilizable para registrar, validar o completar información; no se crean formularios paralelos por superficie. | D6: Documentado v1.0 | E6: S1/S2 | F6: S1 – Walvy_Modulo4_Fase1_Flujo_Funcional_v1_0: Activación, entradas, validación, derivación, bloqueos, dependencias y datos mínimos. S2 – Walvy_Modulo4_Fase2_Matriz_Pantallas_Modales_Acciones_v1_0: Pantallas núcleo/condicionadas, estados, modales, acciones, componentes, fallback y criterios por pantalla.
A7: M4-RN-004 | B7: Gate Ruta Despeje completa | C7: Ruta Despeje completa exige deuda confirmada, gatillo suficiente/presión y datos mínimos completos. | D7: Documentado v1.0 | E7: S1/S2/S3/S4/S9 | F7: S1 – Walvy_Modulo4_Fase1_Flujo_Funcional_v1_0: Activación, entradas, validación, derivación, bloqueos, dependencias y datos mínimos. S2 – Walvy_Modulo4_Fase2_Matriz_Pantallas_Modales_Acciones_v1_0: Pantallas núcleo/condicionadas, estados, modales, acciones, componentes, fallback y criterios por pantalla. S3 – Walvy_Modulo4_Fase3_Reglas_Contextuales_Severidad_v1_0: Gatillos, severidad S0-S4, activación, transiciones, recomendaciones y guardrails. S4 – Walvy_Modulo4_Fase3_Anexo_BDD_Reglas_Productivas_v1_0: Parámetros MVP, fórmulas, entidades, campos, estados, enums, vigencia y reglas implementables. S9 – Indicaciones paquete documental Modulo 4: Orden de lectura, autoridad documental por área y criterios importantes para desarrollo.
A8: M4-RN-005 | B8: Deuda no confirmada no impacta Salud | C8: Deuda detectada, inferida o leída desde documento no afecta Salud de Deuda ni activa Ruta Despeje completa sin confirmación individual. | D8: Documentado v1.0 | E8: S2/S3/S9 | F8: S2 – Walvy_Modulo4_Fase2_Matriz_Pantallas_Modales_Acciones_v1_0: Pantallas núcleo/condicionadas, estados, modales, acciones, componentes, fallback y criterios por pantalla. S3 – Walvy_Modulo4_Fase3_Reglas_Contextuales_Severidad_v1_0: Gatillos, severidad S0-S4, activación, transiciones, recomendaciones y guardrails. S9 – Indicaciones paquete documental Modulo 4: Orden de lectura, autoridad documental por área y criterios importantes para desarrollo.
A9: M4-RN-006 | B9: Datos mínimos por uso | C9: La falta de datos puede permitir registro inicial, pero bloquea evaluación de presión, Ruta Despeje completa, priorización fuerte, simulación fuerte y cronograma con fecha. | D9: Documentado v1.0 | E9: S1/S2/S4 | F9: S1 – Walvy_Modulo4_Fase1_Flujo_Funcional_v1_0: Activación, entradas, validación, derivación, bloqueos, dependencias y datos mínimos. S2 – Walvy_Modulo4_Fase2_Matriz_Pantallas_Modales_Acciones_v1_0: Pantallas núcleo/condicionadas, estados, modales, acciones, componentes, fallback y criterios por pantalla. S4 – Walvy_Modulo4_Fase3_Anexo_BDD_Reglas_Productivas_v1_0: Parámetros MVP, fórmulas, entidades, campos, estados, enums, vigencia y reglas implementables.
A10: M4-RN-007 | B10: Registro pendiente permitido | C10: Una deuda manual puede guardarse pendiente/incompleta sin quedar lista para evaluación o priorización. | D10: Documentado v1.0 | E10: S2/S4 | F10: S2 – Walvy_Modulo4_Fase2_Matriz_Pantallas_Modales_Acciones_v1_0: Pantallas núcleo/condicionadas, estados, modales, acciones, componentes, fallback y criterios por pantalla. S4 – Walvy_Modulo4_Fase3_Anexo_BDD_Reglas_Productivas_v1_0: Parámetros MVP, fórmulas, entidades, campos, estados, enums, vigencia y reglas implementables.
A11: M4-RN-008 | B11: Clave solo si documento protegido | C11: El campo de contraseña se presenta solo cuando el sistema detecta que el documento está protegido. | D11: Documentado v1.0 | E11: S2 | F11: S2 – Walvy_Modulo4_Fase2_Matriz_Pantallas_Modales_Acciones_v1_0: Pantallas núcleo/condicionadas, estados, modales, acciones, componentes, fallback y criterios por pantalla.
A12: M4-RN-009 | B12: Fallback documento protegido | C12: Si la clave es incorrecta se permite reintento; si el usuario no la tiene, debe poder cargar otro documento o ingresar datos manualmente. | D12: Documentado v1.0 | E12: S2/S6 | F12: S2 – Walvy_Modulo4_Fase2_Matriz_Pantallas_Modales_Acciones_v1_0: Pantallas núcleo/condicionadas, estados, modales, acciones, componentes, fallback y criterios por pantalla. S6 – Walvy_Modulo4_Fase4_COPY_UX_v1_0: Títulos, bajadas, CTA, mensajes de fallback, estimaciones y guardrails de lenguaje.
A13: M4-RN-010 | B13: Carga manual es variante | C13: La carga manual no crea una pantalla núcleo adicional; se resuelve como variante de OD-01 o subestado de OD-02. | D13: Documentado v1.0 | E13: S2 | F13: S2 – Walvy_Modulo4_Fase2_Matriz_Pantallas_Modales_Acciones_v1_0: Pantallas núcleo/condicionadas, estados, modales, acciones, componentes, fallback y criterios por pantalla.
A14: M4-RN-011 | B14: Deuda informal sin estigma | C14: La deuda informal se registra/evalúa con lenguaje neutral y requiere datos suficientes para medir presión. | D14: Documentado v1.0 | E14: S2/S3/S6 | F14: S2 – Walvy_Modulo4_Fase2_Matriz_Pantallas_Modales_Acciones_v1_0: Pantallas núcleo/condicionadas, estados, modales, acciones, componentes, fallback y criterios por pantalla. S3 – Walvy_Modulo4_Fase3_Reglas_Contextuales_Severidad_v1_0: Gatillos, severidad S0-S4, activación, transiciones, recomendaciones y guardrails. S6 – Walvy_Modulo4_Fase4_COPY_UX_v1_0: Títulos, bajadas, CTA, mensajes de fallback, estimaciones y guardrails de lenguaje.
... A61: M4-RN-050 | B61: Dominancia de señales y bloqueo S0 | C61: Si una misma deuda presenta varias señales, se usa el estado/severidad dominante y las señales secundarias solo aportan contexto. Si falta confirmación o un dato crítico, S0 bloquea una conclusión fuerte y la activación de Ruta Despeje. | D61: Documentado v1.0 | E61: S2/S3 | F61: S2 – Walvy_Modulo4_Fase2_Matriz_Pantallas_Modales_Acciones_v1_0: Pantallas núcleo/condicionadas, estados, modales, acciones, componentes, fallback y criterios por pantalla. S3 – Walvy_Modulo4_Fase3_Reglas_Contextuales_Severidad_v1_0: Gatillos, severidad S0-S4, activación, transiciones, recomendaciones y guardrails.

Sheet Fuentes
A1: WALVY | M4 – Fuentes documentales utilizadas
A3: Código | B3: Fuente | C3: Tipo | D3: Uso / cobertura | E3: URL / referencia
A4: S1 | B4: Walvy_Modulo4_Fase1_Flujo_Funcional_v1_0 | C4: Flujo funcional | D4: Activación, entradas, validación, derivación, bloqueos, dependencias y datos mínimos. | E4: https://docs.google.com/document/d/1OdP-9JxAPmYMAx8FYlb7jmkzMGsYy4W3/edit
A5: S2 | B5: Walvy_Modulo4_Fase2_Matriz_Pantallas_Modales_Acciones_v1_0 | C5: Matriz funcional/UX | D5: Pantallas núcleo/condicionadas, estados, modales, acciones, componentes, fallback y criterios por pantalla. | E5: https://docs.google.com/document/d/1oZX_BEG552qxA76pZSbVsr3iKpca5i6f/edit
A6: S3 | B6: Walvy_Modulo4_Fase3_Reglas_Contextuales_Severidad_v1_0 | C6: Reglas funcionales | D6: Gatillos, severidad S0-S4, activación, transiciones, recomendaciones y guardrails. | E6: https://docs.google.com/document/d/1fxwZgDcqVa8FaYb5bwP32ITqijO1JStx/edit
A7: S4 | B7: Walvy_Modulo4_Fase3_Anexo_BDD_Reglas_Productivas_v1_0 | C7: Anexo BDD / reglas productivas | D7: Parámetros MVP, fórmulas, entidades, campos, estados, enums, vigencia y reglas implementables. | E7: https://drive.google.com/file/d/1cQWC0LGcY3_XJH5_6SClbYeq7CrUR2le/view
A8: S5 | B8: Walvy_Anexo_Transversal_TC_M04_M05_M06_v1_0 | C8: Anexo transversal TC/CMF | D8: Lectura TC/CMF, precedencia documental, pago/mora, dispatch M04-M06 y reglas R-TC/R-CMF. | E8: https://docs.google.com/document/d/1PzSuKzyTy2CiWfk4HoHtfoHe1A1pnAMo/edit
A9: S6 | B9: Walvy_Modulo4_Fase4_COPY_UX_v1_0 | C9: Copy UX | D9: Títulos, bajadas, CTA, mensajes de fallback, estimaciones y guardrails de lenguaje. | E9: https://drive.google.com/file/d/1z5RPnxKZQwLcPvjk8b3wJlhBEl263Pzw/view
A10: S7 | B10: Walvy_Modulo4_Fase5_Briefing_UX_v1_0 | C10: Briefing UX | D10: Restricciones visuales, requerimientos por pantalla, mobile-first y criterios de aceptación UX. | E10: https://drive.google.com/file/d/18vJ4OJ8AZ5z-gZfXPinElhcpGFHxoU9y/view
A11: S8 | B11: Walvy_Modulo4_Consolidado_Final_Diagramas_Matrices_v1_0 | C11: Consolidado | D11: Lectura integrada: diagramas, inventario, reglas principales, dependencias, fallback y relación entre fases. | E11: https://drive.google.com/file/d/1EwgU4VAZHMRuucY1k9sl2gFPkqwvN13C/view
A12: S9 | B12: Indicaciones paquete documental Modulo 4 | C12: Rector de paquete | D12: Orden de lectura, autoridad documental por área y criterios importantes para desarrollo. | E12: https://docs.google.com/document/d/17C8z8Hb3OX9YNa-L7UgdYPGEJWJYjb_YDcsZ_nfmCVI/edit
A13: S10 | B13: Walvy_Modulo4_informe_deudas_CMF_usuario_x_pepito.xlsx | C13: Ejemplo / dato de prueba | D13: Ejemplo de informe de deudas CMF. Se usa como referencia de datos, no como fuente normativa de RN. | E13: https://docs.google.com/spreadsheets/d/1BRgCtToIzzJnclwkXYoEIl2bKLMduZuV/edit
A14: S11 | B14: Figma · Walvi APP - Edificate Inteligente · Nodo M4 5897:11184 | C14: Diseño UX/UI | D14: Nodo maestro oficial del Módulo 4. Se usa como referencia macro de diseño para las variantes; el mapeo a subnodos específicos queda sujeto a identificación explícita. | E14: https://www.figma.com/design/v45c4HTKnPnU0XABMa5vjY/Walvi-APP---Edificate-Inteligente?node-id=5897-11184&t=MbYXTevtHjInQ9dh-4

Sheet Pendientes Cliente
A1: WALVY | M4 – Decisiones funcionales pendientes del Cliente / Producto
A2: Esta pestaña incluye únicamente definiciones, parámetros o comportamientos que la documentación M4 no cierra de forma determinista. No se inventan valores para completar la matriz. La aprobación de cada variante se registra en “Validación Cliente” de la Matriz Trazabilidad.
A4: ID Pendiente | B4: Tipo de decisión | C4: Variantes / RN afectadas | D4: Tema a definir | E4: Motivo / Fuente | F4: Nodo(s) Figma | G4: Estado decisión | H4: Decisión PO / Comentarios
A5: PD-M4-01 | B5: Producto / Finanzas | C5: M4-V64–V66 | M4-RN-024 / M4-RN-027 / M4-RN-046 | D5: Definir el monto piso configurable de buffer operacional (operational_buffer_min_amount). | E5: El Anexo BDD define fórmula y 5% inicial sobre ingreso, pero deja el monto base como piso configurable sin valor numérico. | G5: Pendiente
A6: PD-M4-02 | B6: Producto / Finanzas | C6: M4-V45–V46 | M4-RN-025 | D6: Definir el monto piso configurable usado para determinar holgura baja (low_available_space_threshold_amount). | E6: El Anexo BDD define 5% inicial sobre ingreso y un piso configurable, pero no entrega monto numérico. | G6: Pendiente
A7: PD-M4-03 | B7: Producto | C7: M4-V41 / V43–V44 / V48 / V51 / V79 | M4-RN-019 / 020 / 035 | D7: Definir la ventana exacta que distingue puntual, recurrente y persistente para señales de deuda. | E7: Los documentos usan estas frecuencias para escalar severidad, pero no fijan un número común de ciclos/meses para todos los casos. | G7: Pendiente
A8: PD-M4-04 | B8: Producto | C8: M4-V13–V14 / V49–V50 | M4-RN-021 | D8: Definir el horizonte temporal exacto para clasificar un vencimiento como “crítico”. | E8: La documentación condiciona severidad a capacidad/mora/evidencia, pero no fija un umbral uniforme de días. | G8: Pendiente
A9: PD-M4-05 | B9: Producto / Riesgo | C9: M4-V51 / V82 | R-CMF-003 | D9: Definir el mapeo exacto de tramos de mora CMF hacia severidad S0–S4, si Producto requiere una tabla determinista. | E9: El anexo establece que tramos superiores escalan severidad y evita asumir equivalencias externas no validadas, pero no entrega tabla S por tramo. | G9: Pendiente
A10: PD-M4-06 | B10: Producto | C10: M4-V59–V60 / V67 / V70–V71 | M4-HU-016 / M4-RN-041 / 044 | D10: Cerrar el algoritmo final de priorización/orden de deudas dentro de Ruta Despeje y su relación con la metodología Bola de Nieve. | E10: La documentación exige orden, deuda prioritaria, supuestos y versión; el Anexo BDD no reemplaza la metodología de priorización con una fórmula completa. | G10: Pendiente
A11: PD-M4-07 | B11: Producto / Técnica | C11: M4-V13 / V49 / V54 | M4-RN-043 | D11: Confirmar qué dependencias estarán disponibles en el MVP de M4 (Alertas, Pagos, Presupuesto) y qué fallback se activa en cada caso. | E11: Fase 1/2 define fallbacks para no bloquear el flujo, pero la disponibilidad concreta por ambiente/hito no está cerrada en la carpeta M4. | G11: Pendiente
A12: PD-M4-08 | B12: Producto / UX | C12: M4-V52 / V58–V60 / V73–V74 | M4-RN-042 | D12: Confirmar resolución UX final de DD-01 y RD-03 como vistas embebidas/condicionadas y de RD-01/RD-02 como pantallas separadas o vista compacta. | E12: El nodo maestro Figma M4 5897:11184 ya está disponible. La decisión pendiente es la resolución final y, si aplica, la asociación de subnodos específicos por vista. | F12: 5897:11184 | G12: Pendiente

Sheet Resumen
A1: WALVY | M4 – Resumen de trazabilidad v1.3
A3: Indicador | B3: Valor | E3: Cómo revisar
A4: Variantes | B4: =COUNTA('Matriz Trazabilidad'!A5:A1000) -> 86 | E4: 1 | F4: Revisar HU/CA | G4: Confirmar que intención y criterios representan el comportamiento esperado.
A5: Historias de Usuario | B5: =COUNTA('Historias y CA'!A4:A1000) -> 27 | E5: 2 | F5: Revisar RN | G5: Ratificar reglas y especialmente las asociadas a Pendientes Cliente.
A6: Reglas de Negocio | B6: =COUNTA('Reglas de Negocio'!A4:A1000) -> 58 | E6: 3 | F6: Revisar variante | G6: Aprobar, ajustar, excluir o pedir análisis por escenario.
A7: Variantes con evidencia Passed | B7: =COUNTIF('Matriz Trazabilidad'!N5:N1000,"Passed") -> 0 | E7: 4 | F7: Revisar CP/Evidencia | G7: Vincular evidencia real cuando se ejecute la validación correspondiente.
A8: Variantes con evidencia pendiente | B8: =COUNTIF('Matriz Trazabilidad'!N5:N1000,"Pendiente") -> 86
A9: Puntos de decisión Cliente/Producto | B9: =COUNTIF('Pendientes Cliente'!G5:G100,"Pendiente") -> 8
A11: Los códigos S1–S11 identifican artefactos fuente del paquete M4. Los IDs M4-RN/HU/CP son identificadores de consolidación para revisión de Producto y deben ratificarse junto con el alcance funcional.
A12: Métrica de revisión del Cliente | E12: Decisiones funcionales pendientes
A13: Estado de validación | B13: Cantidad | C13: % del total | E13: Estado decisión | F13: Cantidad | G13: % del total
A14: Aprobado | B14: =COUNTIF('Matriz Trazabilidad'!$R$5:$R$87,"Aprobado") -> 0 | C14: =IF($B$4=0,0,B14/$B$4) -> 0 | E14: Pendiente | F14: =COUNTIF('Pendientes Cliente'!$G$5:$G$23,"Pendiente") -> 8 | G14: =IF($B$9=0,0,F14/$B$9) -> 1
A15: Pendiente | B15: =COUNTIF('Matriz Trazabilidad'!R5:R1000,"Pendiente") -> 86 | C15: =IF(B4=0,0,B15/B4) -> 1 | E15: Resuelto | F15: =COUNTIF('Pendientes Cliente'!$G$5:$G$23,"Resuelto") -> 0 | G15: =IF($B$9=0,0,F15/$B$9) -> 0
A16: Ajustar | B16: =COUNTIF('Matriz Trazabilidad'!$R$5:$R$87,"Ajustar") -> 0 | C16: =IF($B$4=0,0,B16/$B$4) -> 0 | E16: Requiere análisis | F16: =COUNTIF('Pendientes Cliente'!$G$5:$G$23,"Requiere análisis") -> 0 | G16: =IF($B$9=0,0,F16/$B$9) -> 0
A17: Fuera de alcance | B17: =COUNTIF('Matriz Trazabilidad'!$R$5:$R$87,"Fuera de alcance") -> 0 | C17: =IF($B$4=0,0,B17/$B$4) -> 0 | E17: Fuera de alcance | F17: =COUNTIF('Pendientes Cliente'!$G$5:$G$23,"Fuera de alcance") -> 0 | G17: =IF($B$9=0,0,F17/$B$9) -> 0
A18: Requiere análisis | B18: =COUNTIF('Matriz Trazabilidad'!$R$5:$R$87,"Requiere análisis") -> 0 | C18: =IF($B$4=0,0,B18/$B$4) -> 0
