Workbook

Sheet 00_RESUMEN
A1: Walvy · Plan QA por fases · respuesta PMO · v1.1
A2: Solución operativa para Miguel/Kabeli. La matriz separa PASS funcional, fixture cross-contract, superficies M02/M03, E2E real y regresión final.
A4: Hallazgo rector | B4: No tratar “produce algo para otro módulo” como dependencia de entrada. Un productor puede hacer QA funcional antes y reservar la integración real para E2E.
A6: Universo actual | B6: 186 unidades contractuales vigentes = 93 Trace M04 + 34 variantes M05 + 59 variantes M06
A7: Corrección M04 | B7: M04 vigente usa TR-M04-044…136. El HTML de Miguel usa M4-Vxx; no existe crosswalk autoritativo 1:1 para V87–V93. No se fabricó ese mapeo.
A8: Propuesta Miguel | B8: El HTML declara 152 totales, pero sus propios módulos suman 186; las fases declaradas suman 159. El plan requiere reconciliación antes de operar.
A9: Qué conserva | B9: La intención: paralelizar QA. Se reemplaza la partición rígida por gates acumulativos: F1/F2/F3 son primer PASS; F4/F5 son reejecución E2E/regresión.
A10: Revisión v1.1 | B10: 23/23 excepciones revisadas: 22 aprobadas sin cambios y 1 ajustada (M5-V20). La matriz primaria de 186 casos y sus conteos permanecen sin cambio.
A12: Módulo | B12: F1 · local | C12: F2 · fixture cross | D12: F3 · M02/M03 | E12: Total | F12: Check
A13: M04 | B13: =COUNTIFS('01_MATRIZ_OPERATIVA_186'!$A:$A,$A13,'01_MATRIZ_OPERATIVA_186'!$H:$H,"F1*") | C13: =COUNTIFS('01_MATRIZ_OPERATIVA_186'!$A:$A,$A13,'01_MATRIZ_OPERATIVA_186'!$H:$H,"F2*") | D13: =COUNTIFS('01_MATRIZ_OPERATIVA_186'!$A:$A,$A13,'01_MATRIZ_OPERATIVA_186'!$H:$H,"F3*") | E13: =SUM(B13:D13) | F13: =IF(E13=93,"PASS","FAIL")
A14: M05 | B14: =COUNTIFS('01_MATRIZ_OPERATIVA_186'!$A:$A,$A14,'01_MATRIZ_OPERATIVA_186'!$H:$H,"F1*") | C14: =COUNTIFS('01_MATRIZ_OPERATIVA_186'!$A:$A,$A14,'01_MATRIZ_OPERATIVA_186'!$H:$H,"F2*") | D14: =COUNTIFS('01_MATRIZ_OPERATIVA_186'!$A:$A,$A14,'01_MATRIZ_OPERATIVA_186'!$H:$H,"F3*") | E14: =SUM(B14:D14) | F14: =IF(E14=34,"PASS","FAIL")
A15: M06 | B15: =COUNTIFS('01_MATRIZ_OPERATIVA_186'!$A:$A,$A15,'01_MATRIZ_OPERATIVA_186'!$H:$H,"F1*") | C15: =COUNTIFS('01_MATRIZ_OPERATIVA_186'!$A:$A,$A15,'01_MATRIZ_OPERATIVA_186'!$H:$H,"F2*") | D15: =COUNTIFS('01_MATRIZ_OPERATIVA_186'!$A:$A,$A15,'01_MATRIZ_OPERATIVA_186'!$H:$H,"F3*") | E15: =SUM(B15:D15) | F15: =IF(E15=59,"PASS","FAIL")
A16: TOTAL | B16: =SUM(B13:B15) | C16: =SUM(C13:C15) | D16: =SUM(D13:D15) | E16: =SUM(E13:E15) | F16: =IF(E16=186,"PASS","FAIL")
A19: Lectura de las fases
A20: F1 | B20: QA funcional local | C20: PASS del comportamiento propio del módulo. Si además produce un payload downstream, se valida aquí el payload; la entrega real se prueba después.
A21: F2 | B21: Fixture cross-contract | C21: El resultado consume input de otro módulo. Se usa payload/fixture canónico del contrato cerrado; PASS funcional, todavía no E2E.
A22: F3 | B22: M02/M03 / superficie | C22: El criterio de aceptación completo vive en Home, Perfil, avisos/canales u otra superficie M02/M03. El productor puede tener QA parcial previo.
A23: F4 | B23: E2E real | C23: Reejecución de interfaces M04↔M05↔M06 con productor/consumidor reales. No es una nueva bolsa de IDs.
A24: F5 | B24: Regresión final | C24: Smoke contractual + journeys críticos sobre el release candidato. No crea nuevas variantes ni reabre Producto.
A27: Mensaje operativo para Miguel
A28: El enfoque de separar por dependencias se mantiene, pero proponemos distinguir PASS funcional de integración. F1 valida lo owner-local; F2 valida consumidores cross-module con fixtures canónicos; F3 valida M02/M03/superficies; F4 reejecuta E2E real y F5 hace regresión final. Esto permite adelantar productores que hoy están en F3/F4/F5 sin declarar una integración como aprobada antes de tiempo. Para M04 hay además que corregir el esquema de IDs: el contrato vigente tiene 93 Trace IDs TR-M04-044…136 y el HTML usa M4-V; no fabricamos V89–V93.

Sheet 01_MATRIZ_OPERATIVA_186
A1: Matriz operativa QA · 186 unidades vigentes
A2: F1/F2/F3 = primer PASS. F4/F5 = overlays de integración/regresión. M04 se conserva con sus Trace IDs vigentes; ver crosswalk legacy.
A4: Módulo | B4: ID vigente | C4: Flujo / Subflujo | D4: Variante / Escenario | E4: Condición / Disparador | F4: Comportamiento / Obligación | G4: Dependencia real / owner | H4: Gate primario Walvy | I4: QA funcional local | J4: Fixture cross-contract | K4: M02/M03 / superficie | L4: E2E real | M4: Regresión final | N4: Fase Miguel (HTML) | O4: Excepción vs Miguel | P4: Criterio / por qué | Q4: Fuente vigente | R4: Conteo ID
A5: M04 | B5: TR-M04-044 | C5: FLOW-M04-001 · Entrada contextual | D5: Existe candidato/proyección M04 accionable ya resuelto por el módulo dueño; Home solo consume el contrato. | E5: Home | CTA contextual | F5: Home representa el candidato M04 y deriva a su destino sin recalcular estado, reason ni Ruta; la selección del ganador global queda fuera de M04. | G5: M04 | M03/Home | H5: F3 · M02/M03 / superficie | I5: No como PASS completo | J5: Parcial · productor/oráculo sí; no sustituye PASS superficie | K5: Sí | L5: Sí · F3/F5 | M5: Sí · F5 journey crítico | N5: No comparable 1:1 · Miguel usa M4-V; vigente usa TR-M04 | O5: CROSSWALK | P5: El criterio de aceptación completo vive en Home/Perfil/avisos o en una superficie M02/M03; el productor puede probarse antes, pero no reemplaza el PASS de superficie. | Q5: Walvy_M04_Matriz_Trazabilidad_Cliente_v1.3.xlsx · 01_Matriz_Trazabilidad · TR-M04-044 | R5: =COUNTIF($B$5:$B$190,B5)
A6: M04 | B6: TR-M04-045 | C6: FLOW-M04-001 · Entrada contextual | D6: Señal corresponde a pago próximo/al día/vencimiento simple con capacidad | E6: Home | CTA contextual | F6: Home deriva a M06/Pagos-Alertas; no a Ruta. | G6: M06 | M06/Pagos | H6: F3 · M02/M03 / superficie | I6: No como PASS completo | J6: Parcial · productor/oráculo sí; no sustituye PASS superficie | K6: Sí | L6: Sí · F3/F5 | M6: Sí · F5 journey crítico | N6: No comparable 1:1 · Miguel usa M4-V; vigente usa TR-M04 | O6: CROSSWALK | P6: El criterio de aceptación completo vive en Home/Perfil/avisos o en una superficie M02/M03; el productor puede probarse antes, pero no reemplaza el PASS de superficie. | Q6: Walvy_M04_Matriz_Trazabilidad_Cliente_v1.3.xlsx · 01_Matriz_Trazabilidad · TR-M04-045 | R6: =COUNTIF($B$5:$B$190,B6)
A7: M04 | B7: TR-M04-046 | C7: FLOW-M04-001 · Entrada contextual | D7: Existe deuda confirmada con faltante material accionable; si aún no está confirmada, precede F2. | E7: Home | Completar | F7: Proyectar F1/completitud hacia revisión; no plan activo. Consolidar pendings de calidad por deuda y preservar reasons secundarios. | G7: M04 | M03/Home | H7: F3 · M02/M03 / superficie | I7: No como PASS completo | J7: Parcial · productor/oráculo sí; no sustituye PASS superficie | K7: Sí | L7: Sí · F3/F5 | M7: Sí · F5 journey crítico | N7: No comparable 1:1 · Miguel usa M4-V; vigente usa TR-M04 | O7: CROSSWALK | P7: El criterio de aceptación completo vive en Home/Perfil/avisos o en una superficie M02/M03; el productor puede probarse antes, pero no reemplaza el PASS de superficie. | Q7: Walvy_M04_Matriz_Trazabilidad_Cliente_v1.3.xlsx · 01_Matriz_Trazabilidad · TR-M04-046 | R7: =COUNTIF($B$5:$B$190,B7)
A8: M04 | B8: TR-M04-047 | C8: FLOW-M04-001 · Entrada contextual | D8: Existe estado/proyección M04 consumible por Perfil (Salud, Ruta, calidad u orientación permitida). | E8: Perfil Financiero | CTA/lectura contextual | F8: Perfil representa estado/CTA compacto heredado del owner M04; no recalcula ni crea state machine o señal paralela. | G8: M04 | H8: F3 · M02/M03 / superficie | I8: No como PASS completo | J8: Parcial · productor/oráculo sí; no sustituye PASS superficie | K8: Sí | L8: Sí · F3/F5 | M8: Sí · F5 journey crítico | N8: No comparable 1:1 · Miguel usa M4-V; vigente usa TR-M04 | O8: CROSSWALK | P8: El criterio de aceptación completo vive en Home/Perfil/avisos o en una superficie M02/M03; el productor puede probarse antes, pero no reemplaza el PASS de superficie. | Q8: Walvy_M04_Matriz_Trazabilidad_Cliente_v1.3.xlsx · 01_Matriz_Trazabilidad · TR-M04-047 | R8: =COUNTIF($B$5:$B$190,B8)
A9: M04 | B9: TR-M04-048 | C9: FLOW-M04-002 · Onboarding 1 · Carga | D9: Usuario selecciona documento de deuda permitido | E9: OD-01 Agrega tus deudas | Cargar documentos | F9: El archivo entra a procesamiento documental manual y queda pendiente hasta lectura/revisión. | G9: M04 | Procesamiento documental | H9: F1 · QA funcional local | I9: Sí | J9: No requerido para PASS primario | K9: No para PASS primario | L9: No obligatorio fuera de regresión | M9: Sí · F5 smoke contractual | N9: No comparable 1:1 · Miguel usa M4-V; vigente usa TR-M04 | O9: CROSSWALK | P9: El resultado primario se determina en M04 con sus estados/reglas; una salida downstream no se trata como dependencia de entrada. | Q9: Walvy_M04_Matriz_Trazabilidad_Cliente_v1.3.xlsx · 01_Matriz_Trazabilidad · TR-M04-048 | R9: =COUNTIF($B$5:$B$190,B9)
A10: M04 | B10: TR-M04-049 | C10: FLOW-M04-002 · Onboarding 1 · Carga | D10: Archivo es Informe de Deudas CMF cargado manualmente | E10: OD-01 Agrega tus deudas | Cargar documentos | F10: Se trata como documento manual bajo las mismas reglas de ingesta; no inicia conexión/consulta/sincronización CMF/SFA. | G10: M04 | CMF/SFA externo | H10: F1 · QA funcional local | I10: Sí | J10: No requerido para PASS primario | K10: No para PASS primario | L10: No obligatorio fuera de regresión | M10: Sí · F5 smoke contractual | N10: No comparable 1:1 · Miguel usa M4-V; vigente usa TR-M04 | O10: CROSSWALK | P10: El resultado primario se determina en M04 con sus estados/reglas; una salida downstream no se trata como dependencia de entrada. | Q10: Walvy_M04_Matriz_Trazabilidad_Cliente_v1.3.xlsx · 01_Matriz_Trazabilidad · TR-M04-049 | R10: =COUNTIF($B$5:$B$190,B10)
A11: M04 | B11: TR-M04-050 | C11: FLOW-M04-002 · Onboarding 1 · Carga | D11: Procesamiento aún no termina | E11: Procesamiento documental | Estado de procesamiento | F11: Mantener processing pending; no producir deuda confirmada ni Ruta completa. | G11: M04 | Procesamiento documental | H11: F1 · QA funcional local | I11: Sí | J11: No requerido para PASS primario | K11: No para PASS primario | L11: No obligatorio fuera de regresión | M11: Sí · F5 smoke contractual | N11: No comparable 1:1 · Miguel usa M4-V; vigente usa TR-M04 | O11: CROSSWALK | P11: El resultado primario se determina en M04 con sus estados/reglas; una salida downstream no se trata como dependencia de entrada. | Q11: Walvy_M04_Matriz_Trazabilidad_Cliente_v1.3.xlsx · 01_Matriz_Trazabilidad · TR-M04-050 | R11: =COUNTIF($B$5:$B$190,B11)
A12: M04 | B12: TR-M04-051 | C12: FLOW-M04-003 · Onboarding 1 · Carga | D12: Registro manual formal con campos de registro básico | E12: OD-01 / sheet deuda manual | Guardar deuda | F12: Guardar la deuda declarada manualmente y marcarla como confirmada respecto de su existencia/pertenencia; reevaluar la completitud de forma independiente. El registro no implica Presion ni Ruta. | G12: M04 | H12: F1 · QA funcional local | I12: Sí | J12: No requerido para PASS primario | K12: No para PASS primario | L12: No obligatorio fuera de regresión | M12: Sí · F5 smoke contractual | N12: No comparable 1:1 · Miguel usa M4-V; vigente usa TR-M04 | O12: CROSSWALK | P12: El resultado primario se determina en M04 con sus estados/reglas; una salida downstream no se trata como dependencia de entrada. | Q12: Walvy_M04_Matriz_Trazabilidad_Cliente_v1.3.xlsx · 01_Matriz_Trazabilidad · TR-M04-051 | R12: =COUNTIF($B$5:$B$190,B12)
A13: M04 | B13: TR-M04-052 | C13: FLOW-M04-003 · Onboarding 1 · Carga | D13: Registro es préstamo personal o compromiso informal con monto/frecuencia | E13: OD-01 / sheet deuda manual | Guardar deuda | F13: Guardar como deuda manual/informal sin tratamiento estigmatizante; evaluar luego según mismas reglas de presión. | G13: M04 | H13: F1 · QA funcional local | I13: Sí | J13: No requerido para PASS primario | K13: No para PASS primario | L13: No obligatorio fuera de regresión | M13: Sí · F5 smoke contractual | N13: No comparable 1:1 · Miguel usa M4-V; vigente usa TR-M04 | O13: CROSSWALK | P13: El resultado primario se determina en M04 con sus estados/reglas; una salida downstream no se trata como dependencia de entrada. | Q13: Walvy_M04_Matriz_Trazabilidad_Cliente_v1.3.xlsx · 01_Matriz_Trazabilidad · TR-M04-052 | R13: =COUNTIF($B$5:$B$190,B13)
A14: M04 | B14: TR-M04-053 | C14: FLOW-M04-003 · Onboarding 1 · Carga | D14: Faltan datos para presión/Ruta | E14: OD-01 / sheet deuda manual | Guardar deuda | F14: Conservar la deuda manual como confirmada respecto de su existencia/pertenencia, pero pendiente/incompleta para el uso afectado; no evaluar presion fuerte, priorizacion ni cronograma mientras falten datos materiales requeridos. | G14: M04 | H14: F1 · QA funcional local | I14: Sí | J14: No requerido para PASS primario | K14: No para PASS primario | L14: No obligatorio fuera de regresión | M14: Sí · F5 smoke contractual | N14: No comparable 1:1 · Miguel usa M4-V; vigente usa TR-M04 | O14: CROSSWALK | P14: El resultado primario se determina en M04 con sus estados/reglas; una salida downstream no se trata como dependencia de entrada. | Q14: Walvy_M04_Matriz_Trazabilidad_Cliente_v1.3.xlsx · 01_Matriz_Trazabilidad · TR-M04-053 | R14: =COUNTIF($B$5:$B$190,B14)
A15: M04 | B15: TR-M04-054 | C15: FLOW-M04-004 · Onboarding 1 · Documento protegido | D15: Documento está protegido con contraseña | E15: Carga documental | Detectar protección | F15: Mostrar estado recuperable y solicitar clave solo cuando sea necesaria. | G15: M04 | Documento protegido | H15: F1 · QA funcional local | I15: Sí | J15: No requerido para PASS primario | K15: No para PASS primario | L15: No obligatorio fuera de regresión | M15: Sí · F5 smoke contractual | N15: No comparable 1:1 · Miguel usa M4-V; vigente usa TR-M04 | O15: CROSSWALK | P15: El resultado primario se determina en M04 con sus estados/reglas; una salida downstream no se trata como dependencia de entrada. | Q15: Walvy_M04_Matriz_Trazabilidad_Cliente_v1.3.xlsx · 01_Matriz_Trazabilidad · TR-M04-054 | R15: =COUNTIF($B$5:$B$190,B15)
A16: M04 | B16: TR-M04-055 | C16: FLOW-M04-004 · Onboarding 1 · Documento protegido | D16: Clave correcta | E16: Estado requiere clave | Continuar revisión | F16: Procesar documento y continuar a revisión; clave no se persiste como atributo de deuda. | G16: M04 | Documento protegido | H16: F1 · QA funcional local | I16: Sí | J16: No requerido para PASS primario | K16: No para PASS primario | L16: No obligatorio fuera de regresión | M16: Sí · F5 smoke contractual | N16: No comparable 1:1 · Miguel usa M4-V; vigente usa TR-M04 | O16: CROSSWALK | P16: El resultado primario se determina en M04 con sus estados/reglas; una salida downstream no se trata como dependencia de entrada. | Q16: Walvy_M04_Matriz_Trazabilidad_Cliente_v1.3.xlsx · 01_Matriz_Trazabilidad · TR-M04-055 | R16: =COUNTIF($B$5:$B$190,B16)
... A190: M06 | B190: M6-V59 | C190: Diseño / Equivalencia | D190: Pantalla Pagos vs superficie equivalente | E190: Se debe representar M6 en UX | F190: La solución debe cubrir todas las obligaciones MVP mínimas; la pantalla propia es candidata fuerte, pero el cierre visual final requiere validación UX/QA. | G190: M06 | H190: F1 · QA funcional local | I190: Sí | J190: No requerido para PASS primario | K190: No para PASS primario | L190: No obligatorio fuera de regresión | M190: Sí · F5 smoke contractual | N190: F5 | O190: SÍ | P190: El resultado primario se determina en M06 con sus estados/reglas; una salida downstream no se trata como dependencia de entrada. | Q190: Walvy_M6_Matriz_Trazabilidad_Cliente_v1.0_RESPUESTA_WALVY.xlsx · Matriz Trazabilidad · M6-V59 | R190: =COUNTIF($B$5:$B$190,B190)

Sheet 02_EXCEPCIONES_MIGUEL
A1: Excepciones respecto de la propuesta de Miguel
A2: Solo diferencias materiales. Comparación contra plan_fases_qa_pmo.html; el Excel/CSV simple mencionado en el HTML no está adjunto.
A4: Módulo | B4: ID / rango Miguel | C4: Miguel | D4: Walvy recomendado | E4: Tipo de corrección | F4: Por qué | G4: Acción para Miguel | H4: Certeza | I4: Fuente | J4: Revisión
A5: M04 | B5: Universo / IDs | C5: 93 “variantes” M4-Vxx | D5: 93 Trace vigentes TR-M04-044…136 | E5: ID / universo | F5: El contrato final M04 ya no usa M4-V como ID rector. El lineage histórico localiza M4-V01…V86; V87/V88 aparecen solo en el HTML y V89–V93 no tienen fuente explícita localizada. | G5: Mantener plan operativo sobre TR-M04 vigente y usar el crosswalk legacy solo como referencia; no inventar V89–V93. | H5: Alta | I5: M04 final v1.3 + matriz reconciliada producto | J5: Aprobado
A6: M04 | B6: M4-V87–V88 | C6: F1 y también dentro de V50–V88/F5 | D6: Una sola disposición; semanticamente entrada directa/reingreso. | E6: Duplicidad | F6: El HTML los incluye en F1 y simultáneamente el rango F5 los vuelve a incluir. | G6: Eliminar la duplicidad; no contar dos veces. | H6: Alta | I6: plan_fases_qa_pmo.html | J6: Aprobado
A7: M04 | B7: M4-V89–V93 | C7: No aparecen | D7: SOURCE_GAP: no asignar hasta mapear contra TR vigentes | E7: Ausencia | F7: El HTML declara M04=93, pero no dispone V89–V93. No se localizó un crosswalk autoritativo que convierta TR-M04-132…136 en esos V IDs. | G7: No fabricar IDs. Si Miguel aporta su Excel simple, reconciliar esos cinco contra TR vigentes. | H7: Alta | I7: plan_fases_qa_pmo.html + M04 final v1.3 | J7: Aprobado
A8: M04 | B8: M4-V30–V49 | C8: F4 | D8: Separar: consumo upstream → F2 con fixture; output/local → F1; E2E → F4 | E8: Partición demasiado gruesa | F8: “Cross-module” no significa que todo deba esperar integración real; solo los inputs externos bloquean el PASS sin fixture. | G8: Desagregar por dependencia real, usando matriz operativa vigente. | H8: Alta | I8: M04 final v1.3 · P4 / owner inputs | J8: Aprobado
A9: M04 | B9: M4-V50–V88 | C9: F5 | D9: Ruta se prueba por capas: F1 local / F2 inputs cross / F4 E2E / F5 regresión | E9: Falso bloqueo de Ruta | F9: La política prudencial y lifecycle ya están cerrados. Ruta no debe esperar completa hasta F5. | G9: Reservar F5 para journey/regresión; adelantar reglas y simulación según dependencia. | H9: Alta | I9: M04 v1.3 + M05 v1.2 prudencial | J9: Aprobado
A10: M05 | B10: M5-V11 | C10: F3 | D10: F1 productor + F3 Home | E10: Split producer/surface | F10: M05 puede validar la señal; M03/Home valida la superficie/prioridad. | G10: Ajustar fase/overlay; no reabrir regla Producto. | H10: Alta | I10: M05 v1.2 · M5-V11 | J10: Aprobado
A11: M05 | B11: M5-V12 | C11: F3 | D11: F1 | E11: Dependencia sobredimensionada | F11: La recomendación M05 exige evidencia/lifecycle, no un canal M02 para su lógica primaria. | G11: Ajustar fase/overlay; no reabrir regla Producto. | H11: Alta | I11: M05 v1.2 · M5-V12 | J11: Aprobado
A12: M05 | B12: M5-V15 | C12: F2 | D12: F1 | E12: Precondición local | F12: La confirmación de extracción se valida con candidato local controlado. | G12: Ajustar fase/overlay; no reabrir regla Producto. | H12: Alta | I12: M05 v1.2 · M5-V15 | J12: Aprobado
A13: M05 | B13: M5-V18 | C13: F2 | D13: F1 | E13: Precondición local | F13: Plan de recuperación usa evidencia/historial M05; no requiere otro módulo como input rector. | G13: Ajustar fase/overlay; no reabrir regla Producto. | H13: Alta | I13: M05 v1.2 · M5-V18 | J13: Aprobado
A14: M05 | B14: M5-V19 | C14: F4/F5 | D14: F2 fixture + F4 E2E | E14: Cross-contract | F14: Consume deuda/mora/presión; puede validar decisión de derivación con fixture antes del E2E. | G14: Ajustar fase/overlay; no reabrir regla Producto. | H14: Alta | I14: M05 v1.2 · M5-V19 | J14: Aprobado
A15: M05 | B15: M5-V20 | C15: F2 | D15: F3 · M02/M03 / superficie; fixture solo como prevalidación | E15: Dependencia M02 · wording corregido | F15: Consume catálogo/foco aprobado M02; el criterio de aceptación completo requiere M02. El fixture permite prevalidar la lógica, pero no sustituye el PASS F3. | G15: Mantener F3 como gate primario; usar fixture solo para prevalidación funcional y reservar la actualización/consumo real M02 para su gate correspondiente. | H15: Alta | I15: M05 v1.2 · M5-V20 | J15: Ajustado: gate primario corregido a F3; fixture queda solo como prevalidación funcional.
... A27: M06 | B27: M6-V59 | C27: F5 | D27: F1 funcional; cierre visual separado | E27: Pendiente mal tipificado | F27: Hub M06 está cerrado funcionalmente; quedan 15 ajustes Figma/evidencia, no una A5 Producto abierta. | G27: No usar F5 como espera de decisión Producto; tratar visual QA por su gate propio. | H27: Alta | I27: M06 v1.0 · PD-M6-02/08 | J27: Aprobado

Sheet 03_M04_CROSSWALK_LEGACY
A1: M04 · Crosswalk de IDs legacy usados por Miguel
A2: Preserva M4-V01…V93 sin afirmar equivalencia inexistente con los 93 Trace IDs vigentes. V87/V88 solo aparecen en el HTML; V89–V93 quedan como source gap.
A4: ID legacy Miguel | B4: Fase Miguel (HTML) | C4: Lineage localizado | D4: RN / reglas relacionadas | E4: Referencia cliente / P4 | F4: Tratamiento histórico | G4: Posible referencia vigente | H4: Estado crosswalk
A5: M4-V01 | B5: F3 | C5: Sí · matriz reconciliada histórica | D5: M4-RN-001 | E5: M04-RGL-002 | F5: Cubierta por contrato cliente | G5: Reconciliar semánticamente contra TR vigente; no identidad 1:1 | H5: LINEAGE_LOCALIZADO
A6: M4-V02 | B6: F3 | C6: Sí · matriz reconciliada histórica | D6: M4-RN-003; M4-RN-006 | E6: M04-RGL-003; M04-RGL-012; P4-CNT-001; P4-CNT-018 | F6: Cubierta con precisión adicional del cliente; Cubierta por contrato cliente | G6: Reconciliar semánticamente contra TR vigente; no identidad 1:1 | H6: LINEAGE_LOCALIZADO
A7: M4-V03 | B7: F3 | C7: Sí · matriz reconciliada histórica | D7: M4-RN-005; M4-RN-014 | E7: M04-RGL-006; M04-RGL-007; P4-CNT-016; M04-RGL-007 | F7: Cubierta con precisión adicional del cliente; Cubierta por contrato cliente | G7: Reconciliar semánticamente contra TR vigente; no identidad 1:1 | H7: LINEAGE_LOCALIZADO
A8: M4-V04 | B8: F3 | C8: Sí · matriz reconciliada histórica | D8: M4-RN-004; M4-RN-006 | E8: M04-RGL-012; P4-CNT-001; P4-CNT-018; M04-RGL-014; P4-CNT-018; P4-CNT-019 | F8: Cubierta con precisión adicional del cliente; Reemplazada por definición cliente | G8: Reconciliar semánticamente contra TR vigente; no identidad 1:1 | H8: LINEAGE_LOCALIZADO
A9: M4-V05 | B9: F1 | C9: Sí · matriz reconciliada histórica | D9: M4-RN-017; M4-RN-042 | E9: 01_Matriz_Trazabilidad · materialización OD/DD/RD; 06_Ajustes_Materializacion; M04-RGL-015; M04-RGL-038; P4-CNT-007; P4-CNT-016 | F9: Cubierta con precisión adicional del cliente; Reemplazada por definición cliente | G9: Reconciliar semánticamente contra TR vigente; no identidad 1:1 | H9: LINEAGE_LOCALIZADO
A10: M4-V06 | B10: F1 | C10: Sí · matriz reconciliada histórica | D10: M4-RN-017; M4-RN-018 | E10: M04-RGL-014; M04-RGL-015; P4-CNT-001; P4-CNT-018; M04-RGL-015; M04-RGL-038; P4-CNT-007; P4-CNT-016 | F10: Reemplazada por definición cliente | G10: Reconciliar semánticamente contra TR vigente; no identidad 1:1 | H10: LINEAGE_LOCALIZADO
A11: M4-V07 | B11: F1 | C11: Sí · matriz reconciliada histórica | D11: M4-RN-001; M4-RN-004 | E11: M04-RGL-002; M04-RGL-014; P4-CNT-018; P4-CNT-019 | F11: Cubierta por contrato cliente; Reemplazada por definición cliente | G11: Reconciliar semánticamente contra TR vigente; no identidad 1:1 | H11: LINEAGE_LOCALIZADO
A12: M4-V08 | B12: F1 | C12: Sí · matriz reconciliada histórica | D12: M4-RN-002 | E12: M04-RGL-002; M04-RGL-039 | F12: Cubierta con precisión adicional del cliente | G12: Reconciliar semánticamente contra TR vigente; no identidad 1:1 | H12: LINEAGE_LOCALIZADO
A13: M4-V09 | B13: F1 | C13: Sí · matriz reconciliada histórica | D13: M4-RN-002; M4-RN-004 | E13: M04-RGL-002; M04-RGL-039; M04-RGL-014; P4-CNT-018; P4-CNT-019 | F13: Cubierta con precisión adicional del cliente; Reemplazada por definición cliente | G13: Reconciliar semánticamente contra TR vigente; no identidad 1:1 | H13: LINEAGE_LOCALIZADO
A14: M4-V10 | B14: F1 | C14: Sí · matriz reconciliada histórica | D14: M4-RN-003; M4-RN-005 | E14: M04-RGL-003; M04-RGL-006; M04-RGL-007; P4-CNT-016 | F14: Cubierta con precisión adicional del cliente; Cubierta por contrato cliente | G14: Reconciliar semánticamente contra TR vigente; no identidad 1:1 | H14: LINEAGE_LOCALIZADO
A15: M4-V11 | B15: F1 | C15: Sí · matriz reconciliada histórica | D15: M4-RN-006 | E15: M04-RGL-012; P4-CNT-001; P4-CNT-018 | F15: Cubierta con precisión adicional del cliente | G15: Reconciliar semánticamente contra TR vigente; no identidad 1:1 | H15: LINEAGE_LOCALIZADO
... A90: M4-V86 | B90: F5 | C90: Sí · matriz reconciliada histórica | D90: M4-RN-018; M4-RN-050 | E90: M04-RGL-014; M04-RGL-015; P4-CNT-001; P4-CNT-018; P4-CNT-001; P4-CNT-008; M04-RGL-039 | F90: Reemplazada por definición cliente | G90: Reconciliar semánticamente contra TR vigente; no identidad 1:1 | H90: LINEAGE_LOCALIZADO
A91: M4-V87 | B91: F1/F5 DUPLICADO | C91: Solo HTML Miguel · “Entrada directa / reingreso” | G91: TR-M04-130 / TR-M04-131 · coincidencia semántica probable, NO identidad demostrada | H91: HTML_ONLY
A92: M4-V88 | B92: F1/F5 DUPLICADO | C92: Solo HTML Miguel · “Entrada directa / reingreso” | G92: TR-M04-130 / TR-M04-131 · coincidencia semántica probable, NO identidad demostrada | H92: HTML_ONLY
A93: M4-V89 | B93: NO ASIGNADO | C93: No localizado en fuentes revisadas | G93: TR-M04-132…136 existen como obligaciones vigentes, pero NO hay mapeo explícito a V89–V93 | H93: SIN_FUENTE
A94: M4-V90 | B94: NO ASIGNADO | C94: No localizado en fuentes revisadas | G94: TR-M04-132…136 existen como obligaciones vigentes, pero NO hay mapeo explícito a V89–V93 | H94: SIN_FUENTE
A95: M4-V91 | B95: NO ASIGNADO | C95: No localizado en fuentes revisadas | G95: TR-M04-132…136 existen como obligaciones vigentes, pero NO hay mapeo explícito a V89–V93 | H95: SIN_FUENTE
A96: M4-V92 | B96: NO ASIGNADO | C96: No localizado en fuentes revisadas | G96: TR-M04-132…136 existen como obligaciones vigentes, pero NO hay mapeo explícito a V89–V93 | H96: SIN_FUENTE
A97: M4-V93 | B97: NO ASIGNADO | C97: No localizado en fuentes revisadas | G97: TR-M04-132…136 existen como obligaciones vigentes, pero NO hay mapeo explícito a V89–V93 | H97: SIN_FUENTE

Sheet 04_FASES_Y_GATES
A1: Modelo operativo de fases y gates
A2: Una variante puede pasar un gate funcional y volver a ejecutarse en un gate E2E/regresión. F4/F5 no deben volver a contarse como nuevos IDs.
A4: Gate | B4: Objetivo | C4: Prerequisito | D4: Qué puede certificar QA | E4: Qué NO certifica | F4: Resultado permitido | G4: Ejemplo | H4: Regla operativa
A5: F1 · QA funcional local | B5: Validar lógica owner-local y payloads producidos. | C5: Release contiene comportamiento del módulo + datos locales/fixtures propios. | D5: Regla, estado, CTA, lifecycle, guardrail, payload producer. | E5: Entrega/consumo real por otro módulo. | F5: PASS_FUNCIONAL_LOCAL | G5: M6-V42 produce evento M05; se valida payload sin esperar M05. | H5: Output downstream NO es dependencia de entrada.
A6: F2 · Fixture cross-contract | B6: Validar consumidor usando contrato upstream cerrado. | C6: Contrato upstream determinista + fixture/oráculo versionado. | D6: Interpretación, cálculo y bordes del consumidor. | E6: Transporte/producer runtime real. | F6: PASS_FUNCIONAL_CONTRATO | G6: M04 consume headroom M05; inyectar POSITIVE/ZERO/NOT_EVALUABLE. | H6: Fixture debe reproducir exactamente el contrato owner.
A7: F3 · M02/M03 / superficie | B7: Validar Home, Perfil, avisos/canales y prioridad/superficie. | C7: M02/M03/superficie disponible en ambiente QA; producer payload válido. | D7: Representación, CTA, canal/permisos, dedupe/surface según contrato. | E7: Integraciones M04↔M05↔M06 no relacionadas. | F7: PASS_SUPERFICIE | G7: M6-V39 candidato Home; M03 decide superficie. | H7: El productor puede tener PASS previo; la superficie no.
A8: F4 · E2E real | B8: Confirmar integración real entre owners. | C8: Producer y consumer reales, contrato/versiones alineados, ambiente. | D8: Transporte, idempotencia, dedupe, propagación y consumo real. | E8: Regresión total del producto. | F8: PASS_INTEGRACION_E2E | G8: M06 payment/cycle → M04 D/aging; M05 headroom → M04 K. | H8: Reejecuta IDs ya probados; no crea una nueva bolsa.
A9: F5 · Regresión final | B9: Proteger release candidato y journeys críticos. | C9: F1-F4 aplicables cerrados o residual explícitamente aceptado. | D9: Smoke contractual + journeys completos de mayor riesgo. | E9: No reabre Producto ni reemplaza QA de fase anterior. | F9: PASS_REGRESION_RELEASE | G9: Carga → evaluación → Ruta → pago → recálculo → Home/Perfil. | H9: Selección por riesgo; conservar trazabilidad al ID original.

Sheet 05_FUENTES
A1: Fuentes y autoridad
A2: Las fuentes finales gobiernan la semántica actual. Historial y conciliación explican lineage/supersession; el HTML de Miguel es una propuesta a evaluar.
A4: Fuente | B4: Rol | C4: Autoridad en este análisis | D4: Uso | E4: URL / ruta | F4: Nota
A5: plan_fases_qa_pmo.html | B5: Propuesta Kabeli/PMO | C5: No autoritativa | D5: Fases Miguel, conteos, exclusiones y preguntas PMO | E5: Adjunto conversación: plan_fases_qa_pmo.html | F5: El footer menciona matriz_fase01.csv, pero ese archivo separado no está adjunto.
A6: Walvy_M04_Matriz_Trazabilidad_Cliente_v1.3.xlsx | B6: Contrato vigente M04 | C6: Alta | D6: 93 Trace IDs TR-M04-044…136; owner/dependencias/criterios | E6: Dentro de Entrega_Kabeli_2.0_M04_v1.3_FINAL(2).zip | F6: ID vigente M04 = Trace ID, no M4-V.
A7: Walvy_M5_Matriz_Trazabilidad_Cliente_v1.2_RESPUESTA_WALVY.xlsx | B7: Contrato vigente M05 | C7: Alta | D7: 34 variantes M5-V01…V34 | E7: Dentro de Entrega_Kabeli_2.0_M05_v1.2_FINAL(1).zip | F7: Preservar owner M05 del outcome prudencial.
A8: Walvy_M6_Matriz_Trazabilidad_Cliente_v1.0_RESPUESTA_WALVY.xlsx | B8: Contrato vigente M06 | C8: Alta | D8: 59 variantes M6-V01…V59 | E8: Dentro de Walvy_M06_Entrega_Kabeli_v1.0(4).zip | F8: R18 lineage interno; externo M06 v1.0.
A9: M02_M03_M04_M05_M06_Matriz_Transversal_v1.1.csv | B9: Contrato transversal M02 | C9: Alta en su dominio | D9: Canales/preferencias/consumidores M02-M03 | E9: Dentro de Entrega_Kabeli_2.0_M02_v1.1_20260915(3).zip | F9: No trasladar ownership productor a M02.
A10: M06_M03_M02_Matriz_Transversal_v1.0.csv | B10: Contrato transversal M06 | C10: Alta en su dominio | D10: Producer/consumer, E2E, avisos/Home/Perfil | E10: Dentro de Walvy_M06_Entrega_Kabeli_v1.0(4).zip | F10: Clave para distinguir output vs input.
A11: Walvy_M04_M05_M06_Conciliacion_Respuesta_Walvy_v1.0.xlsx | B11: Conciliación transversal | C11: Alta para delta/provenance | D11: 57 deltas, cambio de owner, explicitación, supersession | E11: https://edificateinteligente.sharepoint.com/sites/DesarrollodeProductos-Servicios/Shared%20Documents/General/Desarrollo%20app%20Kabeli/01%20Entrega%20de%20Modulos%20-%20Kabeli/Reconciliaci%C3%B3n%20M04-M06/v1.0/Walvy_M04_M05_M06_Conciliacion_Respuesta_Walvy_v1.0.xlsx?web=1 | F11: No sustituye universos completos.
A12: Walvy_M04_Matriz_Reconciliada_Producto_v1.0_respuesta.xlsx | B12: Lineage M04 legacy | C12: Histórica / soporte | D12: Mapeo M4-V01…V86 a RN/reglas reconciliadas | E12: SharePoint Construyendo M04 / archivo histórico | F12: No usar para inventar V87–V93 ni superseder v1.3.
A13: Outlook · metodología releases 2026-09-15 | B13: Operación QA | C13: Alta operativa | D13: PR → main → release explícito → TestFlight/Play Internal → QA | E13: Outlook: RE: Entrega Módulo 2 _ 02092026 | F13: Merge main no cambia automáticamente app en prueba.

Sheet 06_QA_ZERO_TRUST
A1: QA Zero Trust del plan
A2: Controles de integridad del workbook y falsificación explícita del esquema de fases.
A4: Control | B4: Fórmula / evidencia | C4: Esperado | D4: Resultado | E4: Estado | F4: Tratamiento
A5: Universo total | B5: =COUNTA('01_MATRIZ_OPERATIVA_186'!$B$5:$B$190) | C5: 186 | D5: =B5 | E5: =IF(D5=C5,"PASS","FAIL") | F5: Debe existir exactamente una fila vigente por unidad contractual.
A6: IDs duplicados | B6: =MAX('01_MATRIZ_OPERATIVA_186'!$R$5:$R$190) | C6: 1 | D6: =B6 | E6: =IF(D6=C6,"PASS","FAIL") | F6: Cualquier valor >1 bloquea.
A7: M04 vigente | B7: =COUNTIF('01_MATRIZ_OPERATIVA_186'!$A$5:$A$190,"M04") | C7: 93 | D7: =B7 | E7: =IF(D7=C7,"PASS","FAIL") | F7: 93 Trace IDs vigentes.
A8: M05 vigente | B8: =COUNTIF('01_MATRIZ_OPERATIVA_186'!$A$5:$A$190,"M05") | C8: 34 | D8: =B8 | E8: =IF(D8=C8,"PASS","FAIL") | F8: 34 variantes.
A9: M06 vigente | B9: =COUNTIF('01_MATRIZ_OPERATIVA_186'!$A$5:$A$190,"M06") | C9: 59 | D9: =B9 | E9: =IF(D9=C9,"PASS","FAIL") | F9: 59 variantes.
A10: Partición primaria F1/F2/F3 | B10: =COUNTIF('01_MATRIZ_OPERATIVA_186'!$H$5:$H$190,"F1*")+COUNTIF('01_MATRIZ_OPERATIVA_186'!$H$5:$H$190,"F2*")+COUNTIF('01_MATRIZ_OPERATIVA_186'!$H$5:$H$190,"F3*") | C10: 186 | D10: =B10 | E10: =IF(D10=C10,"PASS","FAIL") | F10: Cada unidad tiene exactamente un primer gate de PASS.
A11: M04 legacy sin fuente | B11: =COUNTIF('03_M04_CROSSWALK_LEGACY'!$H$5:$H$97,"SIN_FUENTE") | C11: 5 | D11: =B11 | E11: =IF(D11=C11,"PASS","FAIL") | F11: V89–V93 quedan como gap; no inventar.
A12: M04 legacy HTML-only | B12: =COUNTIF('03_M04_CROSSWALK_LEGACY'!$H$5:$H$97,"HTML_ONLY") | C12: 2 | D12: =B12 | E12: =IF(D12=C12,"PASS","FAIL") | F12: V87–V88 no se promocionan a identidad contractual por inferencia.
A13: Output ≠ input dependency | B13: Revisión semántica M6-V42–V47 | C13: F1 producer + F4 E2E | D13: Ver 02_EXCEPCIONES_MIGUEL | E13: =IF(COUNTIF('02_EXCEPCIONES_MIGUEL'!$B:$B,"M6-V42–V47")=1,"PASS","FAIL") | F13: Evita congelar productor por dependencia downstream.
A14: Runtime/E2E no declarado | B14: Este workbook es plan documental/funcional | C14: NO PASS runtime | D14: No evaluado | E14: =IF(D14="No evaluado","PASS","FAIL") | F14: No transformar contrato/documento en evidencia de ejecución.
A15: Revisión excepciones v1.1 | B15: =COUNTA('02_EXCEPCIONES_MIGUEL'!$J$5:$J$27) | C15: 23 | D15: =B15 | E15: =IF(D15=C15,"PASS","FAIL") | F15: Las 23 excepciones deben quedar con revisión explícita.
A16: Ajustes realizados v1.1 | B16: =COUNTIF('02_EXCEPCIONES_MIGUEL'!$J$5:$J$27,"Ajustado*") | C16: 1 | D16: =B16 | E16: =IF(D16=C16,"PASS","FAIL") | F16: Único ajuste material del reverse-check: M5-V20; no modifica 186 ni 122/41/23.

Sheet 07_PASOS_EJECUCION_APP
A1: Plan QA · Pasos de Ejecución App · M04/M05/M06 — Walvy_Plan_QA_Fases v1.1
A2: M04: pasos extraídos de M4_Pasos_Ejecucion_App_v0.2 (mapeado por índice secuencial dentro del flujo). M05/M06: pasos derivados de la Matriz de Trazabilidad. ID rector M04 = TR-M04-NNN (no usar M4-V). Columnas M-O para completar por QA.
A3: Módulo | B3: ID vigente | C3: Gate PMO | D3: Flujo / Subflujo | E3: Variante / Escenario | F3: Condición de entrada | G3: Precondición / Estado inicial | H3: Pasos de Ejecución App | I3: Dónde verificar | J3: Resultado esperado | K3: Datos de prueba / Fixture | L3: Ejecutable hoy | M3: Resultado obtenido | N3: Estado QA | O3: Notas QA | P3: Oráculo / ID fuente | Q3: Assertion concreta
A4: M04 | B4: TR-M04-044 | C4: F3 · M02/M03 / superficie | D4: FLOW-M04-001 · Entrada contextual | E4: Existe candidato/proyección M04 accionable ya resuelto por el módulo dueño; Home solo consume el contrato. | F4: Home | CTA contextual | G4: Cuenta de prueba activa y reseteada (sin deudas ni datos previos del flujo). Condición de entrada: Home | CTA contextual | H4: Seguir flujo de FLOW-M04-001 · Entrada contextual. CIERRE · Registrar resultado en columna «Resultado obtenido» y marcar «Estado QA». · Resetear solo si el siguiente caso requiere estado inicial incompatible con el actual. Casos del mismo flujo pueden reutilizar el estado. (Ajustes → Borrar mis datos · o solicitar reset al admin de QA) | I4: Pantalla activa de Ruta Despeje. | J4: Home representa el candidato M04 y deriva a su destino sin recalcular estado, reason ni Ruta; la selección del ganador global queda fuera de M04. | K4: Ambiente con Home/Perfil (M03) disponible. Producer payload válido de M04. | L4: No · requiere env | P4: Walvy_M04_Matriz_Trazabilidad_Cliente_v1.3.xlsx · 01_Matriz_Trazabilidad · TR-M04-044 | Q4: En: Pantalla activa de Ruta Despeje. → Home representa el candidato M04 y deriva a su destino sin recalcular estado, reason ni Ruta; la selección del ganador global queda fuera de M04.
A5: M04 | B5: TR-M04-045 | C5: F3 · M02/M03 / superficie | D5: FLOW-M04-001 · Entrada contextual | E5: Señal corresponde a pago próximo/al día/vencimiento simple con capacidad | F5: Home | CTA contextual | G5: Cuenta de prueba activa y reseteada (sin deudas ni datos previos del flujo). Condición de entrada: Home | CTA contextual | H5: Seguir flujo de FLOW-M04-001 · Entrada contextual. CIERRE · Registrar resultado en columna «Resultado obtenido» y marcar «Estado QA». · Resetear solo si el siguiente caso requiere estado inicial incompatible con el actual. Casos del mismo flujo pueden reutilizar el estado. (Ajustes → Borrar mis datos · o solicitar reset al admin de QA) | I5: Pantalla activa de Ruta Despeje. | J5: Home deriva a M06/Pagos-Alertas; no a Ruta. | K5: Ambiente con Home/Perfil (M03) disponible. Producer payload válido de M04. | L5: No · requiere env | P5: Walvy_M04_Matriz_Trazabilidad_Cliente_v1.3.xlsx · 01_Matriz_Trazabilidad · TR-M04-045 | Q5: En: Pantalla activa de Ruta Despeje. → Home deriva a M06/Pagos-Alertas; no a Ruta.
A6: M04 | B6: TR-M04-046 | C6: F3 · M02/M03 / superficie | D6: FLOW-M04-001 · Entrada contextual | E6: Existe deuda confirmada con faltante material accionable; si aún no está confirmada, precede F2. | F6: Home | Completar | G6: Cuenta de prueba activa y reseteada (sin deudas ni datos previos del flujo). Condición de entrada: Home | Completar | H6: Seguir flujo de FLOW-M04-001 · Entrada contextual. CIERRE · Registrar resultado en columna «Resultado obtenido» y marcar «Estado QA». · Resetear solo si el siguiente caso requiere estado inicial incompatible con el actual. Casos del mismo flujo pueden reutilizar el estado. (Ajustes → Borrar mis datos · o solicitar reset al admin de QA) | I6: Pantalla activa de Ruta Despeje. | J6: Proyectar F1/completitud hacia revisión; no plan activo. Consolidar pendings de calidad por deuda y preservar reasons secundarios. | K6: Ambiente con Home/Perfil (M03) disponible. Producer payload válido de M04. | L6: No · requiere env | P6: Walvy_M04_Matriz_Trazabilidad_Cliente_v1.3.xlsx · 01_Matriz_Trazabilidad · TR-M04-046 | Q6: En: Pantalla activa de Ruta Despeje. → Proyectar F1/completitud hacia revisión; no plan activo. Consolidar pendings de calidad por deuda y preservar reasons secundarios.
A7: M04 | B7: TR-M04-047 | C7: F3 · M02/M03 / superficie | D7: FLOW-M04-001 · Entrada contextual | E7: Existe estado/proyección M04 consumible por Perfil (Salud, Ruta, calidad u orientación permitida). | F7: Perfil Financiero | CTA/lectura contextual | G7: Cuenta de prueba activa y reseteada (sin deudas ni datos previos del flujo). Condición de entrada: Perfil Financiero | CTA/lectura contextual | H7: Seguir flujo de FLOW-M04-001 · Entrada contextual. CIERRE · Registrar resultado en columna «Resultado obtenido» y marcar «Estado QA». · Resetear solo si el siguiente caso requiere estado inicial incompatible con el actual. Casos del mismo flujo pueden reutilizar el estado. (Ajustes → Borrar mis datos · o solicitar reset al admin de QA) | I7: Pantalla activa de Ruta Despeje. | J7: Perfil representa estado/CTA compacto heredado del owner M04; no recalcula ni crea state machine o señal paralela. | K7: Ambiente con Home/Perfil (M03) disponible. Producer payload válido de M04. | L7: No · requiere env | P7: Walvy_M04_Matriz_Trazabilidad_Cliente_v1.3.xlsx · 01_Matriz_Trazabilidad · TR-M04-047 | Q7: En: Pantalla activa de Ruta Despeje. → Perfil representa estado/CTA compacto heredado del owner M04; no recalcula ni crea state machine o señal paralela.
A8: M04 | B8: TR-M04-048 | C8: F1 · QA funcional local | D8: FLOW-M04-002 · Onboarding 1 · Carga | E8: Usuario selecciona documento de deuda permitido | F8: OD-01 Agrega tus deudas | Cargar documentos | G8: Cuenta de prueba activa y reseteada (sin deudas ni datos previos del flujo). Condición de entrada: OD-01 Agrega tus deudas | Cargar documentos | H8: 1. Iniciar sesión con la cuenta de prueba reseteada. 2. Navegar a: Módulo M04 → OD-01 «Agrega tus deudas» → pantalla de carga de documentos. 3. Tocar «Cargar documento» y seleccionar un archivo permitido (PDF, XLSX o CSV de estado de cuenta). 4. Confirmar que la app acepta el archivo y muestra pantalla de análisis / spinner de procesamiento. 5. Verificar que el estado muestra «procesando» y que NO aparece ninguna deuda confirmada todavía. → Si hay spinner de análisis y cero deudas confirmadas: ✓ PASA. CIERRE · Registrar resultado en «Resultado obtenido» y marcar «Estado QA». · Resetear cuenta solo si el siguiente caso requiere estado diferente al actual. (Perfil → Herramientas QA → «Reiniciar cuenta de prueba» (doble confirmación)) | I8: Pantalla activa de Ruta Despeje. | J8: El archivo entra a procesamiento documental manual y queda pendiente hasta lectura/revisión. | L8: Sí | P8: Walvy_M04_Matriz_Trazabilidad_Cliente_v1.3.xlsx · 01_Matriz_Trazabilidad · TR-M04-048 | Q8: En: Pantalla activa de Ruta Despeje. → El archivo entra a procesamiento documental manual y queda pendiente hasta lectura/revisión.
A9: M04 | B9: TR-M04-049 | C9: F1 · QA funcional local | D9: FLOW-M04-002 · Onboarding 1 · Carga | E9: Archivo es Informe de Deudas CMF cargado manualmente | F9: OD-01 Agrega tus deudas | Cargar documentos | G9: Cuenta de prueba activa y reseteada (sin deudas ni datos previos del flujo). Condición de entrada: OD-01 Agrega tus deudas | Cargar documentos | H9: 1. Iniciar sesión con la cuenta de prueba reseteada. 2. Navegar a: OD-01 «Agrega tus deudas» → pantalla de carga de documentos. 3. Seleccionar un archivo que sea un Informe de Deudas CMF (PDF descargado del sitio CMF o equivalente). 4. Subir el archivo y observar el flujo de procesamiento. 5. Verificar que la app lo trata igual que cualquier documento manual (misma pantalla de análisis). 6. Verificar que NO aparece ningún indicador de «sincronización CMF», «conexión CMF/SFA» ni flujo automático externo. → Si el flujo es idéntico al de un PDF normal y no hay mención de sincronización: ✓ PASA. CIERRE · Registrar resultado en «Resultado obtenido» y marcar «Estado QA». · Resetear cuenta solo si el siguiente caso requiere estado diferente al actual. (Perfil → Herramientas QA → «Reiniciar cuenta de prueba» (doble confirmación)) | I9: Pantalla activa de Ruta Despeje. | J9: Se trata como documento manual bajo las mismas reglas de ingesta; no inicia conexión/consulta/sincronización CMF/SFA. | L9: Sí | P9: Walvy_M04_Matriz_Trazabilidad_Cliente_v1.3.xlsx · 01_Matriz_Trazabilidad · TR-M04-049 | Q9: En: Pantalla activa de Ruta Despeje. → Se trata como documento manual bajo las mismas reglas de ingesta; no inicia conexión/consulta/sincronización CMF/SFA.
A10: M04 | B10: TR-M04-050 | C10: F1 · QA funcional local | D10: FLOW-M04-002 · Onboarding 1 · Carga | E10: Procesamiento aún no termina | F10: Procesamiento documental | Estado de procesamiento | G10: Cuenta de prueba activa y reseteada (sin deudas ni datos previos del flujo). Condición de entrada: Procesamiento documental | Estado de procesamiento | H10: 1. Iniciar sesión con la cuenta de prueba reseteada. 2. Subir un documento (puede reutilizar el de TR-M04-048 o TR-M04-049). 3. Mientras el procesamiento está en curso (CaptureAnalyzingScreen / spinner), salir de la pantalla (navegar atrás o enviar la app al background) y volver a ingresar. 4. Verificar que la app muestra que el procesamiento sigue en curso (no reinició desde cero). 5. Verificar que NO se generó ninguna deuda confirmada ni se activó la Ruta mientras el estado era «processing». → Si el estado vuelve a «procesando» y no hay deudas: ✓ PASA. CIERRE · Registrar resultado en «Resultado obtenido» y marcar «Estado QA». · Resetear cuenta solo si el siguiente caso requiere estado diferente al actual. (Perfil → Herramientas QA → «Reiniciar cuenta de prueba» (doble confirmación)) | I10: Pantalla activa de Ruta Despeje. | J10: Mantener processing pending; no producir deuda confirmada ni Ruta completa. | L10: Sí | P10: Walvy_M04_Matriz_Trazabilidad_Cliente_v1.3.xlsx · 01_Matriz_Trazabilidad · TR-M04-050 | Q10: En: Pantalla activa de Ruta Despeje. → Mantener processing pending; no producir deuda confirmada ni Ruta completa.
A11: M04 | B11: TR-M04-051 | C11: F1 · QA funcional local | D11: FLOW-M04-003 · Onboarding 1 · Carga | E11: Registro manual formal con campos de registro básico | F11: OD-01 / sheet deuda manual | Guardar deuda | G11: Cuenta de prueba activa y reseteada (sin deudas ni datos previos del flujo). Condición de entrada: OD-01 / sheet deuda manual | Guardar deuda | H11: 1. Iniciar sesión con la cuenta de prueba reseteada. 2. Navegar a: OD-01 «Agrega tus deudas» → opción «Ingresar manualmente». 3. Rellenar todos los campos del formulario de alta manual: - Tipo de deuda (ej: tarjeta_credito) - Acreedor / institución - Saldo actual - Cuota mensual mínima - Fecha de vencimiento próxima 4. Tocar «Guardar» (o equivalente). 5. Verificar que la deuda aparece en la lista con estado confirmado. 6. Verificar que el sistema reevalúa la completitud (no queda como «falta dato crítico»). → Si la deuda queda confirmada y completa: ✓ PASA. CIERRE · Registrar resultado en «Resultado obtenido» y marcar «Estado QA». · Resetear cuenta solo si el siguiente caso requiere estado diferente al actual. (Perfil → Herramientas QA → «Reiniciar cuenta de prueba» (doble confirmación)) | I11: Pantalla activa de Ruta Despeje. | J11: Guardar la deuda declarada manualmente y marcarla como confirmada respecto de su existencia/pertenencia; reevaluar la completitud de forma independiente. El registro no implica Presion ni Ruta. | L11: Sí | P11: Walvy_M04_Matriz_Trazabilidad_Cliente_v1.3.xlsx · 01_Matriz_Trazabilidad · TR-M04-051 | Q11: En: Pantalla activa de Ruta Despeje. → Guardar la deuda declarada manualmente y marcarla como confirmada respecto de su existencia/pertenencia; reevaluar la completitud de forma independiente. El registro no implica Presion ni Ruta.
A12: M04 | B12: TR-M04-052 | C12: F1 · QA funcional local | D12: FLOW-M04-003 · Onboarding 1 · Carga | E12: Registro es préstamo personal o compromiso informal con monto/frecuencia | F12: OD-01 / sheet deuda manual | Guardar deuda | G12: Cuenta de prueba activa y reseteada (sin deudas ni datos previos del flujo). Condición de entrada: OD-01 / sheet deuda manual | Guardar deuda | H12: 1. Iniciar sesión con la cuenta de prueba reseteada. 2. Navegar a: OD-01 «Agrega tus deudas» → opción «Ingresar manualmente». 3. Seleccionar tipo de deuda informal (ej: préstamo_informal, compromiso_personal o similar). 4. Ingresar acreedor (persona o apodo) y monto/frecuencia (ej: $80.000 quincenales). 5. Guardar la deuda. 6. Verificar que se guarda sin mensajes estigmatizantes y aparece en la lista junto a las demás deudas. 7. Verificar que la presión financiera la evalúa con las mismas reglas que cualquier otra deuda. → Si se guarda correctamente y sin trato diferenciado: ✓ PASA. CIERRE · Registrar resultado en «Resultado obtenido» y marcar «Estado QA». · Resetear cuenta solo si el siguiente caso requiere estado diferente al actual. (Perfil → Herramientas QA → «Reiniciar cuenta de prueba» (doble confirmación)) | I12: Pantalla activa de Ruta Despeje. | J12: Guardar como deuda manual/informal sin tratamiento estigmatizante; evaluar luego según mismas reglas de presión. | L12: Sí | P12: Walvy_M04_Matriz_Trazabilidad_Cliente_v1.3.xlsx · 01_Matriz_Trazabilidad · TR-M04-052 | Q12: En: Pantalla activa de Ruta Despeje. → Guardar como deuda manual/informal sin tratamiento estigmatizante; evaluar luego según mismas reglas de presión.
A13: M04 | B13: TR-M04-053 | C13: F1 · QA funcional local | D13: FLOW-M04-003 · Onboarding 1 · Carga | E13: Faltan datos para presión/Ruta | F13: OD-01 / sheet deuda manual | Guardar deuda | G13: Cuenta de prueba activa y reseteada (sin deudas ni datos previos del flujo). Condición de entrada: OD-01 / sheet deuda manual | Guardar deuda | H13: 1. Iniciar sesión con la cuenta de prueba reseteada. 2. Navegar a: OD-01 «Agrega tus deudas» → opción «Ingresar manualmente». 3. Ingresar solo los datos mínimos posibles (ej: acreedor y saldo; omitir cuota y fecha de vencimiento). 4. Guardar la deuda. 5. Verificar que la deuda se guarda con estado confirmado (en cuanto a existencia), pero marcada como incompleta para presión/Ruta (muestra indicador de dato faltante). 6. Verificar que la Ruta NO se activa ni la presión se calcula errónea por datos ausentes. → Si la deuda queda confirmada-pero-incompleta y la Ruta no se activa: ✓ PASA. CIERRE · Registrar resultado en «Resultado obtenido» y marcar «Estado QA». · Resetear cuenta solo si el siguiente caso requiere estado diferente al actual. (Perfil → Herramientas QA → «Reiniciar cuenta de prueba» (doble confirmación)) | I13: Pantalla activa de Ruta Despeje. | J13: Conservar la deuda manual como confirmada respecto de su existencia/pertenencia, pero pendiente/incompleta para el uso afectado; no evaluar presion fuerte, priorizacion ni cronograma mientras falten datos materiales requeridos. | L13: Sí | P13: Walvy_M04_Matriz_Trazabilidad_Cliente_v1.3.xlsx · 01_Matriz_Trazabilidad · TR-M04-053 | Q13: En: Pantalla activa de Ruta Despeje. → Conservar la deuda manual como confirmada respecto de su existencia/pertenencia, pero pendiente/incompleta para el uso afectado; no evaluar presion fuerte, priorizacion ni cronograma mientras falten datos materiales requeridos.
A14: M04 | B14: TR-M04-054 | C14: F1 · QA funcional local | D14: FLOW-M04-004 · Onboarding 1 · Documento protegido | E14: Documento está protegido con contraseña | F14: Carga documental | Detectar protección | G14: Cuenta de prueba activa y reseteada (sin deudas ni datos previos del flujo). Condición de entrada: Carga documental | Detectar protección | H14: 1. Iniciar sesión con la cuenta de prueba reseteada. 2. Navegar a: OD-01 «Agrega tus deudas» → cargar documentos. 3. Subir un archivo PDF protegido con contraseña (QA debe crearlo previamente o usar fixture del equipo). 4. Verificar que la app detecta la protección y muestra estado «requiere clave» (no error genérico). 5. Verificar que el mensaje informa que el documento está protegido y ofrece una acción concreta. 6. Verificar que NO se crea ninguna deuda ni se avanza en el flujo hasta resolver la clave. → Si aparece el estado recuperable con solicitud de clave: ✓ PASA. CIERRE · Registrar resultado en «Resultado obtenido» y marcar «Estado QA». · Resetear cuenta solo si el siguiente caso requiere estado diferente al actual. (Perfil → Herramientas QA → «Reiniciar cuenta de prueba» (doble confirmación)) | I14: Pantalla activa de Ruta Despeje. | J14: Mostrar estado recuperable y solicitar clave solo cuando sea necesaria. | L14: Sí | P14: Walvy_M04_Matriz_Trazabilidad_Cliente_v1.3.xlsx · 01_Matriz_Trazabilidad · TR-M04-054 | Q14: En: Pantalla activa de Ruta Despeje. → Mostrar estado recuperable y solicitar clave solo cuando sea necesaria.
A15: M04 | B15: TR-M04-055 | C15: F1 · QA funcional local | D15: FLOW-M04-004 · Onboarding 1 · Documento protegido | E15: Clave correcta | F15: Estado requiere clave | Continuar revisión | G15: Cuenta de prueba activa y reseteada (sin deudas ni datos previos del flujo). Condición de entrada: Estado requiere clave | Continuar revisión | H15: 1. Continuar desde TR-M04-054 (app mostrando estado «requiere clave»). 2. Ingresar la clave correcta del PDF protegido. 3. Confirmar que la app desbloquea el documento y continúa con el procesamiento normal. 4. Verificar que NO se persiste la clave ingresada como atributo de la deuda (no debe aparecer en ningún campo). 5. Verificar que el flujo avanza a la pantalla de análisis como si fuera un documento normal. → Si procesa y la clave no queda guardada: ✓ PASA. CIERRE · Registrar resultado en «Resultado obtenido» y marcar «Estado QA». · Resetear cuenta solo si el siguiente caso requiere estado diferente al actual. (Perfil → Herramientas QA → «Reiniciar cuenta de prueba» (doble confirmación)) | I15: Pantalla activa de Ruta Despeje. | J15: Procesar documento y continuar a revisión; clave no se persiste como atributo de deuda. | L15: Sí | P15: Walvy_M04_Matriz_Trazabilidad_Cliente_v1.3.xlsx · 01_Matriz_Trazabilidad · TR-M04-055 | Q15: En: Pantalla activa de Ruta Despeje. → Procesar documento y continuar a revisión; clave no se persiste como atributo de deuda.
A16: M04 | B16: TR-M04-056 | C16: F1 · QA funcional local | D16: FLOW-M04-004 · Onboarding 1 · Documento protegido | E16: Clave incorrecta | F16: Estado requiere clave | Reintentar | G16: Cuenta de prueba activa y reseteada (sin deudas ni datos previos del flujo). Condición de entrada: Estado requiere clave | Reintentar | H16: 1. Continuar desde TR-M04-054 (app mostrando estado «requiere clave»). 2. Ingresar una clave incorrecta. 3. Verificar que la app muestra error de clave incorrecta y permite reintentar. 4. Verificar que el documento sigue en estado «requiere clave» (no se descarta automáticamente). 5. Verificar que NO se crea ninguna deuda ni avanza el flujo con la clave errónea. → Si permite reintento sin descartar el documento: ✓ PASA. CIERRE · Registrar resultado en «Resultado obtenido» y marcar «Estado QA». · Resetear cuenta solo si el siguiente caso requiere estado diferente al actual. (Perfil → Herramientas QA → «Reiniciar cuenta de prueba» (doble confirmación)) | I16: Pantalla activa de Ruta Despeje. | J16: Mantener recuperación; permitir reintento u otro documento sin confirmar deuda. | L16: Sí | P16: Walvy_M04_Matriz_Trazabilidad_Cliente_v1.3.xlsx · 01_Matriz_Trazabilidad · TR-M04-056 | Q16: En: Pantalla activa de Ruta Despeje. → Mantener recuperación; permitir reintento u otro documento sin confirmar deuda.
A17: M04 | B17: TR-M04-057 | C17: F1 · QA funcional local | D17: FLOW-M04-004 · Onboarding 1 · Documento protegido | E17: Usuario no dispone de clave | F17: Estado requiere clave | Alternativa | G17: Cuenta de prueba activa y reseteada (sin deudas ni datos previos del flujo). Condición de entrada: Estado requiere clave | Alternativa | H17: 1. Continuar desde TR-M04-054 (app mostrando estado «requiere clave»). 2. Sin ingresar clave, desplazarse en la pantalla de Carga: verificar que siguen visibles «Cargar más documentos» y «Agregar deuda manual». 3. Verificar que el flujo M04 NO queda bloqueado; el usuario puede continuar por otra vía sin necesidad de resolver la clave del documento protegido. 4. Seleccionar «Agregar deuda manual» o «Cargar más documentos» y verificar que navega correctamente. → Si el flujo continúa sin bloqueo usando las alternativas de la pantalla: ✓ PASA. Nota: No existe CTA «No tengo la clave». El contrato define que al pedir clave se vuelve a la pantalla de Carga, donde las alternativas ya están disponibles. CIERRE · Registrar resultado en «Resultado obtenido» y marcar «Estado QA». · Resetear cuenta solo si el siguiente caso requiere estado diferente al actual. (Perfil → Herramientas QA → «Reiniciar cuenta de prueba» (doble confirmación)) | I17: Pantalla activa de Ruta Despeje. | J17: Permitir subir otro documento o registrar manualmente; flujo M04 no queda bloqueado. | L17: Sí | P17: Walvy_M04_Matriz_Trazabilidad_Cliente_v1.3.xlsx · 01_Matriz_Trazabilidad · TR-M04-057 | Q17: En: Pantalla activa de Ruta Despeje. → Permitir subir otro documento o registrar manualmente; flujo M04 no queda bloqueado.
A18: M04 | B18: TR-M04-058 | C18: F1 · QA funcional local | D18: FLOW-M04-005 · Onboarding 1 · Error documento | E18: Documento no procesable o sin datos suficientes | F18: Carga/Analizando | Error de procesamiento | G18: Cuenta de prueba activa y reseteada (sin deudas ni datos previos del flujo). Condición de entrada: Carga/Analizando | Error de procesamiento | H18: 1. Iniciar sesión con la cuenta de prueba reseteada. 2. Navegar a: OD-01 «Agrega tus deudas» → cargar documentos. 3. Subir un archivo que no sea procesable: imagen sin texto, PDF en blanco, o archivo dañado. 4. Verificar que la app muestra un error de procesamiento (no un spinner infinito). 5. Verificar que la app ofrece alternativas: subir otro documento o registrar manualmente. 6. Verificar que NO se crea ninguna deuda confirmada ni se produce una lectura fuerte del archivo. → Si el error es explícito y ofrece alternativa sin crear deudas: ✓ PASA. CIERRE · Registrar resultado en «Resultado obtenido» y marcar «Estado QA». · Resetear cuenta solo si el siguiente caso requiere estado diferente al actual. (Perfil → Herramientas QA → «Reiniciar cuenta de prueba» (doble confirmación)) | I18: Pantalla activa de Ruta Despeje. | J18: Ofrecer otro documento o carga manual; no producir deuda confirmada ni lectura fuerte. | L18: Sí | P18: Walvy_M04_Matriz_Trazabilidad_Cliente_v1.3.xlsx · 01_Matriz_Trazabilidad · TR-M04-058 | Q18: En: Pantalla activa de Ruta Despeje. → Ofrecer otro documento o carga manual; no producir deuda confirmada ni lectura fuerte.
A19: M04 | B19: TR-M04-059 | C19: F1 · QA funcional local | D19: FLOW-M04-006 · Onboarding 2 · Revisión | E19: Deuda detectada con datos suficientes y sin confirmación | F19: OD-02 | Confirmar deuda | G19: Cuenta de prueba activa y reseteada (sin deudas ni datos previos del flujo). Condición de entrada: OD-02 | Confirmar deuda | H19: 1. Iniciar sesión con la cuenta de prueba reseteada. 2. Subir un documento válido con al menos una deuda identificable (o usar cuenta seed con deuda detectada). 3. Navegar a: OD-02 «Revisar deudas detectadas». 4. Localizar la deuda detectada (con datos suficientes: tipo, saldo, acreedor, cuota). 5. Tocar «Confirmar» en la deuda. 6. Verificar que el estado de la deuda cambia a confirmada (confirmationStatus=confirmed). 7. Verificar que confirmar la deuda NO activa automáticamente la Ruta (permanece en revisión). → Si la deuda queda confirmada y la Ruta no se activa sola: ✓ PASA. CIERRE · Registrar resultado en «Resultado obtenido» y marcar «Estado QA». · Resetear cuenta solo si el siguiente caso requiere estado diferente al actual. (Perfil → Herramientas QA → «Reiniciar cuenta de prueba» (doble confirmación)) | I19: Pantalla activa de Ruta Despeje. | J19: Cambiar confirmation_status a confirmed; mantener separación entre confirmar y activar Ruta. | L19: Sí | P19: Walvy_M04_Matriz_Trazabilidad_Cliente_v1.3.xlsx · 01_Matriz_Trazabilidad · TR-M04-059 | Q19: En: Pantalla activa de Ruta Despeje. → Cambiar confirmation_status a confirmed; mantener separación entre confirmar y activar Ruta.
