Workbook

Sheet Matriz Trazabilidad
A1: WALVY | M6 – Matriz de trazabilidad para validación con Cliente
A2: Cadena de trazabilidad: Historia de Usuario → Criterio de Aceptación → Regla Funcional → Variante → Caso de Prueba → Evidencia QA. Las HU de esta matriz se derivan de F1–F5 para ordenar la trazabilidad; las definiciones exclusivamente visuales de Figma permanecen identificadas como referencia visual/pendiente de validación cuando corresponda.
A4: ID Variante | B4: Flujo / Subflujo | C4: Variante / Escenario | D4: Condición / Disparador | E4: Comportamiento esperado | F4: HU asociada | G4: CA asociado | H4: Regla de negocio asociada | I4: Origen / Estado RN | J4: Código fuente RN | K4: Descripción fuente RN | L4: Caso de Prueba | M4: Evidencia QA | N4: Estado evidencia | O4: Nodo Figma | P4: URL Figma | Q4: Clasificación de soporte | R4: Validación Cliente | S4: Decisión PO / Comentarios | T4: ID Pendiente Cliente
A5: M6-V01 | B5: Pagos / Hub | C5: Sin pagos registrados | D5: Usuario no tiene cuentas por pagar registradas | E5: Mostrar empty state orientativo y CTA Registrar cuenta por pagar, sin presión artificial. | F5: M6-HU-017 | G5: CA1 | H5: R-M6-001 / BDD-M6-024 | I5: MVP | J5: F2 | F4 | F5 | M6-BP | K5: Fase 2 – Inventario de Pantallas, Estados y Componentes M6 Pagos v1.0: superficies, pantallas candidatas, estados, componentes, CTAs y acciones. Fase 4 – Copy UX, CTAs y Mensajería Contextual M6 Pagos v1.0: CTAs oficiales, copy permitido/restringido/prohibido y mensajes por estado. Fase 5 – Briefing UX y Matriz Maestra de Obligaciones UX M6 Pagos v1.0: obligaciones UX OUX-M6-001..024, superficies, prioridad y guardrails. Blueprint plaintext M6-FLOW-02: nodos M6-SCR-01..11, cards, modales, rutas, retornos, memoria y señales externas. | L5: CP-M6-001 | M5: Pendiente de evidencia QA ejecutada | N5: Pendiente | O5: 8859:31712 · ID lógico blueprint M6-SCR-01 / M6-SCR-10 | P5: https://www.figma.com/design/v45c4HTKnPnU0XABMa5vjY/Walvi-APP---Edificate-Inteligente?node-id=8859-31712 | Q5: Confirmado documental + Figma sección | R5: Pendiente
A6: M6-V02 | B6: Pagos / Hub | C6: Consolidado con pagos en distintos estados | D6: Existen compromisos registrados o detectados | E6: Mostrar una superficie Pagos o equivalente que permita distinguir Pendiente, Próximo, Vencido, Pagado, Detectado, Revisión, recurrencia y duplicidad con acciones seguras. | F6: M6-HU-001 | G6: CA1-CA3 | H6: R-M6-001 / R-M6-020 / R-M6-030 / R-M6-040 | I6: MVP | J6: F1 | F2 | F5 | M6-BP | K6: Fase 1 – Definición Funcional M6 Pagos v1.0: propósito, alcance MVP, estados, reglas base, dependencias y guardrails. Fase 2 – Inventario de Pantallas, Estados y Componentes M6 Pagos v1.0: superficies, pantallas candidatas, estados, componentes, CTAs y acciones. Fase 5 – Briefing UX y Matriz Maestra de Obligaciones UX M6 Pagos v1.0: obligaciones UX OUX-M6-001..024, superficies, prioridad y guardrails. Blueprint plaintext M6-FLOW-02: nodos M6-SCR-01..11, cards, modales, rutas, retornos, memoria y señales externas. | L6: CP-M6-002 | M6: Pendiente de evidencia QA ejecutada | N6: Pendiente | O6: 8859:31712 · ID lógico blueprint M6-SCR-01 | P6: https://www.figma.com/design/v45c4HTKnPnU0XABMa5vjY/Walvi-APP---Edificate-Inteligente?node-id=8859-31712 | Q6: Confirmado documental; arquitectura visual final pendiente + Figma sección | R6: Pendiente | T6: PD-M6-02
A7: M6-V03 | B7: Pagos / Detalle | C7: Revisar detalle de pago | D7: Usuario abre Ver detalle / Revisar pago | E7: Mostrar estado, fecha, monto, origen, relación y acciones seguras; no representar checkout ni confirmación bancaria. | F7: M6-HU-001 / M6-HU-009 | G7: CA2-CA3 | H7: R-M6-050 / R-M6-051 | I7: MVP | J7: F2 | F4 | F5 | M6-BP | K7: Fase 2 – Inventario de Pantallas, Estados y Componentes M6 Pagos v1.0: superficies, pantallas candidatas, estados, componentes, CTAs y acciones. Fase 4 – Copy UX, CTAs y Mensajería Contextual M6 Pagos v1.0: CTAs oficiales, copy permitido/restringido/prohibido y mensajes por estado. Fase 5 – Briefing UX y Matriz Maestra de Obligaciones UX M6 Pagos v1.0: obligaciones UX OUX-M6-001..024, superficies, prioridad y guardrails. Blueprint plaintext M6-FLOW-02: nodos M6-SCR-01..11, cards, modales, rutas, retornos, memoria y señales externas. | L7: CP-M6-003 | M7: Pendiente de evidencia QA ejecutada | N7: Pendiente | O7: 8859:31712 · ID lógico blueprint M6-SCR-02 | P7: https://www.figma.com/design/v45c4HTKnPnU0XABMa5vjY/Walvi-APP---Edificate-Inteligente?node-id=8859-31712 | Q7: Confirmado documental + Figma sección | R7: Pendiente
A8: M6-V04 | B8: Alta manual | C8: Registro completo | D8: Usuario ingresa descripción y fecha de vencimiento | E8: Crear cuenta activa en estado Pendiente, conservar origen manual y no ejecutar pago. | F8: M6-HU-002 | G8: CA1 / CA3 | H8: R-M6-001 / R-M6-004 | I8: MVP | J8: F1 | F3 | M6-BP | K8: Fase 1 – Definición Funcional M6 Pagos v1.0: propósito, alcance MVP, estados, reglas base, dependencias y guardrails. Fase 3 – Reglas Funcionales, Severidad y Anexo BDD M6 Pagos v1.0: reglas R-M6, severidad, semáforo de presión, señales intermodulares y BDD. Blueprint plaintext M6-FLOW-02: nodos M6-SCR-01..11, cards, modales, rutas, retornos, memoria y señales externas. | L8: CP-M6-004 | M8: Pendiente de evidencia QA ejecutada | N8: Pendiente | O8: 8859:31712 · ID lógico blueprint M6-SCR-03 | P8: https://www.figma.com/design/v45c4HTKnPnU0XABMa5vjY/Walvi-APP---Edificate-Inteligente?node-id=8859-31712 | Q8: Confirmado documental + Figma sección | R8: Pendiente
A9: M6-V05 | B9: Alta manual | C9: Registro incompleto | D9: Falta descripción o fecha de vencimiento | E9: Mantener Borrador / Sin datos suficientes; CTA Completar datos; no gatillar alerta fuerte. | F9: M6-HU-002 / M6-HU-004 | G9: CA2 | H9: R-M6-002 / R-M6-080 / R-M6-081 / BDD-M6-002 | I9: MVP | J9: F3 | F4 | M6-BP | K9: Fase 3 – Reglas Funcionales, Severidad y Anexo BDD M6 Pagos v1.0: reglas R-M6, severidad, semáforo de presión, señales intermodulares y BDD. Fase 4 – Copy UX, CTAs y Mensajería Contextual M6 Pagos v1.0: CTAs oficiales, copy permitido/restringido/prohibido y mensajes por estado. Blueprint plaintext M6-FLOW-02: nodos M6-SCR-01..11, cards, modales, rutas, retornos, memoria y señales externas. | L9: CP-M6-005 | M9: Pendiente de evidencia QA ejecutada | N9: Pendiente | O9: 8859:31712 · ID lógico blueprint M6-SCR-03 / M6-SCR-10 | P9: https://www.figma.com/design/v45c4HTKnPnU0XABMa5vjY/Walvi-APP---Edificate-Inteligente?node-id=8859-31712 | Q9: Confirmado documental + Figma sección | R9: Pendiente
A10: M6-V06 | B10: Alta manual | C10: Monto ausente | D10: Descripción y fecha existen, pero falta monto | E10: La cuenta puede existir, pero el impacto económico no debe elevarse a severidad crítica solo por monto ausente. | F10: M6-HU-002 / M6-HU-004 | G10: CA1-CA2 | H10: R-M6-003 / R-M6-082 | I10: MVP | J10: F3 | K10: Fase 3 – Reglas Funcionales, Severidad y Anexo BDD M6 Pagos v1.0: reglas R-M6, severidad, semáforo de presión, señales intermodulares y BDD. | L10: CP-M6-006 | M10: Pendiente de evidencia QA ejecutada | N10: Pendiente | O10: 8859:31712 · ID lógico blueprint M6-SCR-03 | P10: https://www.figma.com/design/v45c4HTKnPnU0XABMa5vjY/Walvi-APP---Edificate-Inteligente?node-id=8859-31712 | Q10: Confirmado documental + Figma sección | R10: Pendiente
A11: M6-V07 | B11: Candidato detectado | C11: Crear candidato, no cuenta confirmada | D11: Captura, ingesta, glosa, documento, cartola o patrón sugiere un pago | E11: Crear estado Detectado con origen/confianza; no consolidar automáticamente. | F11: M6-HU-003 | G11: CA1 / CA3 | H11: R-M6-010 / R-M6-011 | I11: MVP | J11: F1 | F3 | F5 | M6-BP | K11: Fase 1 – Definición Funcional M6 Pagos v1.0: propósito, alcance MVP, estados, reglas base, dependencias y guardrails. Fase 3 – Reglas Funcionales, Severidad y Anexo BDD M6 Pagos v1.0: reglas R-M6, severidad, semáforo de presión, señales intermodulares y BDD. Fase 5 – Briefing UX y Matriz Maestra de Obligaciones UX M6 Pagos v1.0: obligaciones UX OUX-M6-001..024, superficies, prioridad y guardrails. Blueprint plaintext M6-FLOW-02: nodos M6-SCR-01..11, cards, modales, rutas, retornos, memoria y señales externas. | L11: CP-M6-007 | M11: Pendiente de evidencia QA ejecutada | N11: Pendiente | O11: 8859:31712 · ID lógico blueprint M6-SCR-04 | P11: https://www.figma.com/design/v45c4HTKnPnU0XABMa5vjY/Walvi-APP---Edificate-Inteligente?node-id=8859-31712 | Q11: Confirmado documental + Figma sección | R11: Pendiente
A12: M6-V08 | B12: Candidato detectado | C12: Confirmar cuenta detectada | D12: Candidato con datos mínimos y usuario confirma | E12: Transformar a Pendiente, Próximo o Pagado según contexto; usar CTA oficial Confirmar cuenta / Confirmar como pago pendiente. | F12: M6-HU-003 | G12: CA2-CA3 | H12: R-M6-013 / BDD-M6-003 | I12: MVP | J12: F3 | F4 | F5 | M6-BP | K12: Fase 3 – Reglas Funcionales, Severidad y Anexo BDD M6 Pagos v1.0: reglas R-M6, severidad, semáforo de presión, señales intermodulares y BDD. Fase 4 – Copy UX, CTAs y Mensajería Contextual M6 Pagos v1.0: CTAs oficiales, copy permitido/restringido/prohibido y mensajes por estado. Fase 5 – Briefing UX y Matriz Maestra de Obligaciones UX M6 Pagos v1.0: obligaciones UX OUX-M6-001..024, superficies, prioridad y guardrails. Blueprint plaintext M6-FLOW-02: nodos M6-SCR-01..11, cards, modales, rutas, retornos, memoria y señales externas. | L12: CP-M6-008 | M12: Pendiente de evidencia QA ejecutada | N12: Pendiente | O12: 8859:31712 · ID lógico blueprint M6-SCR-04 | P12: https://www.figma.com/design/v45c4HTKnPnU0XABMa5vjY/Walvi-APP---Edificate-Inteligente?node-id=8859-31712 | Q12: Confirmado documental + Figma sección | R12: Pendiente
A13: M6-V09 | B13: Candidato detectado | C13: Corregir candidato | D13: Usuario corrige datos antes de consolidar | E13: Guardar dato corregido como fuente funcional prioritaria, conservar origen original y recalcular estado. | F13: M6-HU-003 | G13: CA1-CA3 | H13: R-M6-014 / BDD-M6-004 | I13: MVP | J13: F3 | F4 | M6-BP | K13: Fase 3 – Reglas Funcionales, Severidad y Anexo BDD M6 Pagos v1.0: reglas R-M6, severidad, semáforo de presión, señales intermodulares y BDD. Fase 4 – Copy UX, CTAs y Mensajería Contextual M6 Pagos v1.0: CTAs oficiales, copy permitido/restringido/prohibido y mensajes por estado. Blueprint plaintext M6-FLOW-02: nodos M6-SCR-01..11, cards, modales, rutas, retornos, memoria y señales externas. | L13: CP-M6-009 | M13: Pendiente de evidencia QA ejecutada | N13: Pendiente | O13: 8859:31712 · ID lógico blueprint M6-SCR-04 | P13: https://www.figma.com/design/v45c4HTKnPnU0XABMa5vjY/Walvi-APP---Edificate-Inteligente?node-id=8859-31712 | Q13: Confirmado documental + Figma sección | R13: Pendiente
A14: M6-V10 | B14: Candidato detectado | C14: Descartar candidato | D14: Usuario indica que el candidato no corresponde | E14: Estado Descartado; evitar reproponer de forma insistente salvo nueva señal/dato/regla. | F14: M6-HU-003 | G14: CA3 | H14: R-M6-015 / BDD-M6-005 | I14: MVP | J14: F3 | F4 | M6-BP | K14: Fase 3 – Reglas Funcionales, Severidad y Anexo BDD M6 Pagos v1.0: reglas R-M6, severidad, semáforo de presión, señales intermodulares y BDD. Fase 4 – Copy UX, CTAs y Mensajería Contextual M6 Pagos v1.0: CTAs oficiales, copy permitido/restringido/prohibido y mensajes por estado. Blueprint plaintext M6-FLOW-02: nodos M6-SCR-01..11, cards, modales, rutas, retornos, memoria y señales externas. | L14: CP-M6-010 | M14: Pendiente de evidencia QA ejecutada | N14: Pendiente | O14: 8859:31712 · ID lógico blueprint M6-SCR-04 | P14: https://www.figma.com/design/v45c4HTKnPnU0XABMa5vjY/Walvi-APP---Edificate-Inteligente?node-id=8859-31712 | Q14: Confirmado documental + Figma sección | R14: Pendiente
A15: M6-V11 | B15: Candidato detectado | C15: Baja confianza | D15: Candidato con dato ambiguo o de baja confianza | E15: Mantener Requiere revisión; CTA Revisar dato; no consolidar ni escalar a alerta crítica. | F15: M6-HU-004 | G15: CA1-CA3 | H15: R-M6-012 / R-M6-083 / R-M6-084 / BDD-M6-006 | I15: MVP | J15: F3 | F4 | F5 | M6-BP | K15: Fase 3 – Reglas Funcionales, Severidad y Anexo BDD M6 Pagos v1.0: reglas R-M6, severidad, semáforo de presión, señales intermodulares y BDD. Fase 4 – Copy UX, CTAs y Mensajería Contextual M6 Pagos v1.0: CTAs oficiales, copy permitido/restringido/prohibido y mensajes por estado. Fase 5 – Briefing UX y Matriz Maestra de Obligaciones UX M6 Pagos v1.0: obligaciones UX OUX-M6-001..024, superficies, prioridad y guardrails. Blueprint plaintext M6-FLOW-02: nodos M6-SCR-01..11, cards, modales, rutas, retornos, memoria y señales externas. | L15: CP-M6-011 | M15: Pendiente de evidencia QA ejecutada | N15: Pendiente | O15: 8859:31712 · ID lógico blueprint M6-SCR-10 | P15: https://www.figma.com/design/v45c4HTKnPnU0XABMa5vjY/Walvi-APP---Edificate-Inteligente?node-id=8859-31712 | Q15: Confirmado documental + Figma sección | R15: Pendiente
A16: M6-V12 | B16: Vencimiento | C16: Paso a Próximo | D16: Cuenta Pendiente entra en umbral funcional | E16: Cambiar a Próximo con severidad Atención; umbral parametrizable. | F16: M6-HU-005 | G16: CA1 | H16: R-M6-020 / R-M6-021 / BDD-M6-007 | I16: MVP – parametrizable | J16: F3 | F5 | K16: Fase 3 – Reglas Funcionales, Severidad y Anexo BDD M6 Pagos v1.0: reglas R-M6, severidad, semáforo de presión, señales intermodulares y BDD. Fase 5 – Briefing UX y Matriz Maestra de Obligaciones UX M6 Pagos v1.0: obligaciones UX OUX-M6-001..024, superficies, prioridad y guardrails. | L16: CP-M6-012 | M16: Pendiente de evidencia QA ejecutada | N16: Pendiente | O16: 8859:31712 · ID lógico blueprint M6-SCR-01 / M6-SCR-02 | P16: https://www.figma.com/design/v45c4HTKnPnU0XABMa5vjY/Walvi-APP---Edificate-Inteligente?node-id=8859-31712 | Q16: Confirmado documental + Figma sección | R16: Pendiente | T16: PD-M6-01
A17: M6-V13 | B17: Vencimiento | C17: Próximo con impacto relevante | D17: Pago Próximo tiene fecha/origen confiables y alto impacto o deuda asociada | E17: Puede elevarse a Urgente y gatillar señal/recordatorio seguro; no implica pago directo. | F17: M6-HU-005 | G17: CA2-CA3 | H17: R-M6-023 / R-M6-090 | I17: MVP | J17: F3 | F4 | K17: Fase 3 – Reglas Funcionales, Severidad y Anexo BDD M6 Pagos v1.0: reglas R-M6, severidad, semáforo de presión, señales intermodulares y BDD. Fase 4 – Copy UX, CTAs y Mensajería Contextual M6 Pagos v1.0: CTAs oficiales, copy permitido/restringido/prohibido y mensajes por estado. | L17: CP-M6-013 | M17: Pendiente de evidencia QA ejecutada | N17: Pendiente | O17: 8859:31712 · ID lógico blueprint M6-SCR-01 / M6-SCR-02 | P17: https://www.figma.com/design/v45c4HTKnPnU0XABMa5vjY/Walvi-APP---Edificate-Inteligente?node-id=8859-31712 | Q17: Confirmado documental + Figma sección | R17: Pendiente | T17: PD-M6-05
A18: M6-V14 | B18: Vencimiento | C18: Próximo sin fecha confiable | D18: Falta fecha confiable, origen claro o dato suficiente | E18: Mantener Requiere revisión / Atención; no gatillar urgencia ni criticidad. | F18: M6-HU-004 / M6-HU-005 | G18: CA2-CA3 | H18: R-M6-024 / R-M6-080 | I18: MVP | J18: F3 | F4 | K18: Fase 3 – Reglas Funcionales, Severidad y Anexo BDD M6 Pagos v1.0: reglas R-M6, severidad, semáforo de presión, señales intermodulares y BDD. Fase 4 – Copy UX, CTAs y Mensajería Contextual M6 Pagos v1.0: CTAs oficiales, copy permitido/restringido/prohibido y mensajes por estado. | L18: CP-M6-014 | M18: Pendiente de evidencia QA ejecutada | N18: Pendiente | O18: 8859:31712 · ID lógico blueprint M6-SCR-10 | P18: https://www.figma.com/design/v45c4HTKnPnU0XABMa5vjY/Walvi-APP---Edificate-Inteligente?node-id=8859-31712 | Q18: Confirmado documental + Figma sección | R18: Pendiente
A19: M6-V15 | B19: Vencimiento | C19: Pago vencido | D19: Fecha confiable superada sin pago registrado ni vínculo suficiente | E19: Estado Vencido, severidad Urgente; puede gatillar alerta operativa; CTA Registrar pago realizado / Revisar pago. | F19: M6-HU-006 | G19: CA1-CA3 | H19: R-M6-030 / R-M6-033 / BDD-M6-008 / BDD-M6-018 | I19: MVP | J19: F3 | F4 | F5 | K19: Fase 3 – Reglas Funcionales, Severidad y Anexo BDD M6 Pagos v1.0: reglas R-M6, severidad, semáforo de presión, señales intermodulares y BDD. Fase 4 – Copy UX, CTAs y Mensajería Contextual M6 Pagos v1.0: CTAs oficiales, copy permitido/restringido/prohibido y mensajes por estado. Fase 5 – Briefing UX y Matriz Maestra de Obligaciones UX M6 Pagos v1.0: obligaciones UX OUX-M6-001..024, superficies, prioridad y guardrails. | L19: CP-M6-015 | M19: Pendiente de evidencia QA ejecutada | N19: Pendiente | O19: 8859:31712 · ID lógico blueprint M6-SCR-01 / M6-SCR-02 | P19: https://www.figma.com/design/v45c4HTKnPnU0XABMa5vjY/Walvi-APP---Edificate-Inteligente?node-id=8859-31712 | Q19: Confirmado documental + Figma sección | R19: Pendiente
A20: M6-V16 | B20: Vencimiento | C20: Pago vencido con severidad crítica | D20: Vencido con datos confiables y monto relevante, deuda bajo presión, mora, pago parcial/mínimo recurrente o fuerte impacto | E20: Elevar a Crítica internamente y mostrar revisión prioritaria sin usar 'crítico' como etiqueta visible por defecto. | F20: M6-HU-006 / M6-HU-018 | G20: CA2-CA3 | H20: R-M6-031 / R-M6-035 | I20: MVP | J20: F3 | F4 | F5 | K20: Fase 3 – Reglas Funcionales, Severidad y Anexo BDD M6 Pagos v1.0: reglas R-M6, severidad, semáforo de presión, señales intermodulares y BDD. Fase 4 – Copy UX, CTAs y Mensajería Contextual M6 Pagos v1.0: CTAs oficiales, copy permitido/restringido/prohibido y mensajes por estado. Fase 5 – Briefing UX y Matriz Maestra de Obligaciones UX M6 Pagos v1.0: obligaciones UX OUX-M6-001..024, superficies, prioridad y guardrails. | L20: CP-M6-016 | M20: Pendiente de evidencia QA ejecutada | N20: Pendiente | O20: 8859:31712 · ID lógico blueprint M6-SCR-01 / M6-SCR-02 | P20: https://www.figma.com/design/v45c4HTKnPnU0XABMa5vjY/Walvi-APP---Edificate-Inteligente?node-id=8859-31712 | Q20: Confirmado documental + Figma sección | R20: Pendiente | T20: PD-M6-05
A21: M6-V17 | B21: Vencimiento | C21: Vencido con datos insuficientes | D21: Monto/origen/fecha ambiguos o baja confianza | E21: No escalar a Crítica; mantener Requiere revisión / Atención. | F21: M6-HU-004 / M6-HU-006 | G21: CA1-CA3 | H21: R-M6-032 / R-M6-084 | I21: MVP | J21: F3 | F4 | K21: Fase 3 – Reglas Funcionales, Severidad y Anexo BDD M6 Pagos v1.0: reglas R-M6, severidad, semáforo de presión, señales intermodulares y BDD. Fase 4 – Copy UX, CTAs y Mensajería Contextual M6 Pagos v1.0: CTAs oficiales, copy permitido/restringido/prohibido y mensajes por estado. | L21: CP-M6-017 | M21: Pendiente de evidencia QA ejecutada | N21: Pendiente | O21: 8859:31712 · ID lógico blueprint M6-SCR-10 | P21: https://www.figma.com/design/v45c4HTKnPnU0XABMa5vjY/Walvi-APP---Edificate-Inteligente?node-id=8859-31712 | Q21: Confirmado documental + Figma sección | R21: Pendiente
A22: M6-V18 | B22: Pago realizado | C22: Registrar desde Pendiente/Próximo/Vencido | D22: Usuario declara que ya pagó fuera de Walvy | E22: Estado Pagado; conservar fecha/origen/actor; limpiar o reducir señal pendiente sin borrar historial. | F22: M6-HU-007 | G22: CA1-CA3 | H22: R-M6-040 / R-M6-041 / R-M6-042 / BDD-M6-009 | I22: MVP | J22: F1 | F3 | F4 | F5 | M6-BP | K22: Fase 1 – Definición Funcional M6 Pagos v1.0: propósito, alcance MVP, estados, reglas base, dependencias y guardrails. Fase 3 – Reglas Funcionales, Severidad y Anexo BDD M6 Pagos v1.0: reglas R-M6, severidad, semáforo de presión, señales intermodulares y BDD. Fase 4 – Copy UX, CTAs y Mensajería Contextual M6 Pagos v1.0: CTAs oficiales, copy permitido/restringido/prohibido y mensajes por estado. Fase 5 – Briefing UX y Matriz Maestra de Obligaciones UX M6 Pagos v1.0: obligaciones UX OUX-M6-001..024, superficies, prioridad y guardrails. Blueprint plaintext M6-FLOW-02: nodos M6-SCR-01..11, cards, modales, rutas, retornos, memoria y señales externas. | L22: CP-M6-018 | M22: Pendiente de evidencia QA ejecutada | N22: Pendiente | O22: 8859:31712 · ID lógico blueprint M6-SCR-05 | P22: https://www.figma.com/design/v45c4HTKnPnU0XABMa5vjY/Walvi-APP---Edificate-Inteligente?node-id=8859-31712 | Q22: Confirmado documental + Figma sección | R22: Pendiente
A23: M6-V19 | B23: Pago realizado | C23: Pago realizado probable por ingesta | D23: Documento/cartola/movimiento sugiere que el pago ocurrió fuera de Walvy | E23: Representar Pago realizado probable; si coincidencia/validación suficiente puede registrarse Pagado; si no, mantener sugerencia/revisión. | F23: M6-HU-007 / M6-HU-009 | G23: CA1-CA3 | H23: R-M6-050 / R-M6-052 / R-M6-056 / R-M6-057 / BDD-M6-015 | I23: MVP | J23: F3 | F4 | M6-BP | K23: Fase 3 – Reglas Funcionales, Severidad y Anexo BDD M6 Pagos v1.0: reglas R-M6, severidad, semáforo de presión, señales intermodulares y BDD. Fase 4 – Copy UX, CTAs y Mensajería Contextual M6 Pagos v1.0: CTAs oficiales, copy permitido/restringido/prohibido y mensajes por estado. Blueprint plaintext M6-FLOW-02: nodos M6-SCR-01..11, cards, modales, rutas, retornos, memoria y señales externas. | L23: CP-M6-019 | M23: Pendiente de evidencia QA ejecutada | N23: Pendiente | O23: 8859:31712 · ID lógico blueprint M6-SCR-07 / M6-SCR-02 | P23: https://www.figma.com/design/v45c4HTKnPnU0XABMa5vjY/Walvi-APP---Edificate-Inteligente?node-id=8859-31712 | Q23: Confirmado documental + Figma sección | R23: Pendiente
A24: M6-V20 | B24: Pago realizado | C24: Corregir pago marcado | D24: Usuario detecta un dato incorrecto en un registro Pagado | E24: Permitir corregir fecha, monto, origen o vínculo; conservar historial funcional. | F24: M6-HU-008 | G24: CA1-CA3 | H24: R-M6-043 / R-M6-044 / R-M6-045 / BDD-M6-010 | I24: MVP | J24: F3 | F4 | F5 | M6-BP | K24: Fase 3 – Reglas Funcionales, Severidad y Anexo BDD M6 Pagos v1.0: reglas R-M6, severidad, semáforo de presión, señales intermodulares y BDD. Fase 4 – Copy UX, CTAs y Mensajería Contextual M6 Pagos v1.0: CTAs oficiales, copy permitido/restringido/prohibido y mensajes por estado. Fase 5 – Briefing UX y Matriz Maestra de Obligaciones UX M6 Pagos v1.0: obligaciones UX OUX-M6-001..024, superficies, prioridad y guardrails. Blueprint plaintext M6-FLOW-02: nodos M6-SCR-01..11, cards, modales, rutas, retornos, memoria y señales externas. | L24: CP-M6-020 | M24: Pendiente de evidencia QA ejecutada | N24: Pendiente | O24: 8859:31712 · ID lógico blueprint M6-SCR-06 | P24: https://www.figma.com/design/v45c4HTKnPnU0XABMa5vjY/Walvi-APP---Edificate-Inteligente?node-id=8859-31712 | Q24: Confirmado documental + Figma sección | R24: Pendiente
A25: M6-V21 | B25: Pago realizado | C25: Deshacer pago marcado | D25: Usuario deshace un pago realizado por error | E25: Recalcular a Pendiente, Próximo, Vencido, Requiere revisión o Corregido según datos vigentes; mantener trazabilidad. | F25: M6-HU-008 | G25: CA1-CA3 | H25: R-M6-043 / R-M6-044 / BDD-M6-010 | I25: MVP | J25: F3 | F4 | M6-BP | K25: Fase 3 – Reglas Funcionales, Severidad y Anexo BDD M6 Pagos v1.0: reglas R-M6, severidad, semáforo de presión, señales intermodulares y BDD. Fase 4 – Copy UX, CTAs y Mensajería Contextual M6 Pagos v1.0: CTAs oficiales, copy permitido/restringido/prohibido y mensajes por estado. Blueprint plaintext M6-FLOW-02: nodos M6-SCR-01..11, cards, modales, rutas, retornos, memoria y señales externas. | L25: CP-M6-021 | M25: Pendiente de evidencia QA ejecutada | N25: Pendiente | O25: 8859:31712 · ID lógico blueprint M6-SCR-06 | P25: https://www.figma.com/design/v45c4HTKnPnU0XABMa5vjY/Walvi-APP---Edificate-Inteligente?node-id=8859-31712 | Q25: Confirmado documental + Figma sección | R25: Pendiente
A26: M6-V22 | B26: Origen del dato | C26: Mostrar origen asociado | D26: Pago tiene registro manual o dato detectado asociado | E26: Mostrar origen/registro de forma acotada; no interpretarlo como comprobante formal, pago ejecutado o deuda cerrada. | F26: M6-HU-009 | G26: CA1-CA2 | H26: R-M6-050 / R-M6-051 | I26: MVP | J26: F3 | F4 | F5 | M6-BP | K26: Fase 3 – Reglas Funcionales, Severidad y Anexo BDD M6 Pagos v1.0: reglas R-M6, severidad, semáforo de presión, señales intermodulares y BDD. Fase 4 – Copy UX, CTAs y Mensajería Contextual M6 Pagos v1.0: CTAs oficiales, copy permitido/restringido/prohibido y mensajes por estado. Fase 5 – Briefing UX y Matriz Maestra de Obligaciones UX M6 Pagos v1.0: obligaciones UX OUX-M6-001..024, superficies, prioridad y guardrails. Blueprint plaintext M6-FLOW-02: nodos M6-SCR-01..11, cards, modales, rutas, retornos, memoria y señales externas. | L26: CP-M6-022 | M26: Pendiente de evidencia QA ejecutada | N26: Pendiente | O26: 8859:31712 · ID lógico blueprint M6-SCR-07 | P26: https://www.figma.com/design/v45c4HTKnPnU0XABMa5vjY/Walvi-APP---Edificate-Inteligente?node-id=8859-31712 | Q26: Confirmado documental + Figma sección | R26: Pendiente
A27: M6-V23 | B27: Origen del dato | C27: Dato detectado con coincidencia mínima | D27: Existe coincidencia funcional por monto, fecha, glosa, categoría/proveedor u otro identificador razonable | E27: Permitir vínculo/revisión con confianza media/alta; no consolidar de forma opaca. | F27: M6-HU-009 | G27: CA1-CA3 | H27: R-M6-052 | I27: MVP | J27: F3 | F4 | M6-BP | K27: Fase 3 – Reglas Funcionales, Severidad y Anexo BDD M6 Pagos v1.0: reglas R-M6, severidad, semáforo de presión, señales intermodulares y BDD. Fase 4 – Copy UX, CTAs y Mensajería Contextual M6 Pagos v1.0: CTAs oficiales, copy permitido/restringido/prohibido y mensajes por estado. Blueprint plaintext M6-FLOW-02: nodos M6-SCR-01..11, cards, modales, rutas, retornos, memoria y señales externas. | L27: CP-M6-023 | M27: Pendiente de evidencia QA ejecutada | N27: Pendiente | O27: 8859:31712 · ID lógico blueprint M6-SCR-07 | P27: https://www.figma.com/design/v45c4HTKnPnU0XABMa5vjY/Walvi-APP---Edificate-Inteligente?node-id=8859-31712 | Q27: Confirmado documental + Figma sección | R27: Pendiente
A28: M6-V24 | B28: Origen del dato | C28: Dato ilegible o insuficiente | D28: Documento/dato no permite lectura confiable | E28: Estado Requiere revisión / baja confianza; CTA Revisar archivo/origen o ingresar manualmente; no exigir comprobante obligatorio. | F28: M6-HU-004 / M6-HU-009 / M6-HU-017 | G28: CA1-CA3 | H28: R-M6-053 / R-M6-054 / BDD-M6-016 | I28: MVP | J28: F2 | F3 | F4 | F5 | M6-BP | K28: Fase 2 – Inventario de Pantallas, Estados y Componentes M6 Pagos v1.0: superficies, pantallas candidatas, estados, componentes, CTAs y acciones. Fase 3 – Reglas Funcionales, Severidad y Anexo BDD M6 Pagos v1.0: reglas R-M6, severidad, semáforo de presión, señales intermodulares y BDD. Fase 4 – Copy UX, CTAs y Mensajería Contextual M6 Pagos v1.0: CTAs oficiales, copy permitido/restringido/prohibido y mensajes por estado. Fase 5 – Briefing UX y Matriz Maestra de Obligaciones UX M6 Pagos v1.0: obligaciones UX OUX-M6-001..024, superficies, prioridad y guardrails. Blueprint plaintext M6-FLOW-02: nodos M6-SCR-01..11, cards, modales, rutas, retornos, memoria y señales externas. | L28: CP-M6-024 | M28: Pendiente de evidencia QA ejecutada | N28: Pendiente | O28: 8859:31712 · ID lógico blueprint M6-SCR-10 / M6-SCR-07 | P28: https://www.figma.com/design/v45c4HTKnPnU0XABMa5vjY/Walvi-APP---Edificate-Inteligente?node-id=8859-31712 | Q28: Confirmado documental + Figma sección | R28: Pendiente
A29: M6-V25 | B29: Origen del dato | C29: Dato contradictorio | D29: Dato detectado contradice dato declarado | E29: Solicitar revisión o corrección; no confirmar sin revisión. | F29: M6-HU-004 / M6-HU-009 | G29: CA1-CA3 | H29: R-M6-055 | I29: MVP | J29: F3 | F4 | K29: Fase 3 – Reglas Funcionales, Severidad y Anexo BDD M6 Pagos v1.0: reglas R-M6, severidad, semáforo de presión, señales intermodulares y BDD. Fase 4 – Copy UX, CTAs y Mensajería Contextual M6 Pagos v1.0: CTAs oficiales, copy permitido/restringido/prohibido y mensajes por estado. | L29: CP-M6-025 | M29: Pendiente de evidencia QA ejecutada | N29: Pendiente | O29: 8859:31712 · ID lógico blueprint M6-SCR-07 | P29: https://www.figma.com/design/v45c4HTKnPnU0XABMa5vjY/Walvi-APP---Edificate-Inteligente?node-id=8859-31712 | Q29: Confirmado documental + Figma sección | R29: Pendiente
A30: M6-V26 | B30: Origen del dato | C30: Pago informado sin confianza suficiente | D30: Dato informado/detectado no alcanza confianza suficiente | E30: Mantener Requiere revisión y no marcar Pagado por defecto. | F30: M6-HU-004 / M6-HU-009 | G30: CA1-CA3 | H30: R-M6-057 | I30: MVP | J30: F3 | F4 | K30: Fase 3 – Reglas Funcionales, Severidad y Anexo BDD M6 Pagos v1.0: reglas R-M6, severidad, semáforo de presión, señales intermodulares y BDD. Fase 4 – Copy UX, CTAs y Mensajería Contextual M6 Pagos v1.0: CTAs oficiales, copy permitido/restringido/prohibido y mensajes por estado. | L30: CP-M6-026 | M30: Pendiente de evidencia QA ejecutada | N30: Pendiente | O30: 8859:31712 · ID lógico blueprint M6-SCR-07 / M6-SCR-10 | P30: https://www.figma.com/design/v45c4HTKnPnU0XABMa5vjY/Walvi-APP---Edificate-Inteligente?node-id=8859-31712 | Q30: Confirmado documental + Figma sección | R30: Pendiente
A31: M6-V27 | B31: Duplicidad | C31: Detectar duplicado probable | D31: Candidato coincide con cuenta existente por monto, fecha, descripción, glosa o categoría | E31: Estado Duplicado probable; bloquear fusión/consolidación automática y CTA Revisar duplicado. | F31: M6-HU-010 | G31: CA1-CA2 | H31: R-M6-060 / R-M6-061 / R-M6-062 / BDD-M6-011 | I31: MVP | J31: F3 | F4 | F5 | M6-BP | K31: Fase 3 – Reglas Funcionales, Severidad y Anexo BDD M6 Pagos v1.0: reglas R-M6, severidad, semáforo de presión, señales intermodulares y BDD. Fase 4 – Copy UX, CTAs y Mensajería Contextual M6 Pagos v1.0: CTAs oficiales, copy permitido/restringido/prohibido y mensajes por estado. Fase 5 – Briefing UX y Matriz Maestra de Obligaciones UX M6 Pagos v1.0: obligaciones UX OUX-M6-001..024, superficies, prioridad y guardrails. Blueprint plaintext M6-FLOW-02: nodos M6-SCR-01..11, cards, modales, rutas, retornos, memoria y señales externas. | L31: CP-M6-027 | M31: Pendiente de evidencia QA ejecutada | N31: Pendiente | O31: 8859:31712 · ID lógico blueprint M6-SCR-08 | P31: https://www.figma.com/design/v45c4HTKnPnU0XABMa5vjY/Walvi-APP---Edificate-Inteligente?node-id=8859-31712 | Q31: Confirmado documental + Figma sección | R31: Pendiente
A32: M6-V28 | B32: Duplicidad | C32: Confirmar que no es duplicado | D32: Usuario determina que corresponde a compromiso distinto | E32: Mantener cuenta separada como Pendiente/Detectado y conservar trazabilidad. | F32: M6-HU-010 | G32: CA3 | H32: R-M6-063 | I32: MVP | J32: F3 | F4 | M6-BP | K32: Fase 3 – Reglas Funcionales, Severidad y Anexo BDD M6 Pagos v1.0: reglas R-M6, severidad, semáforo de presión, señales intermodulares y BDD. Fase 4 – Copy UX, CTAs y Mensajería Contextual M6 Pagos v1.0: CTAs oficiales, copy permitido/restringido/prohibido y mensajes por estado. Blueprint plaintext M6-FLOW-02: nodos M6-SCR-01..11, cards, modales, rutas, retornos, memoria y señales externas. | L32: CP-M6-028 | M32: Pendiente de evidencia QA ejecutada | N32: Pendiente | O32: 8859:31712 · ID lógico blueprint M6-SCR-08 | P32: https://www.figma.com/design/v45c4HTKnPnU0XABMa5vjY/Walvi-APP---Edificate-Inteligente?node-id=8859-31712 | Q32: Confirmado documental + Figma sección | R32: Pendiente
... A34: M6-V30 | B34: Recurrencia | C34: Sugerir recurrencia probable | D34: Patrón de fecha, monto, glosa, categoría, proveedor o historial sugiere repetición | E34: Estado Recurrente probable; CTA Confirmar recurrencia; no activar automáticamente. | F34: M6-HU-011 | G34: CA1-CA2 | H34: R-M6-070 / R-M6-071 / BDD-M6-012 | I34: MVP | J34: F3 | F4 | F5 | M6-BP | K34: Fase 3 – Reglas Funcionales, Severidad y Anexo BDD M6 Pagos v1.0: reglas R-M6, severidad, semáforo de presión, señales intermodulares y BDD. Fase 4 – Copy UX, CTAs y Mensajería Contextual M6 Pagos v1.0: CTAs oficiales, copy permitido/restringido/prohibido y mensajes por estado. Fase 5 – Briefing UX y Matriz Maestra de Obligaciones UX M6 Pagos v1.0: obligaciones UX OUX-M6-001..024, superficies, prioridad y guardrails. Blueprint plaintext M6-FLOW-02: nodos M6-SCR-01..11, cards, modales, rutas, retornos, memoria y señales externas. | L34: CP-M6-030 | M34: Pendiente de evidencia QA ejecutada | N34: Pendiente | O34: 8859:31712 · ID lógico blueprint M6-SCR-09 | P34: https://www.figma.com/design/v45c4HTKnPnU0XABMa5vjY/Walvi-APP---Edificate-Inteligente?node-id=8859-31712 | Q34: Confirmado documental + Figma sección | R34: Pendiente
A35: M6-V31 | B35: Recurrencia | C35: Confirmar recurrencia | D35: Usuario confirma recurrencia | E35: Marcar recurrencia confirmada/preparable; cualquier compromiso futuro depende de regla definida y no de pago automático. | F35: M6-HU-011 | G35: CA1-CA3 | H35: R-M6-072 / BDD-M6-013 | I35: MVP – parametrizable | J35: F3 | F4 | M6-BP | K35: Fase 3 – Reglas Funcionales, Severidad y Anexo BDD M6 Pagos v1.0: reglas R-M6, severidad, semáforo de presión, señales intermodulares y BDD. Fase 4 – Copy UX, CTAs y Mensajería Contextual M6 Pagos v1.0: CTAs oficiales, copy permitido/restringido/prohibido y mensajes por estado. Blueprint plaintext M6-FLOW-02: nodos M6-SCR-01..11, cards, modales, rutas, retornos, memoria y señales externas. | L35: CP-M6-031 | M35: Pendiente de evidencia QA ejecutada | N35: Pendiente | O35: 8859:31712 · ID lógico blueprint M6-SCR-09 | P35: https://www.figma.com/design/v45c4HTKnPnU0XABMa5vjY/Walvi-APP---Edificate-Inteligente?node-id=8859-31712 | Q35: Confirmado documental + Figma sección | R35: Pendiente | T35: PD-M6-06
A36: M6-V32 | B36: Recurrencia | C36: Rechazar recurrencia | D36: Usuario indica No es recurrente | E36: Mantener como pago único / recurrencia descartada, evitando insistencia. | F36: M6-HU-011 | G36: CA2 | H36: R-M6-073 / BDD-M6-014 | I36: MVP | J36: F3 | F4 | M6-BP | K36: Fase 3 – Reglas Funcionales, Severidad y Anexo BDD M6 Pagos v1.0: reglas R-M6, severidad, semáforo de presión, señales intermodulares y BDD. Fase 4 – Copy UX, CTAs y Mensajería Contextual M6 Pagos v1.0: CTAs oficiales, copy permitido/restringido/prohibido y mensajes por estado. Blueprint plaintext M6-FLOW-02: nodos M6-SCR-01..11, cards, modales, rutas, retornos, memoria y señales externas. | L36: CP-M6-032 | M36: Pendiente de evidencia QA ejecutada | N36: Pendiente | O36: 8859:31712 · ID lógico blueprint M6-SCR-09 | P36: https://www.figma.com/design/v45c4HTKnPnU0XABMa5vjY/Walvi-APP---Edificate-Inteligente?node-id=8859-31712 | Q36: Confirmado documental + Figma sección | R36: Pendiente
A37: M6-V33 | B37: Recurrencia | C37: Patrón de baja confianza | D37: Se detecta posible recurrencia con confianza baja | E37: Mostrar Requiere revisión; no presentar recurrencia sugerida fuerte ni crear futuros. | F37: M6-HU-004 / M6-HU-011 | G37: CA1-CA3 | H37: R-M6-074 | I37: MVP | J37: F3 | F4 | K37: Fase 3 – Reglas Funcionales, Severidad y Anexo BDD M6 Pagos v1.0: reglas R-M6, severidad, semáforo de presión, señales intermodulares y BDD. Fase 4 – Copy UX, CTAs y Mensajería Contextual M6 Pagos v1.0: CTAs oficiales, copy permitido/restringido/prohibido y mensajes por estado. | L37: CP-M6-033 | M37: Pendiente de evidencia QA ejecutada | N37: Pendiente | O37: 8859:31712 · ID lógico blueprint M6-SCR-10 / M6-SCR-09 | P37: https://www.figma.com/design/v45c4HTKnPnU0XABMa5vjY/Walvi-APP---Edificate-Inteligente?node-id=8859-31712 | Q37: Confirmado documental + Figma sección | R37: Pendiente
A38: M6-V34 | B38: Alertas | C38: Recordatorio de pago próximo | D38: Estado Próximo | E38: Gatillar alerta/recordatorio seguro con CTA Revisar pago; no inducir pago. | F38: M6-HU-013 | G38: CA1-CA3 | H38: R-M6-090 / R-M6-094 / BDD-M6-017 / BDD-M6-023 | I38: MVP | J38: F3 | F4 | K38: Fase 3 – Reglas Funcionales, Severidad y Anexo BDD M6 Pagos v1.0: reglas R-M6, severidad, semáforo de presión, señales intermodulares y BDD. Fase 4 – Copy UX, CTAs y Mensajería Contextual M6 Pagos v1.0: CTAs oficiales, copy permitido/restringido/prohibido y mensajes por estado. | L38: CP-M6-034 | M38: Pendiente de evidencia QA ejecutada | N38: Pendiente | O38: 8859:31712 · ID lógico blueprint M6-SCR-01 | P38: https://www.figma.com/design/v45c4HTKnPnU0XABMa5vjY/Walvi-APP---Edificate-Inteligente?node-id=8859-31712 | Q38: Confirmado documental + Figma sección | R38: Pendiente | T38: PD-M6-03
A39: M6-V35 | B39: Alertas | C39: Alerta de pago vencido | D39: Estado Vencido | E39: Gatillar alerta operativa con CTA seguro; no usar Pagar ahora ni lenguaje transaccional. | F39: M6-HU-013 | G39: CA1-CA3 | H39: R-M6-091 / R-M6-094 / BDD-M6-018 | I39: MVP | J39: F3 | F4 | K39: Fase 3 – Reglas Funcionales, Severidad y Anexo BDD M6 Pagos v1.0: reglas R-M6, severidad, semáforo de presión, señales intermodulares y BDD. Fase 4 – Copy UX, CTAs y Mensajería Contextual M6 Pagos v1.0: CTAs oficiales, copy permitido/restringido/prohibido y mensajes por estado. | L39: CP-M6-035 | M39: Pendiente de evidencia QA ejecutada | N39: Pendiente | O39: 8859:31712 · ID lógico blueprint M6-SCR-01 | P39: https://www.figma.com/design/v45c4HTKnPnU0XABMa5vjY/Walvi-APP---Edificate-Inteligente?node-id=8859-31712 | Q39: Confirmado documental + Figma sección | R39: Pendiente
A40: M6-V36 | B40: Alertas | C40: Aviso por dato incompleto | D40: Estado Requiere revisión / dato incompleto | E40: Mostrar aviso de revisión, sin urgencia artificial ni criticidad. | F40: M6-HU-013 / M6-HU-004 | G40: CA2 | H40: R-M6-092 | I40: MVP | J40: F3 | F4 | K40: Fase 3 – Reglas Funcionales, Severidad y Anexo BDD M6 Pagos v1.0: reglas R-M6, severidad, semáforo de presión, señales intermodulares y BDD. Fase 4 – Copy UX, CTAs y Mensajería Contextual M6 Pagos v1.0: CTAs oficiales, copy permitido/restringido/prohibido y mensajes por estado. | L40: CP-M6-036 | M40: Pendiente de evidencia QA ejecutada | N40: Pendiente | O40: 8859:31712 · ID lógico blueprint M6-SCR-10 | P40: https://www.figma.com/design/v45c4HTKnPnU0XABMa5vjY/Walvi-APP---Edificate-Inteligente?node-id=8859-31712 | Q40: Confirmado documental + Figma sección | R40: Pendiente
A41: M6-V37 | B41: Alertas | C41: Aviso de recurrencia probable | D41: Estado Recurrente probable | E41: Solicitar confirmación, sin activar recurrencia ni pagos futuros automáticamente. | F41: M6-HU-013 / M6-HU-011 | G41: CA1-CA3 | H41: R-M6-093 | I41: MVP | J41: F3 | F4 | K41: Fase 3 – Reglas Funcionales, Severidad y Anexo BDD M6 Pagos v1.0: reglas R-M6, severidad, semáforo de presión, señales intermodulares y BDD. Fase 4 – Copy UX, CTAs y Mensajería Contextual M6 Pagos v1.0: CTAs oficiales, copy permitido/restringido/prohibido y mensajes por estado. | L41: CP-M6-037 | M41: Pendiente de evidencia QA ejecutada | N41: Pendiente | O41: 8859:31712 · ID lógico blueprint M6-SCR-09 | P41: https://www.figma.com/design/v45c4HTKnPnU0XABMa5vjY/Walvi-APP---Edificate-Inteligente?node-id=8859-31712 | Q41: Confirmado documental + Figma sección | R41: Pendiente
A42: M6-V38 | B42: Recomendaciones | C42: Recomendación contextual segura | D42: Vencido, recurrente o dato por revisar | E42: Mensaje informativo para ordenar/revisar; sin asesoría financiera regulada, promesa, culpa o instrucción de pago. | F42: M6-HU-014 | G42: CA1-CA3 | H42: R-M6-100 / R-M6-101 / R-M6-102 / R-M6-104 / BDD-M6-019 | I42: MVP | J42: F3 | F4 | F5 | K42: Fase 3 – Reglas Funcionales, Severidad y Anexo BDD M6 Pagos v1.0: reglas R-M6, severidad, semáforo de presión, señales intermodulares y BDD. Fase 4 – Copy UX, CTAs y Mensajería Contextual M6 Pagos v1.0: CTAs oficiales, copy permitido/restringido/prohibido y mensajes por estado. Fase 5 – Briefing UX y Matriz Maestra de Obligaciones UX M6 Pagos v1.0: obligaciones UX OUX-M6-001..024, superficies, prioridad y guardrails. | L42: CP-M6-038 | M42: Pendiente de evidencia QA ejecutada | N42: Pendiente | Q42: Confirmado documental | R42: Pendiente
...

Sheet Historias y CA
A1: WALVY | M6 – Historias de Usuario y Criterios de Aceptación
A3: ID | B3: Historia | C3: Redacción | D3: Criterios de aceptación
A4: M6-HU-001 | B4: Consultar consolidado de pagos | C4: Como usuario, quiero ver mis compromisos de pago organizados por estado, para entender qué tengo pendiente, próximo, vencido, realizado o por revisar. | D4: CA1. Debe existir una superficie Pagos o equivalente funcional aprobada que concentre las obligaciones mínimas de M6. CA2. Se distinguen estados pendientes, próximos, vencidos, realizados y casos que requieren revisión. CA3. Cada elemento ofrece una acción segura y no transaccional según su estado.
A5: M6-HU-002 | B5: Registrar cuenta por pagar manualmente | C5: Como usuario, quiero registrar manualmente una cuenta por pagar, para hacer seguimiento de un compromiso aunque Walvy no lo haya detectado. | D5: CA1. Con descripción y fecha de vencimiento puede crearse una cuenta activa. CA2. Si faltan datos mínimos queda como borrador o sin datos suficientes. CA3. El origen manual se conserva y la acción no ejecuta ningún pago.
A6: M6-HU-003 | B6: Revisar candidato detectado | C6: Como usuario, quiero revisar un posible pago detectado antes de consolidarlo, para confirmar, corregir o descartar información sugerida por Walvy. | D6: CA1. El candidato muestra origen y nivel de confianza cuando corresponde. CA2. El CTA oficial para una posible cuenta es Confirmar cuenta o Confirmar como pago pendiente según contexto. CA3. No existe consolidación automática sin confirmación o regla funcional suficiente.
A7: M6-HU-004 | B7: Gestionar datos insuficientes o de baja confianza | C7: Como usuario, quiero identificar y completar datos incompletos o poco confiables, para evitar que Walvy use información incierta como confirmada. | D7: CA1. La baja confianza se muestra como revisión, no como certeza. CA2. Sin fecha confiable no se calcula Próximo/Vencido y sin datos suficientes no se eleva a criticidad. CA3. El usuario puede revisar, completar, corregir o descartar según el caso.
A8: M6-HU-005 | B8: Revisar pago próximo | C8: Como usuario, quiero identificar pagos próximos a vencer, para revisar con anticipación mis compromisos del mes. | D8: CA1. El estado Próximo depende de un umbral funcional parametrizable. CA2. Con datos confiables e impacto relevante puede elevarse a Urgente. CA3. El CTA orienta a Revisar pago o Registrar pago realizado, nunca a pagar desde Walvy.
A9: M6-HU-006 | B9: Revisar pago vencido | C9: Como usuario, quiero identificar pagos vencidos, para revisar su estado y registrar si ya los pagué fuera de Walvy. | D9: CA1. Vencido requiere fecha confiable superada sin pago registrado ni vínculo suficiente. CA2. Puede gatillar alerta y, con datos suficientes, severidad Urgente/Crítica. CA3. El CTA no debe ser transaccional ni usar lenguaje alarmista.
A10: M6-HU-007 | B10: Registrar pago realizado fuera de Walvy | C10: Como usuario, quiero registrar que un pago ya fue realizado fuera de Walvy, para mantener actualizado el seguimiento de mis compromisos. | D10: CA1. Registrar pago realizado no ejecuta ni instruye un pago. CA2. El registro conserva fecha, origen y acción del usuario o dato detectado cuando aplique. CA3. Al registrarse puede limpiar o reducir una señal pendiente, próxima o vencida sin borrar el historial.
A11: M6-HU-008 | B11: Corregir o deshacer un pago realizado | C11: Como usuario, quiero corregir o deshacer un pago marcado como realizado por error, para recuperar el estado correcto sin perder trazabilidad. | D11: CA1. Debe existir tratamiento de Corregir / Deshacer. CA2. El estado se recalcula a Pendiente, Próximo, Vencido, Requiere revisión o Corregido según datos vigentes. CA3. Se conserva historial mínimo de estado anterior, acción y fecha.
A12: M6-HU-009 | B12: Revisar registro u origen del dato | C12: Como usuario, quiero revisar el registro u origen del dato asociado a un pago, para entender de dónde proviene sin asumir que está validado formalmente. | D12: CA1. Puede mostrarse origen manual, documento, cartola, movimiento, glosa, patrón u otra fuente permitida. CA2. El origen del dato no equivale por sí solo a pago validado, comprobante formal o deuda cerrada. CA3. Si el dato es ilegible, incompleto o contradictorio queda en revisión.
A13: M6-HU-010 | B13: Revisar duplicado probable | C13: Como usuario, quiero revisar un pago que podría estar duplicado, para decidir si corresponde al mismo compromiso o a uno distinto. | D13: CA1. La coincidencia puede considerar monto, fecha, descripción, glosa o categoría. CA2. No se fusiona ni consolida automáticamente. CA3. El usuario puede mantener separado, descartar o vincular según la regla aplicable.
A14: M6-HU-011 | B14: Gestionar recurrencia probable | C14: Como usuario, quiero confirmar o rechazar un patrón de pago recurrente, para anticipar compromisos repetidos sin activar pagos automáticos. | D14: CA1. La recurrencia probable se sugiere por patrón y requiere confirmación o regla suficiente. CA2. El usuario puede Confirmar recurrencia o indicar No es recurrente. CA3. Baja confianza mantiene el caso en revisión y no crea compromisos futuros automáticamente.
... A22: M6-HU-019 | B22: Interpretar presión de flujo por compromisos | C22: Como usuario, quiero que Walvy interprete la presión de flujo provocada por compromisos, para recibir señales coherentes según la causa. | D22: CA1. La lectura funcional usa los umbrales 50/80/90/100/110 definidos en Fase 3. CA2. >=80% es alerta preventiva y no activa M4 automáticamente. CA3. La derivación se bifurca por causa: M5/Home para presupuesto general, M6 para compromisos cerrables y M4 solo con deuda bajo presión.

Sheet Reglas de Negocio
A1: WALVY | M6 – Matriz completa de Reglas Funcionales
A3: ID | B3: Nombre / Grupo | C3: Regla | D3: Estado / Origen | E3: Código fuente RN | F3: Descripción fuente RN
A4: R-M6-001 | B4: Creación | C4: Si el usuario crea una cuenta con descripción y fecha de vencimiento, M6 puede crear una cuenta por pagar activa. | D4: MVP / Fase 3 | E4: M6-F3 | F4: Fase 3 – Reglas Funcionales, Severidad y Anexo BDD M6 Pagos v1.0: reglas R-M6, severidad, semáforo de presión, señales intermodulares y BDD. Resultado/Gatillo documentado: Pendiente. Guardrail/condición: No ejecuta pago.
A5: R-M6-002 | B5: Creación | C5: Si falta descripción o fecha de vencimiento, la cuenta no debe quedar activa como pendiente completa. | D5: MVP / Fase 3 | E5: M6-F3 | F5: Fase 3 – Reglas Funcionales, Severidad y Anexo BDD M6 Pagos v1.0: reglas R-M6, severidad, semáforo de presión, señales intermodulares y BDD. Resultado/Gatillo documentado: Borrador / Sin datos suficientes. Guardrail/condición: No gatillar alerta fuerte.
A6: R-M6-003 | B6: Creación | C6: Si el monto falta, la cuenta puede existir, pero su severidad por impacto económico debe quedar limitada. | D6: MVP / Fase 3 | E6: M6-F3 | F6: Fase 3 – Reglas Funcionales, Severidad y Anexo BDD M6 Pagos v1.0: reglas R-M6, severidad, semáforo de presión, señales intermodulares y BDD. Resultado/Gatillo documentado: Pendiente / Requiere revisión. Guardrail/condición: No marcar crítica solo por monto ausente.
A7: R-M6-004 | B7: Creación | C7: Toda cuenta creada manualmente debe conservar origen manual. | D7: MVP / Fase 3 | E7: M6-F3 | F7: Fase 3 – Reglas Funcionales, Severidad y Anexo BDD M6 Pagos v1.0: reglas R-M6, severidad, semáforo de presión, señales intermodulares y BDD. Resultado/Gatillo documentado: Estado correspondiente. Guardrail/condición: Trazabilidad obligatoria.
A8: R-M6-005 | B8: Creación | C8: Una cuenta manual puede corregirse antes o después de ser registrada, según reglas de edición/corrección. | D8: MVP / Fase 3 | E8: M6-F3 | F8: Fase 3 – Reglas Funcionales, Severidad y Anexo BDD M6 Pagos v1.0: reglas R-M6, severidad, semáforo de presión, señales intermodulares y BDD. Resultado/Gatillo documentado: Estado actualizado. Guardrail/condición: Mantener historial funcional.
A9: R-M6-010 | B9: Candidato detectado | C9: Si captura, ingesta, glosa, documento, cartola o patrón sugiere un pago, M6 debe crear candidato detectado, no cuenta confirmada automática. | D9: MVP / Fase 3 | E9: M6-F3 | F9: Fase 3 – Reglas Funcionales, Severidad y Anexo BDD M6 Pagos v1.0: reglas R-M6, severidad, semáforo de presión, señales intermodulares y BDD. Resultado/Gatillo documentado: Detectado. Guardrail/condición: No consolidación automática.
A10: R-M6-011 | B10: Candidato detectado | C10: Todo candidato detectado debe mostrar origen y nivel de confianza funcional. | D10: MVP / Fase 3 | E10: M6-F3 | F10: Fase 3 – Reglas Funcionales, Severidad y Anexo BDD M6 Pagos v1.0: reglas R-M6, severidad, semáforo de presión, señales intermodulares y BDD. Resultado/Gatillo documentado: Detectado. Guardrail/condición: Trazabilidad.
A11: R-M6-012 | B11: Candidato detectado | C11: Si el candidato tiene datos incompletos o ambiguos, debe marcarse como requiere revisión. | D11: MVP / Fase 3 | E11: M6-F3 | F11: Fase 3 – Reglas Funcionales, Severidad y Anexo BDD M6 Pagos v1.0: reglas R-M6, severidad, semáforo de presión, señales intermodulares y BDD. Resultado/Gatillo documentado: Requiere revisión. Guardrail/condición: No alerta crítica.
A12: R-M6-013 | B12: Candidato detectado | C12: Si el usuario confirma candidato con datos mínimos, puede transformarse en cuenta pendiente, próxima o pagada según contexto. | D12: MVP / Fase 3 | E12: M6-F3 | F12: Fase 3 – Reglas Funcionales, Severidad y Anexo BDD M6 Pagos v1.0: reglas R-M6, severidad, semáforo de presión, señales intermodulares y BDD. Resultado/Gatillo documentado: Pendiente / Próximo / Pagado. Guardrail/condición: Confirmación usuario.
A13: R-M6-014 | B13: Candidato detectado | C13: Si el usuario corrige candidato, debe guardarse el dato corregido como fuente funcional prioritaria. | D13: MVP / Fase 3 | E13: M6-F3 | F13: Fase 3 – Reglas Funcionales, Severidad y Anexo BDD M6 Pagos v1.0: reglas R-M6, severidad, semáforo de presión, señales intermodulares y BDD. Resultado/Gatillo documentado: Estado corregido. Guardrail/condición: Mantener origen original.
A14: R-M6-015 | B14: Candidato detectado | C14: Si el usuario descarta candidato, no debe volver a proponerse de forma insistente salvo nueva senal, dato autorizado o regla posterior. | D14: MVP / Fase 3 | E14: M6-F3 | F14: Fase 3 – Reglas Funcionales, Severidad y Anexo BDD M6 Pagos v1.0: reglas R-M6, severidad, semáforo de presión, señales intermodulares y BDD. Resultado/Gatillo documentado: Descartado. Guardrail/condición: Evitar ruido.
... A83: R-M6-141 | B83: Calidad de dato/Perfil | C83: Dato detectado insuficiente o baja confianza puede indicar baja confiabilidad. | D83: MVP / Fase 3 | E83: M6-F3 | F83: Fase 3 – Reglas Funcionales, Severidad y Anexo BDD M6 Pagos v1.0: reglas R-M6, severidad, semáforo de presión, señales intermodulares y BDD. Resultado/Gatillo documentado: Dato baja confianza. Guardrail/condición: No validar automáticamente.

Sheet Fuentes
A1: WALVY | M6 – Fuentes documentales, blueprint y Figma
A3: Código | B3: Fuente | C3: Tipo | D3: Uso / cobertura | E3: URL / referencia
A4: M6-F1 | B4: Walvy_Modulo6_Pagos_Fase1_Definicion_Funcional_v1_0 | C4: Documento funcional | D4: Propósito, alcance MVP, estados, reglas base, capacidades transversales, dependencias y guardrails | E4: Adjunto cliente
A5: M6-F2 | B5: Walvy_Modulo6_Pagos_Fase2_Inventario_Pantallas_Estados_Componentes_v1_0 | C5: Documento funcional / modelado | D5: Pantallas candidatas, estados visibles, componentes, CTAs, acciones y superficies consumidoras | E5: Adjunto cliente
A6: M6-F3 | B6: Walvy_Modulo6_Pagos_Fase3_Reglas_Funcionales_Severidad_Anexo_BDD_v1_0 | C6: Reglas / BDD | D6: Reglas R-M6-001..141, severidad, presión de flujo, señales Home/M5/M4 y BDD-M6-001..027 | E6: Adjunto cliente
A7: M6-F4 | B7: Walvy_Modulo6_Pagos_Fase4_Copy_UX_CTAs_Mensajeria_Contextual_v1_0 | C7: Copy / CTAs | D7: CTAs oficiales, copy por estado, lenguaje permitido/restringido/prohibido y mensajería contextual | E7: Adjunto cliente
A8: M6-F5 | B8: Walvy_Modulo6_Pagos_Fase5_Briefing_UX_Matriz_Obligaciones_UX_v1_0 | C8: Briefing UX funcional | D8: Matriz OUX-M6-001..024, obligaciones MVP, equivalencia de superficie, prioridad y guardrails | E8: Adjunto cliente
A9: M6-BP | B9: Walvy_Modulo6_Pagos_Plaintext_Nodos_Cards_Modales_v1_0 | C9: Blueprint textual | D9: Mapa M6-FLOW-02, M6-SCR-01..11, cards, modales, rutas, retornos, memoria y señales externas | E9: Adjunto cliente
A10: M6-FIG | B10: Walvi APP – Edifícate Inteligente / M6 Pagos | C10: Figma | D10: Referencia visual del módulo M6 Pagos. Se conserva como fuente visual y requiere validación UX/QA para elevar comportamientos Figma-only a definición cerrada. | E10: https://www.figma.com/design/v45c4HTKnPnU0XABMa5vjY/Walvi-APP---Edificate-Inteligente?node-id=8859-31712
A11: M6-RECTOR | B11: Walvy_Rector_Producto_y_Funcionalidades_MVP_v1.0 | C11: Rector MVP declarado por F1–F5 | D11: Fuente rectora citada por la documentación M6; no fue adjuntada en esta entrega, por lo que no se incorporan reglas nuevas desde ella. | E11: Fuente declarada en M6; no adjunta

Sheet Pendientes Cliente
A1: WALVY | M6 – Decisiones funcionales / UX / técnicas pendientes del Cliente
A2: Esta pestaña no replica las variantes pendientes de aprobación. Incluye únicamente definiciones, parámetros o comportamientos que requieren una decisión explícita. La aprobación de cada variante se registra en “Validación Cliente” de la Matriz Trazabilidad.
A4: ID Pendiente | B4: Tipo de decisión | C4: Variantes / RN afectadas | D4: Tema a definir | E4: Motivo / Fuente | F4: Nodo(s) Figma | G4: Estado decisión | H4: Decisión PO / Comentarios
A5: PD-M6-01 | B5: Producto / Configuración | C5: M6-V12 | R-M6-020, R-M6-021, R-M6-022 | D5: Definir el valor/rango del umbral de “Próximo vencimiento”. | E5: F3-D01 deja el umbral parametrizable y explícitamente no fija número de días. | F5: 8859:31712 | G5: Pendiente
A6: PD-M6-02 | B6: Producto / UX | C6: M6-V02, M6-V59 | F5 sección 6 | D6: Confirmar cierre visual de Pantalla principal Pagos versus superficie equivalente aprobada, incluyendo arquitectura de navegación. | E6: F2/F5 recomiendan pantalla propia como candidata fuerte, pero no la cierran como obligación visual final. El nodo Figma se incorpora como referencia visual, no como aprobación de Producto. | F6: 8859:31712 | G6: Pendiente
A7: PD-M6-03 | B7: Producto / UX / Técnica | C7: M6-V36 | F3-D10 / M6-PAN-06 | D7: Definir personalización avanzada de recordatorios: catálogo, anticipación, persistencia y configuración del usuario. | E7: F2 deja Configuración de recordatorios pendiente y F3 deriva personalización avanzada fuera de su alcance. | F7: 8859:31712 | G7: Pendiente
A8: PD-M6-04 | B8: Producto / UX | C8: M6-V41–M6-V43 | R-M6-110..113 | D8: Definir prioridad y representación visual final de señales M6 en Home y superficies consumidoras. | E8: F3/F5 solo definen gatillos funcionales; no fijan jerarquía, layout ni prioridad visual final. | F8: 8859:31712 | G8: Pendiente
A9: PD-M6-05 | B9: Producto / Reglas | C9: M6-V13, M6-V16 | R-M6-023 / R-M6-031 | D9: Definir criterio parametrizable de “monto relevante / alto impacto mensual” cuando se use para elevar severidad a Urgente o Crítica. | E9: F3 utiliza el criterio de monto relevante/impacto con condición de confianza, pero no documenta un umbral cuantitativo específico. | F9: — | G9: Pendiente
A10: PD-M6-06 | B10: Producto / Reglas / Técnica | C10: M6-V33, M6-V46 | R-M6-072 / R-M6-122 | D10: Definir regla para preparar compromisos futuros tras confirmar recurrencia: horizonte, fecha, monto y mecanismo de actualización. | E10: F3 permite preparar futuros “según regla definida” y exige regla suficiente, pero no cierra los parámetros de generación. | F10: — | G10: Pendiente
A11: PD-M6-07 | B11: Técnica / Datos | C11: M6-V20–M6-V21 / M6-V50 | R-M6-041, R-M6-044 | D11: Definir retención, modelo de auditoría y nivel de detalle técnico del historial funcional. | E11: La documentación exige trazabilidad mínima, pero no define retención, estructura física de auditoría ni política técnica de conservación. | F11: — | G11: Pendiente
A12: PD-M6-08 | B12: UX / QA / Producto | C12: M6-V01–M6-V59 | Figma 8859:31712 | D12: Validar correspondencia visual entre el nodo Figma M6 y las obligaciones F1–F5 / blueprint M6-SCR-01..11 antes de considerar el diseño como fuente cerrada. | E12: Las fases documentales declaran que Figma/mockups requieren QA y aprobación posterior. La matriz conserva esa clasificación de autoridad. | F12: 8859:31712 | G12: Pendiente

Sheet Resumen
A1: WALVY | M6 – Resumen de trazabilidad
A3: Indicador | B3: Valor | E3: Cómo revisar
A4: Variantes | B4: =COUNTA('Matriz Trazabilidad'!$A$5:$A$87) -> 59 | E4: 1 | F4: Revisar HU/CA | G4: Confirmar que intención y criterios representan el comportamiento esperado.
A5: Historias de Usuario | B5: =COUNTA('Historias y CA'!$A$4:$A$31) -> 19 | E5: 2 | F5: Revisar RN | G5: Ratificar reglas y especialmente las marcadas como Figma/pendiente.
A6: Reglas de Negocio | B6: =COUNTA('Reglas de Negocio'!$A$4:$A$84) -> 80 | E6: 3 | F6: Revisar variante | G6: Aprobar, ajustar o excluir cada escenario.
A7: Variantes con evidencia Passed | B7: =COUNTIF('Matriz Trazabilidad'!$N$5:$N$87,"Passed") -> 0 | E7: 4 | F7: Revisar CP/QA | G7: Confirmar caso de prueba y luego vincular evidencia real.
A8: Variantes con evidencia pendiente | B8: =COUNTIF('Matriz Trazabilidad'!$N$5:$N$87,"Pendiente") -> 59
A9: Puntos de decisión/validación Cliente | B9: =COUNTA('Pendientes Cliente'!$A$5:$A$23) -> 8
A10: Nota Fuente RN | B10: El código identifica el artefacto de origen; la descripción explica su nombre y cobertura. Las HU M6 fueron derivadas de las obligaciones documentales F1–F5 para estructurar la cadena de trazabilidad y deben ser validadas junto con las variantes.
A12: Métrica de revisión del Cliente | E12: Decisiones funcionales pendientes
A13: Estado de validación | B13: Cantidad | C13: % del total | E13: Estado decisión | F13: Cantidad | G13: % del total
A14: Aprobado | B14: =COUNTIF('Matriz Trazabilidad'!$R$5:$R$87,"Aprobado") -> 0 | C14: =IF($B$4=0,0,B14/$B$4) -> 0 | E14: Pendiente | F14: =COUNTIF('Pendientes Cliente'!$G$5:$G$23,"Pendiente") -> 8 | G14: =IF($B$9=0,0,F14/$B$9) -> 1
A15: Pendiente | B15: =COUNTIF('Matriz Trazabilidad'!$R$5:$R$87,"Pendiente") -> 59 | C15: =IF($B$4=0,0,B15/$B$4) -> 1 | E15: Resuelto | F15: =COUNTIF('Pendientes Cliente'!$G$5:$G$23,"Resuelto") -> 0 | G15: =IF($B$9=0,0,F15/$B$9) -> 0
A16: Ajustar | B16: =COUNTIF('Matriz Trazabilidad'!$R$5:$R$87,"Ajustar") -> 0 | C16: =IF($B$4=0,0,B16/$B$4) -> 0 | E16: Requiere análisis | F16: =COUNTIF('Pendientes Cliente'!$G$5:$G$23,"Requiere análisis") -> 0 | G16: =IF($B$9=0,0,F16/$B$9) -> 0
A17: Fuera de alcance | B17: =COUNTIF('Matriz Trazabilidad'!$R$5:$R$87,"Fuera de alcance") -> 0 | C17: =IF($B$4=0,0,B17/$B$4) -> 0 | E17: Fuera de alcance | F17: =COUNTIF('Pendientes Cliente'!$G$5:$G$23,"Fuera de alcance") -> 0 | G17: =IF($B$9=0,0,F17/$B$9) -> 0
A18: Requiere análisis | B18: =COUNTIF('Matriz Trazabilidad'!$R$5:$R$87,"Requiere análisis") -> 0 | C18: =IF($B$4=0,0,B18/$B$4) -> 0
A20: Variantes revisadas | B20: =SUM(B14,B16:B18) -> 0
A21: Avance de revisión | B21: =IF($B$4=0,0,B20/$B$4) -> 0
A22: Aprobación sobre revisadas | B22: =IF(B20=0,0,B14/B20) -> 0
